==13621== Memcheck, a memory error detector
==13621== Copyright (C) 2002-2017, and GNU GPL'd, by Julian Seward et al.
==13621== Using Valgrind-3.15.0 and LibVEX; rerun with -h for copyright info
==13621== Command: python leak.py
==13621== Parent PID: 13620
==13621== 
==13621== 
==13621== HEAP SUMMARY:
==13621==     in use at exit: 2,290,728 bytes in 172 blocks
==13621==   total heap usage: 1,898 allocs, 1,726 frees, 5,058,027 bytes allocated
==13621== 
==13621== 34 bytes in 1 blocks are still reachable in loss record 1 of 124
==13621==    at 0x483B7F3: malloc (in /usr/lib/x86_64-linux-gnu/valgrind/vgpreload_memcheck-amd64-linux.so)
==13621==    by 0x401F5DE: strdup (strdup.c:42)
==13621==    by 0x4019A91: _dl_load_cache_lookup (dl-cache.c:338)
==13621==    by 0x400A989: _dl_map_object (dl-load.c:2102)
==13621==    by 0x400F514: openaux (dl-deps.c:64)
==13621==    by 0x4B31927: _dl_catch_exception (dl-error-skeleton.c:208)
==13621==    by 0x400F962: _dl_map_object_deps (dl-deps.c:248)
==13621==    by 0x4015DAF: dl_open_worker (dl-open.c:571)
==13621==    by 0x4B31927: _dl_catch_exception (dl-error-skeleton.c:208)
==13621==    by 0x4015609: _dl_open (dl-open.c:837)
==13621==    by 0x487834B: dlopen_doit (dlopen.c:66)
==13621==    by 0x4B31927: _dl_catch_exception (dl-error-skeleton.c:208)
==13621== 
==13621== 34 bytes in 1 blocks are still reachable in loss record 2 of 124
==13621==    at 0x483B7F3: malloc (in /usr/lib/x86_64-linux-gnu/valgrind/vgpreload_memcheck-amd64-linux.so)
==13621==    by 0x400D5B7: _dl_new_object (dl-object.c:196)
==13621==    by 0x4006E96: _dl_map_object_from_fd (dl-load.c:997)
==13621==    by 0x400A61A: _dl_map_object (dl-load.c:2236)
==13621==    by 0x400F514: openaux (dl-deps.c:64)
==13621==    by 0x4B31927: _dl_catch_exception (dl-error-skeleton.c:208)
==13621==    by 0x400F962: _dl_map_object_deps (dl-deps.c:248)
==13621==    by 0x4015DAF: dl_open_worker (dl-open.c:571)
==13621==    by 0x4B31927: _dl_catch_exception (dl-error-skeleton.c:208)
==13621==    by 0x4015609: _dl_open (dl-open.c:837)
==13621==    by 0x487834B: dlopen_doit (dlopen.c:66)
==13621==    by 0x4B31927: _dl_catch_exception (dl-error-skeleton.c:208)
==13621== 
==13621== 45 bytes in 1 blocks are still reachable in loss record 3 of 124
==13621==    at 0x483B7F3: malloc (in /usr/lib/x86_64-linux-gnu/valgrind/vgpreload_memcheck-amd64-linux.so)
==13621==    by 0x401F5DE: strdup (strdup.c:42)
==13621==    by 0x400A5A9: _dl_map_object (dl-load.c:2168)
==13621==    by 0x4015D46: dl_open_worker (dl-open.c:513)
==13621==    by 0x4B31927: _dl_catch_exception (dl-error-skeleton.c:208)
==13621==    by 0x4015609: _dl_open (dl-open.c:837)
==13621==    by 0x487834B: dlopen_doit (dlopen.c:66)
==13621==    by 0x4B31927: _dl_catch_exception (dl-error-skeleton.c:208)
==13621==    by 0x4B319F2: _dl_catch_error (dl-error-skeleton.c:227)
==13621==    by 0x4878B58: _dlerror_run (dlerror.c:170)
==13621==    by 0x48783D9: dlopen@@GLIBC_2.2.5 (dlopen.c:87)
==13621==    by 0x55BF021: py_dl_open (callproc.c:1530)
==13621== 
==13621== 72 bytes in 1 blocks are still reachable in loss record 4 of 124
==13621==    at 0x483DD99: calloc (in /usr/lib/x86_64-linux-gnu/valgrind/vgpreload_memcheck-amd64-linux.so)
==13621==    by 0x401331C: _dl_check_map_versions (dl-version.c:274)
==13621==    by 0x40160FC: dl_open_worker (dl-open.c:577)
==13621==    by 0x4B31927: _dl_catch_exception (dl-error-skeleton.c:208)
==13621==    by 0x4015609: _dl_open (dl-open.c:837)
==13621==    by 0x487834B: dlopen_doit (dlopen.c:66)
==13621==    by 0x4B31927: _dl_catch_exception (dl-error-skeleton.c:208)
==13621==    by 0x4B319F2: _dl_catch_error (dl-error-skeleton.c:227)
==13621==    by 0x4878B58: _dlerror_run (dlerror.c:170)
==13621==    by 0x48783D9: dlopen@@GLIBC_2.2.5 (dlopen.c:87)
==13621==    by 0x55BF021: py_dl_open (callproc.c:1530)
==13621==    by 0x345010: cfunction_call (methodobject.c:552)
==13621== 
==13621== 184 bytes in 2 blocks are still reachable in loss record 5 of 124
==13621==    at 0x483B7F3: malloc (in /usr/lib/x86_64-linux-gnu/valgrind/vgpreload_memcheck-amd64-linux.so)
==13621==    by 0x401F5DE: strdup (strdup.c:42)
==13621==    by 0x400A5A9: _dl_map_object (dl-load.c:2168)
==13621==    by 0x4015D46: dl_open_worker (dl-open.c:513)
==13621==    by 0x4B31927: _dl_catch_exception (dl-error-skeleton.c:208)
==13621==    by 0x4015609: _dl_open (dl-open.c:837)
==13621==    by 0x487834B: dlopen_doit (dlopen.c:66)
==13621==    by 0x4B31927: _dl_catch_exception (dl-error-skeleton.c:208)
==13621==    by 0x4B319F2: _dl_catch_error (dl-error-skeleton.c:227)
==13621==    by 0x4878B58: _dlerror_run (dlerror.c:170)
==13621==    by 0x48783D9: dlopen@@GLIBC_2.2.5 (dlopen.c:87)
==13621==    by 0x29E650: _PyImport_FindSharedFuncptr (dynload_shlib.c:100)
==13621== 
==13621== 229 bytes in 3 blocks are still reachable in loss record 6 of 124
==13621==    at 0x483B7F3: malloc (in /usr/lib/x86_64-linux-gnu/valgrind/vgpreload_memcheck-amd64-linux.so)
==13621==    by 0x400D5B7: _dl_new_object (dl-object.c:196)
==13621==    by 0x4006E96: _dl_map_object_from_fd (dl-load.c:997)
==13621==    by 0x400A61A: _dl_map_object (dl-load.c:2236)
==13621==    by 0x4015D46: dl_open_worker (dl-open.c:513)
==13621==    by 0x4B31927: _dl_catch_exception (dl-error-skeleton.c:208)
==13621==    by 0x4015609: _dl_open (dl-open.c:837)
==13621==    by 0x487834B: dlopen_doit (dlopen.c:66)
==13621==    by 0x4B31927: _dl_catch_exception (dl-error-skeleton.c:208)
==13621==    by 0x4B319F2: _dl_catch_error (dl-error-skeleton.c:227)
==13621==    by 0x4878B58: _dlerror_run (dlerror.c:170)
==13621==    by 0x48783D9: dlopen@@GLIBC_2.2.5 (dlopen.c:87)
==13621== 
==13621== 516 bytes in 1 blocks are still reachable in loss record 7 of 124
==13621==    at 0x483B7F3: malloc (in /usr/lib/x86_64-linux-gnu/valgrind/vgpreload_memcheck-amd64-linux.so)
==13621==    by 0x1C08B4: PyMem_RawMalloc (obmalloc.c:572)
==13621==    by 0x1C08B4: _PyObject_Malloc (obmalloc.c:1956)
==13621==    by 0x1C08B4: _PyObject_Malloc (obmalloc.c:1949)
==13621==    by 0x1F05FF: PyUnicode_New (unicodeobject.c:1463)
==13621==    by 0x21D047: unicode_decode_utf8 (unicodeobject.c:5203)
==13621==    by 0x1DFB47: type_dict_set_doc (typeobject.c:6072)
==13621==    by 0x1DFB47: type_ready_fill_dict (typeobject.c:6108)
==13621==    by 0x1DFB47: type_ready (typeobject.c:6337)
==13621==    by 0x1D581E: PyType_Ready (typeobject.c:6370)
==13621==    by 0x1BD6B3: _PyTypes_Init (object.c:1871)
==13621==    by 0x275860: pycore_init_types (pylifecycle.c:699)
==13621==    by 0x275860: pycore_interp_init (pylifecycle.c:810)
==13621==    by 0x278724: pyinit_config (pylifecycle.c:866)
==13621==    by 0x278724: pyinit_core.constprop.0 (pylifecycle.c:1029)
==13621==    by 0x279113: Py_InitializeFromConfig (pylifecycle.c:1219)
==13621==    by 0x16E719: pymain_init (main.c:66)
==13621==    by 0x16F9F7: pymain_main (main.c:687)
==13621==    by 0x16F9F7: Py_BytesMain (main.c:720)
==13621== 
==13621== 545 bytes in 1 blocks are still reachable in loss record 8 of 124
==13621==    at 0x483B7F3: malloc (in /usr/lib/x86_64-linux-gnu/valgrind/vgpreload_memcheck-amd64-linux.so)
==13621==    by 0x1C08B4: PyMem_RawMalloc (obmalloc.c:572)
==13621==    by 0x1C08B4: _PyObject_Malloc (obmalloc.c:1956)
==13621==    by 0x1C08B4: _PyObject_Malloc (obmalloc.c:1949)
==13621==    by 0x1F05FF: PyUnicode_New (unicodeobject.c:1463)
==13621==    by 0x21D047: unicode_decode_utf8 (unicodeobject.c:5203)
==13621==    by 0x1DFB47: type_dict_set_doc (typeobject.c:6072)
==13621==    by 0x1DFB47: type_ready_fill_dict (typeobject.c:6108)
==13621==    by 0x1DFB47: type_ready (typeobject.c:6337)
==13621==    by 0x1D581E: PyType_Ready (typeobject.c:6370)
==13621==    by 0x271AE6: PyModule_AddType (modsupport.c:706)
==13621==    by 0x2F11DB: PyInit__io (_iomodule.c:731)
==13621==    by 0x25FD67: create_builtin.part.0 (import.c:1012)
==13621==    by 0x25FE7C: create_builtin (import.c:1000)
==13621==    by 0x25FE7C: _imp_create_builtin (import.c:1063)
==13621==    by 0x345556: cfunction_vectorcall_O (methodobject.c:516)
==13621==    by 0x18064B: PyVectorcall_Call (call.c:255)
==13621== 
==13621== 547 bytes in 1 blocks are still reachable in loss record 9 of 124
==13621==    at 0x483B7F3: malloc (in /usr/lib/x86_64-linux-gnu/valgrind/vgpreload_memcheck-amd64-linux.so)
==13621==    by 0x1C08B4: PyMem_RawMalloc (obmalloc.c:572)
==13621==    by 0x1C08B4: _PyObject_Malloc (obmalloc.c:1956)
==13621==    by 0x1C08B4: _PyObject_Malloc (obmalloc.c:1949)
==13621==    by 0x1724F3: _PyBytes_FromSize (bytesobject.c:126)
==13621==    by 0x1724F3: PyBytes_FromStringAndSize (bytesobject.c:159)
==13621==    by 0x26DBA6: r_object (marshal.c:1069)
==13621==    by 0x26E1F5: r_object (marshal.c:1347)
==13621==    by 0x26D830: r_object (marshal.c:1174)
==13621==    by 0x26E20B: r_object (marshal.c:1350)
==13621==    by 0x26D830: r_object (marshal.c:1174)
==13621==    by 0x26E20B: r_object (marshal.c:1350)
==13621==    by 0x26EFD7: read_object (marshal.c:1445)
==13621==    by 0x26FBE4: PyMarshal_ReadObjectFromString (marshal.c:1562)
==13621==    by 0x345556: cfunction_vectorcall_O (methodobject.c:516)
==13621== 
==13621== 561 bytes in 1 blocks are still reachable in loss record 10 of 124
==13621==    at 0x483B7F3: malloc (in /usr/lib/x86_64-linux-gnu/valgrind/vgpreload_memcheck-amd64-linux.so)
==13621==    by 0x1C08B4: PyMem_RawMalloc (obmalloc.c:572)
==13621==    by 0x1C08B4: _PyObject_Malloc (obmalloc.c:1956)
==13621==    by 0x1C08B4: _PyObject_Malloc (obmalloc.c:1949)
==13621==    by 0x1F05FF: PyUnicode_New (unicodeobject.c:1463)
==13621==    by 0x21D047: unicode_decode_utf8 (unicodeobject.c:5203)
==13621==    by 0x1DFB47: type_dict_set_doc (typeobject.c:6072)
==13621==    by 0x1DFB47: type_ready_fill_dict (typeobject.c:6108)
==13621==    by 0x1DFB47: type_ready (typeobject.c:6337)
==13621==    by 0x1D581E: PyType_Ready (typeobject.c:6370)
==13621==    by 0x1BD1EF: _PyTypes_Init (object.c:1810)
==13621==    by 0x275860: pycore_init_types (pylifecycle.c:699)
==13621==    by 0x275860: pycore_interp_init (pylifecycle.c:810)
==13621==    by 0x278724: pyinit_config (pylifecycle.c:866)
==13621==    by 0x278724: pyinit_core.constprop.0 (pylifecycle.c:1029)
==13621==    by 0x279113: Py_InitializeFromConfig (pylifecycle.c:1219)
==13621==    by 0x16E719: pymain_init (main.c:66)
==13621==    by 0x16F9F7: pymain_main (main.c:687)
==13621==    by 0x16F9F7: Py_BytesMain (main.c:720)
==13621== 
==13621== 567 bytes in 1 blocks are still reachable in loss record 11 of 124
==13621==    at 0x483B7F3: malloc (in /usr/lib/x86_64-linux-gnu/valgrind/vgpreload_memcheck-amd64-linux.so)
==13621==    by 0x1C08B4: PyMem_RawMalloc (obmalloc.c:572)
==13621==    by 0x1C08B4: _PyObject_Malloc (obmalloc.c:1956)
==13621==    by 0x1C08B4: _PyObject_Malloc (obmalloc.c:1949)
==13621==    by 0x1F05FF: PyUnicode_New (unicodeobject.c:1463)
==13621==    by 0x21D047: unicode_decode_utf8 (unicodeobject.c:5203)
==13621==    by 0x1DFB47: type_dict_set_doc (typeobject.c:6072)
==13621==    by 0x1DFB47: type_ready_fill_dict (typeobject.c:6108)
==13621==    by 0x1DFB47: type_ready (typeobject.c:6337)
==13621==    by 0x1D581E: PyType_Ready (typeobject.c:6370)
==13621==    by 0x381509: _PyBuiltin_Init (bltinmodule.c:2983)
==13621==    by 0x275749: pycore_init_builtins (pylifecycle.c:745)
==13621==    by 0x275749: pycore_interp_init (pylifecycle.c:829)
==13621==    by 0x278724: pyinit_config (pylifecycle.c:866)
==13621==    by 0x278724: pyinit_core.constprop.0 (pylifecycle.c:1029)
==13621==    by 0x279113: Py_InitializeFromConfig (pylifecycle.c:1219)
==13621==    by 0x16E719: pymain_init (main.c:66)
==13621==    by 0x16F9F7: pymain_main (main.c:687)
==13621==    by 0x16F9F7: Py_BytesMain (main.c:720)
==13621== 
==13621== 568 bytes in 1 blocks are possibly lost in loss record 12 of 124
==13621==    at 0x483B7F3: malloc (in /usr/lib/x86_64-linux-gnu/valgrind/vgpreload_memcheck-amd64-linux.so)
==13621==    by 0x1C08B4: PyMem_RawMalloc (obmalloc.c:572)
==13621==    by 0x1C08B4: _PyObject_Malloc (obmalloc.c:1956)
==13621==    by 0x1C08B4: _PyObject_Malloc (obmalloc.c:1949)
==13621==    by 0x2A395B: _PyObject_GC_Alloc (gcmodule.c:2274)
==13621==    by 0x2A395B: _PyObject_GC_Malloc (gcmodule.c:2301)
==13621==    by 0x2A395B: _PyObject_GC_NewVar (gcmodule.c:2332)
==13621==    by 0x16E523: frame_alloc (frameobject.c:794)
==13621==    by 0x16E523: _PyFrame_New_NoTrack (frameobject.c:837)
==13621==    by 0x238527: _PyEval_MakeFrameVector (ceval.c:4790)
==13621==    by 0x239166: _PyEval_Vector (ceval.c:5057)
==13621==    by 0x16A1D5: _PyObject_VectorcallTstate (abstract.h:114)
==13621==    by 0x16A1D5: PyObject_Vectorcall (abstract.h:123)
==13621==    by 0x16A1D5: call_function (ceval.c:5867)
==13621==    by 0x16A1D5: _PyEval_EvalFrameDefault (ceval.c:4198)
==13621==    by 0x239197: _PyEval_EvalFrame (pycore_ceval.h:46)
==13621==    by 0x239197: _PyEval_Vector (ceval.c:5065)
==13621==    by 0x16A1D5: _PyObject_VectorcallTstate (abstract.h:114)
==13621==    by 0x16A1D5: PyObject_Vectorcall (abstract.h:123)
==13621==    by 0x16A1D5: call_function (ceval.c:5867)
==13621==    by 0x16A1D5: _PyEval_EvalFrameDefault (ceval.c:4198)
==13621==    by 0x239197: _PyEval_EvalFrame (pycore_ceval.h:46)
==13621==    by 0x239197: _PyEval_Vector (ceval.c:5065)
==13621==    by 0x16B72D: _PyObject_VectorcallTstate (abstract.h:114)
==13621==    by 0x16B72D: PyObject_Vectorcall (abstract.h:123)
==13621==    by 0x16B72D: call_function (ceval.c:5867)
==13621==    by 0x16B72D: _PyEval_EvalFrameDefault (ceval.c:4213)
==13621==    by 0x239197: _PyEval_EvalFrame (pycore_ceval.h:46)
==13621==    by 0x239197: _PyEval_Vector (ceval.c:5065)
==13621== 
==13621== 576 bytes in 1 blocks are still reachable in loss record 13 of 124
==13621==    at 0x483B7F3: malloc (in /usr/lib/x86_64-linux-gnu/valgrind/vgpreload_memcheck-amd64-linux.so)
==13621==    by 0x1C08B4: PyMem_RawMalloc (obmalloc.c:572)
==13621==    by 0x1C08B4: _PyObject_Malloc (obmalloc.c:1956)
==13621==    by 0x1C08B4: _PyObject_Malloc (obmalloc.c:1949)
==13621==    by 0x1A774F: new_keys_object (dictobject.c:600)
==13621==    by 0x1A7900: dictresize (dictobject.c:1242)
==13621==    by 0x1AFA9A: insertion_resize (dictobject.c:1060)
==13621==    by 0x1AFA9A: PyDict_SetDefault (dictobject.c:3067)
==13621==    by 0x1DF9E5: type_add_members (typeobject.c:5645)
==13621==    by 0x1DF9E5: type_ready_fill_dict (typeobject.c:6102)
==13621==    by 0x1DF9E5: type_ready (typeobject.c:6337)
==13621==    by 0x1D581E: PyType_Ready (typeobject.c:6370)
==13621==    by 0x1BD1B3: _PyTypes_Init (object.c:1807)
==13621==    by 0x275860: pycore_init_types (pylifecycle.c:699)
==13621==    by 0x275860: pycore_interp_init (pylifecycle.c:810)
==13621==    by 0x278724: pyinit_config (pylifecycle.c:866)
==13621==    by 0x278724: pyinit_core.constprop.0 (pylifecycle.c:1029)
==13621==    by 0x279113: Py_InitializeFromConfig (pylifecycle.c:1219)
==13621==    by 0x16E719: pymain_init (main.c:66)
==13621== 
==13621== 576 bytes in 1 blocks are still reachable in loss record 14 of 124
==13621==    at 0x483B7F3: malloc (in /usr/lib/x86_64-linux-gnu/valgrind/vgpreload_memcheck-amd64-linux.so)
==13621==    by 0x1C08B4: PyMem_RawMalloc (obmalloc.c:572)
==13621==    by 0x1C08B4: _PyObject_Malloc (obmalloc.c:1956)
==13621==    by 0x1C08B4: _PyObject_Malloc (obmalloc.c:1949)
==13621==    by 0x1A774F: new_keys_object (dictobject.c:600)
==13621==    by 0x1A7900: dictresize (dictobject.c:1242)
==13621==    by 0x1AFA9A: insertion_resize (dictobject.c:1060)
==13621==    by 0x1AFA9A: PyDict_SetDefault (dictobject.c:3067)
==13621==    by 0x1DF80E: type_add_method (typeobject.c:5597)
==13621==    by 0x1DF80E: type_add_methods (typeobject.c:5623)
==13621==    by 0x1DF80E: type_ready_fill_dict (typeobject.c:6099)
==13621==    by 0x1DF80E: type_ready (typeobject.c:6337)
==13621==    by 0x1D581E: PyType_Ready (typeobject.c:6370)
==13621==    by 0x1BD22B: _PyTypes_Init (object.c:1813)
==13621==    by 0x275860: pycore_init_types (pylifecycle.c:699)
==13621==    by 0x275860: pycore_interp_init (pylifecycle.c:810)
==13621==    by 0x278724: pyinit_config (pylifecycle.c:866)
==13621==    by 0x278724: pyinit_core.constprop.0 (pylifecycle.c:1029)
==13621==    by 0x279113: Py_InitializeFromConfig (pylifecycle.c:1219)
==13621==    by 0x16E719: pymain_init (main.c:66)
==13621== 
==13621== 576 bytes in 1 blocks are still reachable in loss record 15 of 124
==13621==    at 0x483B7F3: malloc (in /usr/lib/x86_64-linux-gnu/valgrind/vgpreload_memcheck-amd64-linux.so)
==13621==    by 0x1C08B4: PyMem_RawMalloc (obmalloc.c:572)
==13621==    by 0x1C08B4: _PyObject_Malloc (obmalloc.c:1956)
==13621==    by 0x1C08B4: _PyObject_Malloc (obmalloc.c:1949)
==13621==    by 0x1A774F: new_keys_object (dictobject.c:600)
==13621==    by 0x1A7900: dictresize (dictobject.c:1242)
==13621==    by 0x1AB232: insertion_resize (dictobject.c:1060)
==13621==    by 0x1AB232: insertdict (dictobject.c:1103)
==13621==    by 0x1DFB69: type_dict_set_doc (typeobject.c:6077)
==13621==    by 0x1DFB69: type_ready_fill_dict (typeobject.c:6108)
==13621==    by 0x1DFB69: type_ready (typeobject.c:6337)
==13621==    by 0x1D581E: PyType_Ready (typeobject.c:6370)
==13621==    by 0x1BD27B: _PyTypes_Init (object.c:1817)
==13621==    by 0x275860: pycore_init_types (pylifecycle.c:699)
==13621==    by 0x275860: pycore_interp_init (pylifecycle.c:810)
==13621==    by 0x278724: pyinit_config (pylifecycle.c:866)
==13621==    by 0x278724: pyinit_core.constprop.0 (pylifecycle.c:1029)
==13621==    by 0x279113: Py_InitializeFromConfig (pylifecycle.c:1219)
==13621==    by 0x16E719: pymain_init (main.c:66)
==13621== 
==13621== 576 bytes in 1 blocks are still reachable in loss record 16 of 124
==13621==    at 0x483B7F3: malloc (in /usr/lib/x86_64-linux-gnu/valgrind/vgpreload_memcheck-amd64-linux.so)
==13621==    by 0x1C08B4: PyMem_RawMalloc (obmalloc.c:572)
==13621==    by 0x1C08B4: _PyObject_Malloc (obmalloc.c:1956)
==13621==    by 0x1C08B4: _PyObject_Malloc (obmalloc.c:1949)
==13621==    by 0x1A774F: new_keys_object (dictobject.c:600)
==13621==    by 0x1A7900: dictresize (dictobject.c:1242)
==13621==    by 0x1AFA9A: insertion_resize (dictobject.c:1060)
==13621==    by 0x1AFA9A: PyDict_SetDefault (dictobject.c:3067)
==13621==    by 0x1DFA55: type_add_getset (typeobject.c:5670)
==13621==    by 0x1DFA55: type_ready_fill_dict (typeobject.c:6105)
==13621==    by 0x1DFA55: type_ready (typeobject.c:6337)
==13621==    by 0x1D581E: PyType_Ready (typeobject.c:6370)
==13621==    by 0x1BD2DF: _PyTypes_Init (object.c:1822)
==13621==    by 0x275860: pycore_init_types (pylifecycle.c:699)
==13621==    by 0x275860: pycore_interp_init (pylifecycle.c:810)
==13621==    by 0x278724: pyinit_config (pylifecycle.c:866)
==13621==    by 0x278724: pyinit_core.constprop.0 (pylifecycle.c:1029)
==13621==    by 0x279113: Py_InitializeFromConfig (pylifecycle.c:1219)
==13621==    by 0x16E719: pymain_init (main.c:66)
==13621== 
==13621== 576 bytes in 1 blocks are still reachable in loss record 17 of 124
==13621==    at 0x483B7F3: malloc (in /usr/lib/x86_64-linux-gnu/valgrind/vgpreload_memcheck-amd64-linux.so)
==13621==    by 0x1C08B4: PyMem_RawMalloc (obmalloc.c:572)
==13621==    by 0x1C08B4: _PyObject_Malloc (obmalloc.c:1956)
==13621==    by 0x1C08B4: _PyObject_Malloc (obmalloc.c:1949)
==13621==    by 0x1A774F: new_keys_object (dictobject.c:600)
==13621==    by 0x1A7900: dictresize (dictobject.c:1242)
==13621==    by 0x1AFA9A: insertion_resize (dictobject.c:1060)
==13621==    by 0x1AFA9A: PyDict_SetDefault (dictobject.c:3067)
==13621==    by 0x1DF9E5: type_add_members (typeobject.c:5645)
==13621==    by 0x1DF9E5: type_ready_fill_dict (typeobject.c:6102)
==13621==    by 0x1DF9E5: type_ready (typeobject.c:6337)
==13621==    by 0x1D581E: PyType_Ready (typeobject.c:6370)
==13621==    by 0x1BD40B: _PyTypes_Init (object.c:1837)
==13621==    by 0x275860: pycore_init_types (pylifecycle.c:699)
==13621==    by 0x275860: pycore_interp_init (pylifecycle.c:810)
==13621==    by 0x278724: pyinit_config (pylifecycle.c:866)
==13621==    by 0x278724: pyinit_core.constprop.0 (pylifecycle.c:1029)
==13621==    by 0x279113: Py_InitializeFromConfig (pylifecycle.c:1219)
==13621==    by 0x16E719: pymain_init (main.c:66)
==13621== 
==13621== 576 bytes in 1 blocks are still reachable in loss record 18 of 124
==13621==    at 0x483B7F3: malloc (in /usr/lib/x86_64-linux-gnu/valgrind/vgpreload_memcheck-amd64-linux.so)
==13621==    by 0x1C08B4: PyMem_RawMalloc (obmalloc.c:572)
==13621==    by 0x1C08B4: _PyObject_Malloc (obmalloc.c:1956)
==13621==    by 0x1C08B4: _PyObject_Malloc (obmalloc.c:1949)
==13621==    by 0x1A774F: new_keys_object (dictobject.c:600)
==13621==    by 0x1A7900: dictresize (dictobject.c:1242)
==13621==    by 0x1AFA9A: insertion_resize (dictobject.c:1060)
==13621==    by 0x1AFA9A: PyDict_SetDefault (dictobject.c:3067)
==13621==    by 0x1DFA55: type_add_getset (typeobject.c:5670)
==13621==    by 0x1DFA55: type_ready_fill_dict (typeobject.c:6105)
==13621==    by 0x1DFA55: type_ready (typeobject.c:6337)
==13621==    by 0x1D581E: PyType_Ready (typeobject.c:6370)
==13621==    by 0x1BD433: _PyTypes_Init (object.c:1839)
==13621==    by 0x275860: pycore_init_types (pylifecycle.c:699)
==13621==    by 0x275860: pycore_interp_init (pylifecycle.c:810)
==13621==    by 0x278724: pyinit_config (pylifecycle.c:866)
==13621==    by 0x278724: pyinit_core.constprop.0 (pylifecycle.c:1029)
==13621==    by 0x279113: Py_InitializeFromConfig (pylifecycle.c:1219)
==13621==    by 0x16E719: pymain_init (main.c:66)
==13621== 
==13621== 576 bytes in 1 blocks are still reachable in loss record 19 of 124
==13621==    at 0x483B7F3: malloc (in /usr/lib/x86_64-linux-gnu/valgrind/vgpreload_memcheck-amd64-linux.so)
==13621==    by 0x1C08B4: PyMem_RawMalloc (obmalloc.c:572)
==13621==    by 0x1C08B4: _PyObject_Malloc (obmalloc.c:1956)
==13621==    by 0x1C08B4: _PyObject_Malloc (obmalloc.c:1949)
==13621==    by 0x1A774F: new_keys_object (dictobject.c:600)
==13621==    by 0x1A7900: dictresize (dictobject.c:1242)
==13621==    by 0x1AFA9A: insertion_resize (dictobject.c:1060)
==13621==    by 0x1AFA9A: PyDict_SetDefault (dictobject.c:3067)
==13621==    by 0x1DFA55: type_add_getset (typeobject.c:5670)
==13621==    by 0x1DFA55: type_ready_fill_dict (typeobject.c:6105)
==13621==    by 0x1DFA55: type_ready (typeobject.c:6337)
==13621==    by 0x1D581E: PyType_Ready (typeobject.c:6370)
==13621==    by 0x1BD447: _PyTypes_Init (object.c:1840)
==13621==    by 0x275860: pycore_init_types (pylifecycle.c:699)
==13621==    by 0x275860: pycore_interp_init (pylifecycle.c:810)
==13621==    by 0x278724: pyinit_config (pylifecycle.c:866)
==13621==    by 0x278724: pyinit_core.constprop.0 (pylifecycle.c:1029)
==13621==    by 0x279113: Py_InitializeFromConfig (pylifecycle.c:1219)
==13621==    by 0x16E719: pymain_init (main.c:66)
==13621== 
==13621== 576 bytes in 1 blocks are still reachable in loss record 20 of 124
==13621==    at 0x483B7F3: malloc (in /usr/lib/x86_64-linux-gnu/valgrind/vgpreload_memcheck-amd64-linux.so)
==13621==    by 0x1C08B4: PyMem_RawMalloc (obmalloc.c:572)
==13621==    by 0x1C08B4: _PyObject_Malloc (obmalloc.c:1956)
==13621==    by 0x1C08B4: _PyObject_Malloc (obmalloc.c:1949)
==13621==    by 0x1A774F: new_keys_object (dictobject.c:600)
==13621==    by 0x1A7900: dictresize (dictobject.c:1242)
==13621==    by 0x1AB232: insertion_resize (dictobject.c:1060)
==13621==    by 0x1AB232: insertdict (dictobject.c:1103)
==13621==    by 0x1DF62E: add_operators (typeobject.c:8636)
==13621==    by 0x1DF62E: type_ready_fill_dict (typeobject.c:6096)
==13621==    by 0x1DF62E: type_ready (typeobject.c:6337)
==13621==    by 0x1D581E: PyType_Ready (typeobject.c:6370)
==13621==    by 0x1BD46F: _PyTypes_Init (object.c:1842)
==13621==    by 0x275860: pycore_init_types (pylifecycle.c:699)
==13621==    by 0x275860: pycore_interp_init (pylifecycle.c:810)
==13621==    by 0x278724: pyinit_config (pylifecycle.c:866)
==13621==    by 0x278724: pyinit_core.constprop.0 (pylifecycle.c:1029)
==13621==    by 0x279113: Py_InitializeFromConfig (pylifecycle.c:1219)
==13621==    by 0x16E719: pymain_init (main.c:66)
==13621== 
==13621== 576 bytes in 1 blocks are still reachable in loss record 21 of 124
==13621==    at 0x483B7F3: malloc (in /usr/lib/x86_64-linux-gnu/valgrind/vgpreload_memcheck-amd64-linux.so)
==13621==    by 0x1C08B4: PyMem_RawMalloc (obmalloc.c:572)
==13621==    by 0x1C08B4: _PyObject_Malloc (obmalloc.c:1956)
==13621==    by 0x1C08B4: _PyObject_Malloc (obmalloc.c:1949)
==13621==    by 0x1A774F: new_keys_object (dictobject.c:600)
==13621==    by 0x1A7900: dictresize (dictobject.c:1242)
==13621==    by 0x1AB232: insertion_resize (dictobject.c:1060)
==13621==    by 0x1AB232: insertdict (dictobject.c:1103)
==13621==    by 0x1DF62E: add_operators (typeobject.c:8636)
==13621==    by 0x1DF62E: type_ready_fill_dict (typeobject.c:6096)
==13621==    by 0x1DF62E: type_ready (typeobject.c:6337)
==13621==    by 0x1D581E: PyType_Ready (typeobject.c:6370)
==13621==    by 0x1BD523: _PyTypes_Init (object.c:1851)
==13621==    by 0x275860: pycore_init_types (pylifecycle.c:699)
==13621==    by 0x275860: pycore_interp_init (pylifecycle.c:810)
==13621==    by 0x278724: pyinit_config (pylifecycle.c:866)
==13621==    by 0x278724: pyinit_core.constprop.0 (pylifecycle.c:1029)
==13621==    by 0x279113: Py_InitializeFromConfig (pylifecycle.c:1219)
==13621==    by 0x16E719: pymain_init (main.c:66)
==13621== 
==13621== 576 bytes in 1 blocks are still reachable in loss record 22 of 124
==13621==    at 0x483B7F3: malloc (in /usr/lib/x86_64-linux-gnu/valgrind/vgpreload_memcheck-amd64-linux.so)
==13621==    by 0x1C08B4: PyMem_RawMalloc (obmalloc.c:572)
==13621==    by 0x1C08B4: _PyObject_Malloc (obmalloc.c:1956)
==13621==    by 0x1C08B4: _PyObject_Malloc (obmalloc.c:1949)
==13621==    by 0x1A774F: new_keys_object (dictobject.c:600)
==13621==    by 0x1A7900: dictresize (dictobject.c:1242)
==13621==    by 0x1AFA9A: insertion_resize (dictobject.c:1060)
==13621==    by 0x1AFA9A: PyDict_SetDefault (dictobject.c:3067)
==13621==    by 0x1DF9E5: type_add_members (typeobject.c:5645)
==13621==    by 0x1DF9E5: type_ready_fill_dict (typeobject.c:6102)
==13621==    by 0x1DF9E5: type_ready (typeobject.c:6337)
==13621==    by 0x1D581E: PyType_Ready (typeobject.c:6370)
==13621==    by 0x1BD5D7: _PyTypes_Init (object.c:1860)
==13621==    by 0x275860: pycore_init_types (pylifecycle.c:699)
==13621==    by 0x275860: pycore_interp_init (pylifecycle.c:810)
==13621==    by 0x278724: pyinit_config (pylifecycle.c:866)
==13621==    by 0x278724: pyinit_core.constprop.0 (pylifecycle.c:1029)
==13621==    by 0x279113: Py_InitializeFromConfig (pylifecycle.c:1219)
==13621==    by 0x16E719: pymain_init (main.c:66)
==13621== 
==13621== 576 bytes in 1 blocks are still reachable in loss record 23 of 124
==13621==    at 0x483B7F3: malloc (in /usr/lib/x86_64-linux-gnu/valgrind/vgpreload_memcheck-amd64-linux.so)
==13621==    by 0x1C08B4: PyMem_RawMalloc (obmalloc.c:572)
==13621==    by 0x1C08B4: _PyObject_Malloc (obmalloc.c:1956)
==13621==    by 0x1C08B4: _PyObject_Malloc (obmalloc.c:1949)
==13621==    by 0x1A774F: new_keys_object (dictobject.c:600)
==13621==    by 0x1A7900: dictresize (dictobject.c:1242)
==13621==    by 0x1AB232: insertion_resize (dictobject.c:1060)
==13621==    by 0x1AB232: insertdict (dictobject.c:1103)
==13621==    by 0x1E14D9: type_dict_set_doc (typeobject.c:6084)
==13621==    by 0x1E14D9: type_ready_fill_dict (typeobject.c:6108)
==13621==    by 0x1E14D9: type_ready (typeobject.c:6337)
==13621==    by 0x1D581E: PyType_Ready (typeobject.c:6370)
==13621==    by 0x1BD627: _PyTypes_Init (object.c:1864)
==13621==    by 0x275860: pycore_init_types (pylifecycle.c:699)
==13621==    by 0x275860: pycore_interp_init (pylifecycle.c:810)
==13621==    by 0x278724: pyinit_config (pylifecycle.c:866)
==13621==    by 0x278724: pyinit_core.constprop.0 (pylifecycle.c:1029)
==13621==    by 0x279113: Py_InitializeFromConfig (pylifecycle.c:1219)
==13621==    by 0x16E719: pymain_init (main.c:66)
==13621== 
==13621== 576 bytes in 1 blocks are still reachable in loss record 24 of 124
==13621==    at 0x483B7F3: malloc (in /usr/lib/x86_64-linux-gnu/valgrind/vgpreload_memcheck-amd64-linux.so)
==13621==    by 0x1C08B4: PyMem_RawMalloc (obmalloc.c:572)
==13621==    by 0x1C08B4: _PyObject_Malloc (obmalloc.c:1956)
==13621==    by 0x1C08B4: _PyObject_Malloc (obmalloc.c:1949)
==13621==    by 0x1A774F: new_keys_object (dictobject.c:600)
==13621==    by 0x1A7900: dictresize (dictobject.c:1242)
==13621==    by 0x1AFA9A: insertion_resize (dictobject.c:1060)
==13621==    by 0x1AFA9A: PyDict_SetDefault (dictobject.c:3067)
==13621==    by 0x1DF80E: type_add_method (typeobject.c:5597)
==13621==    by 0x1DF80E: type_add_methods (typeobject.c:5623)
==13621==    by 0x1DF80E: type_ready_fill_dict (typeobject.c:6099)
==13621==    by 0x1DF80E: type_ready (typeobject.c:6337)
==13621==    by 0x1D581E: PyType_Ready (typeobject.c:6370)
==13621==    by 0x1BD677: _PyTypes_Init (object.c:1868)
==13621==    by 0x275860: pycore_init_types (pylifecycle.c:699)
==13621==    by 0x275860: pycore_interp_init (pylifecycle.c:810)
==13621==    by 0x278724: pyinit_config (pylifecycle.c:866)
==13621==    by 0x278724: pyinit_core.constprop.0 (pylifecycle.c:1029)
==13621==    by 0x279113: Py_InitializeFromConfig (pylifecycle.c:1219)
==13621==    by 0x16E719: pymain_init (main.c:66)
==13621== 
==13621== 576 bytes in 1 blocks are still reachable in loss record 25 of 124
==13621==    at 0x483B7F3: malloc (in /usr/lib/x86_64-linux-gnu/valgrind/vgpreload_memcheck-amd64-linux.so)
==13621==    by 0x1C08B4: PyMem_RawMalloc (obmalloc.c:572)
==13621==    by 0x1C08B4: _PyObject_Malloc (obmalloc.c:1956)
==13621==    by 0x1C08B4: _PyObject_Malloc (obmalloc.c:1949)
==13621==    by 0x1A774F: new_keys_object (dictobject.c:600)
==13621==    by 0x1A7900: dictresize (dictobject.c:1242)
==13621==    by 0x1AB232: insertion_resize (dictobject.c:1060)
==13621==    by 0x1AB232: insertdict (dictobject.c:1103)
==13621==    by 0x1E14D9: type_dict_set_doc (typeobject.c:6084)
==13621==    by 0x1E14D9: type_ready_fill_dict (typeobject.c:6108)
==13621==    by 0x1E14D9: type_ready (typeobject.c:6337)
==13621==    by 0x1D581E: PyType_Ready (typeobject.c:6370)
==13621==    by 0x1BD69F: _PyTypes_Init (object.c:1870)
==13621==    by 0x275860: pycore_init_types (pylifecycle.c:699)
==13621==    by 0x275860: pycore_interp_init (pylifecycle.c:810)
==13621==    by 0x278724: pyinit_config (pylifecycle.c:866)
==13621==    by 0x278724: pyinit_core.constprop.0 (pylifecycle.c:1029)
==13621==    by 0x279113: Py_InitializeFromConfig (pylifecycle.c:1219)
==13621==    by 0x16E719: pymain_init (main.c:66)
==13621== 
==13621== 576 bytes in 1 blocks are still reachable in loss record 26 of 124
==13621==    at 0x483B7F3: malloc (in /usr/lib/x86_64-linux-gnu/valgrind/vgpreload_memcheck-amd64-linux.so)
==13621==    by 0x1C08B4: PyMem_RawMalloc (obmalloc.c:572)
==13621==    by 0x1C08B4: _PyObject_Malloc (obmalloc.c:1956)
==13621==    by 0x1C08B4: _PyObject_Malloc (obmalloc.c:1949)
==13621==    by 0x1A774F: new_keys_object (dictobject.c:600)
==13621==    by 0x1A7900: dictresize (dictobject.c:1242)
==13621==    by 0x1AB232: insertion_resize (dictobject.c:1060)
==13621==    by 0x1AB232: insertdict (dictobject.c:1103)
==13621==    by 0x1DF62E: add_operators (typeobject.c:8636)
==13621==    by 0x1DF62E: type_ready_fill_dict (typeobject.c:6096)
==13621==    by 0x1DF62E: type_ready (typeobject.c:6337)
==13621==    by 0x1D581E: PyType_Ready (typeobject.c:6370)
==13621==    by 0x1BD7B7: _PyTypes_Init (object.c:1884)
==13621==    by 0x275860: pycore_init_types (pylifecycle.c:699)
==13621==    by 0x275860: pycore_interp_init (pylifecycle.c:810)
==13621==    by 0x278724: pyinit_config (pylifecycle.c:866)
==13621==    by 0x278724: pyinit_core.constprop.0 (pylifecycle.c:1029)
==13621==    by 0x279113: Py_InitializeFromConfig (pylifecycle.c:1219)
==13621==    by 0x16E719: pymain_init (main.c:66)
==13621== 
==13621== 576 bytes in 1 blocks are still reachable in loss record 27 of 124
==13621==    at 0x483B7F3: malloc (in /usr/lib/x86_64-linux-gnu/valgrind/vgpreload_memcheck-amd64-linux.so)
==13621==    by 0x1C08B4: PyMem_RawMalloc (obmalloc.c:572)
==13621==    by 0x1C08B4: _PyObject_Malloc (obmalloc.c:1956)
==13621==    by 0x1C08B4: _PyObject_Malloc (obmalloc.c:1949)
==13621==    by 0x1A774F: new_keys_object (dictobject.c:600)
==13621==    by 0x1A7900: dictresize (dictobject.c:1242)
==13621==    by 0x1AFA9A: insertion_resize (dictobject.c:1060)
==13621==    by 0x1AFA9A: PyDict_SetDefault (dictobject.c:3067)
==13621==    by 0x1DF80E: type_add_method (typeobject.c:5597)
==13621==    by 0x1DF80E: type_add_methods (typeobject.c:5623)
==13621==    by 0x1DF80E: type_ready_fill_dict (typeobject.c:6099)
==13621==    by 0x1DF80E: type_ready (typeobject.c:6337)
==13621==    by 0x1D581E: PyType_Ready (typeobject.c:6370)
==13621==    by 0x1BD7DF: _PyTypes_Init (object.c:1886)
==13621==    by 0x275860: pycore_init_types (pylifecycle.c:699)
==13621==    by 0x275860: pycore_interp_init (pylifecycle.c:810)
==13621==    by 0x278724: pyinit_config (pylifecycle.c:866)
==13621==    by 0x278724: pyinit_core.constprop.0 (pylifecycle.c:1029)
==13621==    by 0x279113: Py_InitializeFromConfig (pylifecycle.c:1219)
==13621==    by 0x16E719: pymain_init (main.c:66)
==13621== 
==13621== 576 bytes in 1 blocks are still reachable in loss record 28 of 124
==13621==    at 0x483B7F3: malloc (in /usr/lib/x86_64-linux-gnu/valgrind/vgpreload_memcheck-amd64-linux.so)
==13621==    by 0x1C08B4: PyMem_RawMalloc (obmalloc.c:572)
==13621==    by 0x1C08B4: _PyObject_Malloc (obmalloc.c:1956)
==13621==    by 0x1C08B4: _PyObject_Malloc (obmalloc.c:1949)
==13621==    by 0x1A774F: new_keys_object (dictobject.c:600)
==13621==    by 0x1A7900: dictresize (dictobject.c:1242)
==13621==    by 0x1AB232: insertion_resize (dictobject.c:1060)
==13621==    by 0x1AB232: insertdict (dictobject.c:1103)
==13621==    by 0x1DF62E: add_operators (typeobject.c:8636)
==13621==    by 0x1DF62E: type_ready_fill_dict (typeobject.c:6096)
==13621==    by 0x1DF62E: type_ready (typeobject.c:6337)
==13621==    by 0x1D581E: PyType_Ready (typeobject.c:6370)
==13621==    by 0x1BD7F3: _PyTypes_Init (object.c:1887)
==13621==    by 0x275860: pycore_init_types (pylifecycle.c:699)
==13621==    by 0x275860: pycore_interp_init (pylifecycle.c:810)
==13621==    by 0x278724: pyinit_config (pylifecycle.c:866)
==13621==    by 0x278724: pyinit_core.constprop.0 (pylifecycle.c:1029)
==13621==    by 0x279113: Py_InitializeFromConfig (pylifecycle.c:1219)
==13621==    by 0x16E719: pymain_init (main.c:66)
==13621== 
==13621== 576 bytes in 1 blocks are still reachable in loss record 29 of 124
==13621==    at 0x483B7F3: malloc (in /usr/lib/x86_64-linux-gnu/valgrind/vgpreload_memcheck-amd64-linux.so)
==13621==    by 0x1C08B4: PyMem_RawMalloc (obmalloc.c:572)
==13621==    by 0x1C08B4: _PyObject_Malloc (obmalloc.c:1956)
==13621==    by 0x1C08B4: _PyObject_Malloc (obmalloc.c:1949)
==13621==    by 0x1A774F: new_keys_object (dictobject.c:600)
==13621==    by 0x1A7900: dictresize (dictobject.c:1242)
==13621==    by 0x1AB232: insertion_resize (dictobject.c:1060)
==13621==    by 0x1AB232: insertdict (dictobject.c:1103)
==13621==    by 0x1DF62E: add_operators (typeobject.c:8636)
==13621==    by 0x1DF62E: type_ready_fill_dict (typeobject.c:6096)
==13621==    by 0x1DF62E: type_ready (typeobject.c:6337)
==13621==    by 0x1D581E: PyType_Ready (typeobject.c:6370)
==13621==    by 0x1BD857: _PyTypes_Init (object.c:1892)
==13621==    by 0x275860: pycore_init_types (pylifecycle.c:699)
==13621==    by 0x275860: pycore_interp_init (pylifecycle.c:810)
==13621==    by 0x278724: pyinit_config (pylifecycle.c:866)
==13621==    by 0x278724: pyinit_core.constprop.0 (pylifecycle.c:1029)
==13621==    by 0x279113: Py_InitializeFromConfig (pylifecycle.c:1219)
==13621==    by 0x16E719: pymain_init (main.c:66)
==13621== 
==13621== 576 bytes in 1 blocks are still reachable in loss record 30 of 124
==13621==    at 0x483B7F3: malloc (in /usr/lib/x86_64-linux-gnu/valgrind/vgpreload_memcheck-amd64-linux.so)
==13621==    by 0x1C08B4: PyMem_RawMalloc (obmalloc.c:572)
==13621==    by 0x1C08B4: _PyObject_Malloc (obmalloc.c:1956)
==13621==    by 0x1C08B4: _PyObject_Malloc (obmalloc.c:1949)
==13621==    by 0x1A774F: new_keys_object (dictobject.c:600)
==13621==    by 0x1A7900: dictresize (dictobject.c:1242)
==13621==    by 0x1AB232: insertion_resize (dictobject.c:1060)
==13621==    by 0x1AB232: insertdict (dictobject.c:1103)
==13621==    by 0x1DF62E: add_operators (typeobject.c:8636)
==13621==    by 0x1DF62E: type_ready_fill_dict (typeobject.c:6096)
==13621==    by 0x1DF62E: type_ready (typeobject.c:6337)
==13621==    by 0x1D581E: PyType_Ready (typeobject.c:6370)
==13621==    by 0x1BD86B: _PyTypes_Init (object.c:1893)
==13621==    by 0x275860: pycore_init_types (pylifecycle.c:699)
==13621==    by 0x275860: pycore_interp_init (pylifecycle.c:810)
==13621==    by 0x278724: pyinit_config (pylifecycle.c:866)
==13621==    by 0x278724: pyinit_core.constprop.0 (pylifecycle.c:1029)
==13621==    by 0x279113: Py_InitializeFromConfig (pylifecycle.c:1219)
==13621==    by 0x16E719: pymain_init (main.c:66)
==13621== 
==13621== 576 bytes in 1 blocks are still reachable in loss record 31 of 124
==13621==    at 0x483B7F3: malloc (in /usr/lib/x86_64-linux-gnu/valgrind/vgpreload_memcheck-amd64-linux.so)
==13621==    by 0x1C08B4: PyMem_RawMalloc (obmalloc.c:572)
==13621==    by 0x1C08B4: _PyObject_Malloc (obmalloc.c:1956)
==13621==    by 0x1C08B4: _PyObject_Malloc (obmalloc.c:1949)
==13621==    by 0x1A774F: new_keys_object (dictobject.c:600)
==13621==    by 0x1A7900: dictresize (dictobject.c:1242)
==13621==    by 0x1AFA9A: insertion_resize (dictobject.c:1060)
==13621==    by 0x1AFA9A: PyDict_SetDefault (dictobject.c:3067)
==13621==    by 0x1DF9E5: type_add_members (typeobject.c:5645)
==13621==    by 0x1DF9E5: type_ready_fill_dict (typeobject.c:6102)
==13621==    by 0x1DF9E5: type_ready (typeobject.c:6337)
==13621==    by 0x1D581E: PyType_Ready (typeobject.c:6370)
==13621==    by 0x1CC6F1: _PyStructSequence_InitType (structseq.c:506)
==13621==    by 0x18E41E: _PyFloat_InitTypes (floatobject.c:2026)
==13621==    by 0x275967: pycore_init_types (pylifecycle.c:715)
==13621==    by 0x275967: pycore_interp_init (pylifecycle.c:810)
==13621==    by 0x278724: pyinit_config (pylifecycle.c:866)
==13621==    by 0x278724: pyinit_core.constprop.0 (pylifecycle.c:1029)
==13621==    by 0x279113: Py_InitializeFromConfig (pylifecycle.c:1219)
==13621== 
==13621== 576 bytes in 1 blocks are still reachable in loss record 32 of 124
==13621==    at 0x483B7F3: malloc (in /usr/lib/x86_64-linux-gnu/valgrind/vgpreload_memcheck-amd64-linux.so)
==13621==    by 0x1C08B4: PyMem_RawMalloc (obmalloc.c:572)
==13621==    by 0x1C08B4: _PyObject_Malloc (obmalloc.c:1956)
==13621==    by 0x1C08B4: _PyObject_Malloc (obmalloc.c:1949)
==13621==    by 0x1A774F: new_keys_object (dictobject.c:600)
==13621==    by 0x1A7900: dictresize (dictobject.c:1242)
==13621==    by 0x1AFA9A: insertion_resize (dictobject.c:1060)
==13621==    by 0x1AFA9A: PyDict_SetDefault (dictobject.c:3067)
==13621==    by 0x1DF9E5: type_add_members (typeobject.c:5645)
==13621==    by 0x1DF9E5: type_ready_fill_dict (typeobject.c:6102)
==13621==    by 0x1DF9E5: type_ready (typeobject.c:6337)
==13621==    by 0x1D581E: PyType_Ready (typeobject.c:6370)
==13621==    by 0x18771B: _PyExc_Init (exceptions.c:2687)
==13621==    by 0x27560D: pycore_init_types (pylifecycle.c:720)
==13621==    by 0x27560D: pycore_interp_init (pylifecycle.c:810)
==13621==    by 0x278724: pyinit_config (pylifecycle.c:866)
==13621==    by 0x278724: pyinit_core.constprop.0 (pylifecycle.c:1029)
==13621==    by 0x279113: Py_InitializeFromConfig (pylifecycle.c:1219)
==13621==    by 0x16E719: pymain_init (main.c:66)
==13621== 
==13621== 576 bytes in 1 blocks are still reachable in loss record 33 of 124
==13621==    at 0x483B7F3: malloc (in /usr/lib/x86_64-linux-gnu/valgrind/vgpreload_memcheck-amd64-linux.so)
==13621==    by 0x1C08B4: PyMem_RawMalloc (obmalloc.c:572)
==13621==    by 0x1C08B4: _PyObject_Malloc (obmalloc.c:1956)
==13621==    by 0x1C08B4: _PyObject_Malloc (obmalloc.c:1949)
==13621==    by 0x1A774F: new_keys_object (dictobject.c:600)
==13621==    by 0x1A7900: dictresize (dictobject.c:1242)
==13621==    by 0x1AB232: insertion_resize (dictobject.c:1060)
==13621==    by 0x1AB232: insertdict (dictobject.c:1103)
==13621==    by 0x1DFB69: type_dict_set_doc (typeobject.c:6077)
==13621==    by 0x1DFB69: type_ready_fill_dict (typeobject.c:6108)
==13621==    by 0x1DFB69: type_ready (typeobject.c:6337)
==13621==    by 0x1D581E: PyType_Ready (typeobject.c:6370)
==13621==    by 0x1879A3: _PyExc_Init (exceptions.c:2705)
==13621==    by 0x27560D: pycore_init_types (pylifecycle.c:720)
==13621==    by 0x27560D: pycore_interp_init (pylifecycle.c:810)
==13621==    by 0x278724: pyinit_config (pylifecycle.c:866)
==13621==    by 0x278724: pyinit_core.constprop.0 (pylifecycle.c:1029)
==13621==    by 0x279113: Py_InitializeFromConfig (pylifecycle.c:1219)
==13621==    by 0x16E719: pymain_init (main.c:66)
==13621== 
==13621== 576 bytes in 1 blocks are still reachable in loss record 34 of 124
==13621==    at 0x483B7F3: malloc (in /usr/lib/x86_64-linux-gnu/valgrind/vgpreload_memcheck-amd64-linux.so)
==13621==    by 0x1C08B4: PyMem_RawMalloc (obmalloc.c:572)
==13621==    by 0x1C08B4: _PyObject_Malloc (obmalloc.c:1956)
==13621==    by 0x1C08B4: _PyObject_Malloc (obmalloc.c:1949)
==13621==    by 0x1A774F: new_keys_object (dictobject.c:600)
==13621==    by 0x1A7900: dictresize (dictobject.c:1242)
==13621==    by 0x1AB232: insertion_resize (dictobject.c:1060)
==13621==    by 0x1AB232: insertdict (dictobject.c:1103)
==13621==    by 0x1D07EC: add_subclass.isra.0 (typeobject.c:6406)
==13621==    by 0x1E0219: type_ready_add_subclasses (typeobject.c:6256)
==13621==    by 0x1E0219: type_ready (typeobject.c:6346)
==13621==    by 0x1D581E: PyType_Ready (typeobject.c:6370)
==13621==    by 0x187E4F: _PyExc_Init (exceptions.c:2736)
==13621==    by 0x27560D: pycore_init_types (pylifecycle.c:720)
==13621==    by 0x27560D: pycore_interp_init (pylifecycle.c:810)
==13621==    by 0x278724: pyinit_config (pylifecycle.c:866)
==13621==    by 0x278724: pyinit_core.constprop.0 (pylifecycle.c:1029)
==13621==    by 0x279113: Py_InitializeFromConfig (pylifecycle.c:1219)
==13621== 
==13621== 576 bytes in 1 blocks are still reachable in loss record 35 of 124
==13621==    at 0x483B7F3: malloc (in /usr/lib/x86_64-linux-gnu/valgrind/vgpreload_memcheck-amd64-linux.so)
==13621==    by 0x1C08B4: PyMem_RawMalloc (obmalloc.c:572)
==13621==    by 0x1C08B4: _PyObject_Malloc (obmalloc.c:1956)
==13621==    by 0x1C08B4: _PyObject_Malloc (obmalloc.c:1949)
==13621==    by 0x1A774F: new_keys_object (dictobject.c:600)
==13621==    by 0x1A7900: dictresize (dictobject.c:1242)
==13621==    by 0x1AB232: insertion_resize (dictobject.c:1060)
==13621==    by 0x1AB232: insertdict (dictobject.c:1103)
==13621==    by 0x1D07EC: add_subclass.isra.0 (typeobject.c:6406)
==13621==    by 0x1E0219: type_ready_add_subclasses (typeobject.c:6256)
==13621==    by 0x1E0219: type_ready (typeobject.c:6346)
==13621==    by 0x1D581E: PyType_Ready (typeobject.c:6370)
==13621==    by 0x1874E2: _PyExc_Init (exceptions.c:2754)
==13621==    by 0x27560D: pycore_init_types (pylifecycle.c:720)
==13621==    by 0x27560D: pycore_interp_init (pylifecycle.c:810)
==13621==    by 0x278724: pyinit_config (pylifecycle.c:866)
==13621==    by 0x278724: pyinit_core.constprop.0 (pylifecycle.c:1029)
==13621==    by 0x279113: Py_InitializeFromConfig (pylifecycle.c:1219)
==13621== 
==13621== 576 bytes in 1 blocks are still reachable in loss record 36 of 124
==13621==    at 0x483B7F3: malloc (in /usr/lib/x86_64-linux-gnu/valgrind/vgpreload_memcheck-amd64-linux.so)
==13621==    by 0x1C08B4: PyMem_RawMalloc (obmalloc.c:572)
==13621==    by 0x1C08B4: _PyObject_Malloc (obmalloc.c:1956)
==13621==    by 0x1C08B4: _PyObject_Malloc (obmalloc.c:1949)
==13621==    by 0x1A774F: new_keys_object (dictobject.c:600)
==13621==    by 0x1A7900: dictresize (dictobject.c:1242)
==13621==    by 0x1AB232: insertion_resize (dictobject.c:1060)
==13621==    by 0x1AB232: insertdict (dictobject.c:1103)
==13621==    by 0x1B08C5: PyDict_SetItem (dictobject.c:1623)
==13621==    by 0x1B08C5: PyDict_SetItemString (dictobject.c:3614)
==13621==    by 0x1CB842: initialize_structseq_dict.isra.0 (structseq.c:402)
==13621==    by 0x1CC718: _PyStructSequence_InitType (structseq.c:512)
==13621==    by 0x256362: _PyErr_InitTypes (errors.c:1225)
==13621==    by 0x275687: pycore_init_types (pylifecycle.c:725)
==13621==    by 0x275687: pycore_interp_init (pylifecycle.c:810)
==13621==    by 0x278724: pyinit_config (pylifecycle.c:866)
==13621==    by 0x278724: pyinit_core.constprop.0 (pylifecycle.c:1029)
==13621==    by 0x279113: Py_InitializeFromConfig (pylifecycle.c:1219)
==13621== 
==13621== 576 bytes in 1 blocks are still reachable in loss record 37 of 124
==13621==    at 0x483B7F3: malloc (in /usr/lib/x86_64-linux-gnu/valgrind/vgpreload_memcheck-amd64-linux.so)
==13621==    by 0x1C08B4: PyMem_RawMalloc (obmalloc.c:572)
==13621==    by 0x1C08B4: _PyObject_Malloc (obmalloc.c:1956)
==13621==    by 0x1C08B4: _PyObject_Malloc (obmalloc.c:1949)
==13621==    by 0x1A774F: new_keys_object (dictobject.c:600)
==13621==    by 0x1A7900: dictresize (dictobject.c:1242)
==13621==    by 0x1AB232: insertion_resize (dictobject.c:1060)
==13621==    by 0x1AB232: insertdict (dictobject.c:1103)
==13621==    by 0x1DF62E: add_operators (typeobject.c:8636)
==13621==    by 0x1DF62E: type_ready_fill_dict (typeobject.c:6096)
==13621==    by 0x1DF62E: type_ready (typeobject.c:6337)
==13621==    by 0x1D581E: PyType_Ready (typeobject.c:6370)
==13621==    by 0x387063: _PyHamt_Init (hamt.c:2958)
==13621==    by 0x383D1D: _PyContext_Init (context.c:1320)
==13621==    by 0x2757D4: pycore_init_types (pylifecycle.c:731)
==13621==    by 0x2757D4: pycore_interp_init (pylifecycle.c:810)
==13621==    by 0x278724: pyinit_config (pylifecycle.c:866)
==13621==    by 0x278724: pyinit_core.constprop.0 (pylifecycle.c:1029)
==13621==    by 0x279113: Py_InitializeFromConfig (pylifecycle.c:1219)
==13621== 
==13621== 576 bytes in 1 blocks are still reachable in loss record 38 of 124
==13621==    at 0x483B7F3: malloc (in /usr/lib/x86_64-linux-gnu/valgrind/vgpreload_memcheck-amd64-linux.so)
==13621==    by 0x1C08B4: PyMem_RawMalloc (obmalloc.c:572)
==13621==    by 0x1C08B4: _PyObject_Malloc (obmalloc.c:1956)
==13621==    by 0x1C08B4: _PyObject_Malloc (obmalloc.c:1949)
==13621==    by 0x1A774F: new_keys_object (dictobject.c:600)
==13621==    by 0x1A7900: dictresize (dictobject.c:1242)
==13621==    by 0x1AB232: insertion_resize (dictobject.c:1060)
==13621==    by 0x1AB232: insertdict (dictobject.c:1103)
==13621==    by 0x1DF62E: add_operators (typeobject.c:8636)
==13621==    by 0x1DF62E: type_ready_fill_dict (typeobject.c:6096)
==13621==    by 0x1DF62E: type_ready (typeobject.c:6337)
==13621==    by 0x1D581E: PyType_Ready (typeobject.c:6370)
==13621==    by 0x383D3B: _PyContext_Init (context.c:1324)
==13621==    by 0x2757D4: pycore_init_types (pylifecycle.c:731)
==13621==    by 0x2757D4: pycore_interp_init (pylifecycle.c:810)
==13621==    by 0x278724: pyinit_config (pylifecycle.c:866)
==13621==    by 0x278724: pyinit_core.constprop.0 (pylifecycle.c:1029)
==13621==    by 0x279113: Py_InitializeFromConfig (pylifecycle.c:1219)
==13621==    by 0x16E719: pymain_init (main.c:66)
==13621== 
==13621== 576 bytes in 1 blocks are still reachable in loss record 39 of 124
==13621==    at 0x483B7F3: malloc (in /usr/lib/x86_64-linux-gnu/valgrind/vgpreload_memcheck-amd64-linux.so)
==13621==    by 0x1C08B4: PyMem_RawMalloc (obmalloc.c:572)
==13621==    by 0x1C08B4: _PyObject_Malloc (obmalloc.c:1956)
==13621==    by 0x1C08B4: _PyObject_Malloc (obmalloc.c:1949)
==13621==    by 0x1A774F: new_keys_object (dictobject.c:600)
==13621==    by 0x1A7900: dictresize (dictobject.c:1242)
==13621==    by 0x1AFA9A: insertion_resize (dictobject.c:1060)
==13621==    by 0x1AFA9A: PyDict_SetDefault (dictobject.c:3067)
==13621==    by 0x1DF9E5: type_add_members (typeobject.c:5645)
==13621==    by 0x1DF9E5: type_ready_fill_dict (typeobject.c:6102)
==13621==    by 0x1DF9E5: type_ready (typeobject.c:6337)
==13621==    by 0x1D581E: PyType_Ready (typeobject.c:6370)
==13621==    by 0x1CC6F1: _PyStructSequence_InitType (structseq.c:506)
==13621==    by 0x28DDA9: _PySys_InitCore (sysmodule.c:2790)
==13621==    by 0x28DDA9: _PySys_Create (sysmodule.c:3070)
==13621==    by 0x27572F: pycore_interp_init (pylifecycle.c:824)
==13621==    by 0x278724: pyinit_config (pylifecycle.c:866)
==13621==    by 0x278724: pyinit_core.constprop.0 (pylifecycle.c:1029)
==13621==    by 0x279113: Py_InitializeFromConfig (pylifecycle.c:1219)
==13621== 
==13621== 576 bytes in 1 blocks are still reachable in loss record 40 of 124
==13621==    at 0x483B7F3: malloc (in /usr/lib/x86_64-linux-gnu/valgrind/vgpreload_memcheck-amd64-linux.so)
==13621==    by 0x1C08B4: PyMem_RawMalloc (obmalloc.c:572)
==13621==    by 0x1C08B4: _PyObject_Malloc (obmalloc.c:1956)
==13621==    by 0x1C08B4: _PyObject_Malloc (obmalloc.c:1949)
==13621==    by 0x1A774F: new_keys_object (dictobject.c:600)
==13621==    by 0x1A7900: dictresize (dictobject.c:1242)
==13621==    by 0x1AB232: insertion_resize (dictobject.c:1060)
==13621==    by 0x1AB232: insertdict (dictobject.c:1103)
==13621==    by 0x1B08C5: PyDict_SetItem (dictobject.c:1623)
==13621==    by 0x1B08C5: PyDict_SetItemString (dictobject.c:3614)
==13621==    by 0x1CB882: initialize_structseq_dict.isra.0 (structseq.c:403)
==13621==    by 0x1CC718: _PyStructSequence_InitType (structseq.c:512)
==13621==    by 0x28E4AA: _PySys_InitCore (sysmodule.c:2814)
==13621==    by 0x28E4AA: _PySys_Create (sysmodule.c:3070)
==13621==    by 0x27572F: pycore_interp_init (pylifecycle.c:824)
==13621==    by 0x278724: pyinit_config (pylifecycle.c:866)
==13621==    by 0x278724: pyinit_core.constprop.0 (pylifecycle.c:1029)
==13621==    by 0x279113: Py_InitializeFromConfig (pylifecycle.c:1219)
==13621== 
==13621== 576 bytes in 1 blocks are still reachable in loss record 41 of 124
==13621==    at 0x483B7F3: malloc (in /usr/lib/x86_64-linux-gnu/valgrind/vgpreload_memcheck-amd64-linux.so)
==13621==    by 0x1C08B4: PyMem_RawMalloc (obmalloc.c:572)
==13621==    by 0x1C08B4: _PyObject_Malloc (obmalloc.c:1956)
==13621==    by 0x1C08B4: _PyObject_Malloc (obmalloc.c:1949)
==13621==    by 0x1A774F: new_keys_object (dictobject.c:600)
==13621==    by 0x1A7900: dictresize (dictobject.c:1242)
==13621==    by 0x1AB232: insertion_resize (dictobject.c:1060)
==13621==    by 0x1AB232: insertdict (dictobject.c:1103)
==13621==    by 0x1B08C5: PyDict_SetItem (dictobject.c:1623)
==13621==    by 0x1B08C5: PyDict_SetItemString (dictobject.c:3614)
==13621==    by 0x1CB92E: initialize_structseq_dict.isra.0 (structseq.c:428)
==13621==    by 0x1CC718: _PyStructSequence_InitType (structseq.c:512)
==13621==    by 0x28F9BA: PyThread_GetInfo (thread.c:197)
==13621==    by 0x28E2BB: _PySys_InitCore (sysmodule.c:2853)
==13621==    by 0x28E2BB: _PySys_Create (sysmodule.c:3070)
==13621==    by 0x27572F: pycore_interp_init (pylifecycle.c:824)
==13621==    by 0x278724: pyinit_config (pylifecycle.c:866)
==13621==    by 0x278724: pyinit_core.constprop.0 (pylifecycle.c:1029)
==13621== 
==13621== 576 bytes in 1 blocks are still reachable in loss record 42 of 124
==13621==    at 0x483B7F3: malloc (in /usr/lib/x86_64-linux-gnu/valgrind/vgpreload_memcheck-amd64-linux.so)
==13621==    by 0x1C08B4: PyMem_RawMalloc (obmalloc.c:572)
==13621==    by 0x1C08B4: _PyObject_Malloc (obmalloc.c:1956)
==13621==    by 0x1C08B4: _PyObject_Malloc (obmalloc.c:1949)
==13621==    by 0x1A774F: new_keys_object (dictobject.c:600)
==13621==    by 0x1A7900: dictresize (dictobject.c:1242)
==13621==    by 0x1AFA9A: insertion_resize (dictobject.c:1060)
==13621==    by 0x1AFA9A: PyDict_SetDefault (dictobject.c:3067)
==13621==    by 0x1DFA55: type_add_getset (typeobject.c:5670)
==13621==    by 0x1DFA55: type_ready_fill_dict (typeobject.c:6105)
==13621==    by 0x1DFA55: type_ready (typeobject.c:6337)
==13621==    by 0x1E3212: PyType_Ready (typeobject.c:6370)
==13621==    by 0x1E3212: type_new_impl (typeobject.c:3186)
==13621==    by 0x1E3212: type_new (typeobject.c:3325)
==13621==    by 0x1D3538: type_call (typeobject.c:1121)
==13621==    by 0x17FC2B: _PyObject_MakeTpCall (call.c:215)
==13621==    by 0x180475: _PyObject_FastCallDictTstate (call.c:142)
==13621==    by 0x180475: PyObject_VectorcallDict (call.c:166)
==13621==    by 0x37E34C: builtin___build_class__ (bltinmodule.c:224)
==13621==    by 0x345669: cfunction_vectorcall_FASTCALL_KEYWORDS (methodobject.c:446)
==13621== 
==13621== 576 bytes in 1 blocks are still reachable in loss record 43 of 124
==13621==    at 0x483B7F3: malloc (in /usr/lib/x86_64-linux-gnu/valgrind/vgpreload_memcheck-amd64-linux.so)
==13621==    by 0x1C08B4: PyMem_RawMalloc (obmalloc.c:572)
==13621==    by 0x1C08B4: _PyObject_Malloc (obmalloc.c:1956)
==13621==    by 0x1C08B4: _PyObject_Malloc (obmalloc.c:1949)
==13621==    by 0x1A774F: new_keys_object (dictobject.c:600)
==13621==    by 0x1A7900: dictresize (dictobject.c:1242)
==13621==    by 0x1AB232: insertion_resize (dictobject.c:1060)
==13621==    by 0x1AB232: insertdict (dictobject.c:1103)
==13621==    by 0x1B08C5: PyDict_SetItem (dictobject.c:1623)
==13621==    by 0x1B08C5: PyDict_SetItemString (dictobject.c:3614)
==13621==    by 0x1CB882: initialize_structseq_dict.isra.0 (structseq.c:403)
==13621==    by 0x1CC718: _PyStructSequence_InitType (structseq.c:512)
==13621==    by 0x2EC66A: thread_module_exec (_threadmodule.c:1629)
==13621==    by 0x1B9056: PyModule_ExecDef (moduleobject.c:407)
==13621==    by 0x25EA72: _imp_exec_builtin (import.c.h:64)
==13621==    by 0x345556: cfunction_vectorcall_O (methodobject.c:516)
==13621== 
==13621== 576 bytes in 1 blocks are still reachable in loss record 44 of 124
==13621==    at 0x483B7F3: malloc (in /usr/lib/x86_64-linux-gnu/valgrind/vgpreload_memcheck-amd64-linux.so)
==13621==    by 0x1C08B4: PyMem_RawMalloc (obmalloc.c:572)
==13621==    by 0x1C08B4: _PyObject_Malloc (obmalloc.c:1956)
==13621==    by 0x1C08B4: _PyObject_Malloc (obmalloc.c:1949)
==13621==    by 0x1A774F: new_keys_object (dictobject.c:600)
==13621==    by 0x1A7900: dictresize (dictobject.c:1242)
==13621==    by 0x1AFA9A: insertion_resize (dictobject.c:1060)
==13621==    by 0x1AFA9A: PyDict_SetDefault (dictobject.c:3067)
==13621==    by 0x1DF80E: type_add_method (typeobject.c:5597)
==13621==    by 0x1DF80E: type_add_methods (typeobject.c:5623)
==13621==    by 0x1DF80E: type_ready_fill_dict (typeobject.c:6099)
==13621==    by 0x1DF80E: type_ready (typeobject.c:6337)
==13621==    by 0x1D581E: PyType_Ready (typeobject.c:6370)
==13621==    by 0x271AE6: PyModule_AddType (modsupport.c:706)
==13621==    by 0x2F1275: PyInit__io (_iomodule.c:747)
==13621==    by 0x25FD67: create_builtin.part.0 (import.c:1012)
==13621==    by 0x25FE7C: create_builtin (import.c:1000)
==13621==    by 0x25FE7C: _imp_create_builtin (import.c:1063)
==13621==    by 0x345556: cfunction_vectorcall_O (methodobject.c:516)
==13621== 
==13621== 576 bytes in 1 blocks are still reachable in loss record 45 of 124
==13621==    at 0x483B7F3: malloc (in /usr/lib/x86_64-linux-gnu/valgrind/vgpreload_memcheck-amd64-linux.so)
==13621==    by 0x1C08B4: PyMem_RawMalloc (obmalloc.c:572)
==13621==    by 0x1C08B4: _PyObject_Malloc (obmalloc.c:1956)
==13621==    by 0x1C08B4: _PyObject_Malloc (obmalloc.c:1949)
==13621==    by 0x1A774F: new_keys_object (dictobject.c:600)
==13621==    by 0x1A7900: dictresize (dictobject.c:1242)
==13621==    by 0x1AFA9A: insertion_resize (dictobject.c:1060)
==13621==    by 0x1AFA9A: PyDict_SetDefault (dictobject.c:3067)
==13621==    by 0x1DF80E: type_add_method (typeobject.c:5597)
==13621==    by 0x1DF80E: type_add_methods (typeobject.c:5623)
==13621==    by 0x1DF80E: type_ready_fill_dict (typeobject.c:6099)
==13621==    by 0x1DF80E: type_ready (typeobject.c:6337)
==13621==    by 0x1D581E: PyType_Ready (typeobject.c:6370)
==13621==    by 0x271AE6: PyModule_AddType (modsupport.c:706)
==13621==    by 0x2F12CF: PyInit__io (_iomodule.c:765)
==13621==    by 0x25FD67: create_builtin.part.0 (import.c:1012)
==13621==    by 0x25FE7C: create_builtin (import.c:1000)
==13621==    by 0x25FE7C: _imp_create_builtin (import.c:1063)
==13621==    by 0x345556: cfunction_vectorcall_O (methodobject.c:516)
==13621== 
==13621== 576 bytes in 1 blocks are still reachable in loss record 46 of 124
==13621==    at 0x483B7F3: malloc (in /usr/lib/x86_64-linux-gnu/valgrind/vgpreload_memcheck-amd64-linux.so)
==13621==    by 0x1C08B4: PyMem_RawMalloc (obmalloc.c:572)
==13621==    by 0x1C08B4: _PyObject_Malloc (obmalloc.c:1956)
==13621==    by 0x1C08B4: _PyObject_Malloc (obmalloc.c:1949)
==13621==    by 0x1A774F: new_keys_object (dictobject.c:600)
==13621==    by 0x1A7900: dictresize (dictobject.c:1242)
==13621==    by 0x1AB232: insertion_resize (dictobject.c:1060)
==13621==    by 0x1AB232: insertdict (dictobject.c:1103)
==13621==    by 0x1D07EC: add_subclass.isra.0 (typeobject.c:6406)
==13621==    by 0x1E0219: type_ready_add_subclasses (typeobject.c:6256)
==13621==    by 0x1E0219: type_ready (typeobject.c:6346)
==13621==    by 0x1D581E: PyType_Ready (typeobject.c:6370)
==13621==    by 0x1E1E70: PyType_FromModuleAndSpec (typeobject.c:3559)
==13621==    by 0x1CC9D0: PyStructSequence_NewType (structseq.c:571)
==13621==    by 0x2ABD1A: posixmodule_exec (posixmodule.c:15680)
==13621==    by 0x1B9056: PyModule_ExecDef (moduleobject.c:407)
==13621== 
==13621== 576 bytes in 1 blocks are still reachable in loss record 47 of 124
==13621==    at 0x483B7F3: malloc (in /usr/lib/x86_64-linux-gnu/valgrind/vgpreload_memcheck-amd64-linux.so)
==13621==    by 0x1C08B4: PyMem_RawMalloc (obmalloc.c:572)
==13621==    by 0x1C08B4: _PyObject_Malloc (obmalloc.c:1956)
==13621==    by 0x1C08B4: _PyObject_Malloc (obmalloc.c:1949)
==13621==    by 0x1A774F: new_keys_object (dictobject.c:600)
==13621==    by 0x1A7900: dictresize (dictobject.c:1242)
==13621==    by 0x1AFA9A: insertion_resize (dictobject.c:1060)
==13621==    by 0x1AFA9A: PyDict_SetDefault (dictobject.c:3067)
==13621==    by 0x1DF9E5: type_add_members (typeobject.c:5645)
==13621==    by 0x1DF9E5: type_ready_fill_dict (typeobject.c:6102)
==13621==    by 0x1DF9E5: type_ready (typeobject.c:6337)
==13621==    by 0x1D581E: PyType_Ready (typeobject.c:6370)
==13621==    by 0x1CC6F1: _PyStructSequence_InitType (structseq.c:506)
==13621==    by 0x2EAA5A: time_exec (timemodule.c:1999)
==13621==    by 0x1B9056: PyModule_ExecDef (moduleobject.c:407)
==13621==    by 0x25EA72: _imp_exec_builtin (import.c.h:64)
==13621==    by 0x345556: cfunction_vectorcall_O (methodobject.c:516)
==13621== 
==13621== 576 bytes in 1 blocks are still reachable in loss record 48 of 124
==13621==    at 0x483B7F3: malloc (in /usr/lib/x86_64-linux-gnu/valgrind/vgpreload_memcheck-amd64-linux.so)
==13621==    by 0x1C08B4: PyMem_RawMalloc (obmalloc.c:572)
==13621==    by 0x1C08B4: _PyObject_Malloc (obmalloc.c:1956)
==13621==    by 0x1C08B4: _PyObject_Malloc (obmalloc.c:1949)
==13621==    by 0x1A774F: new_keys_object (dictobject.c:600)
==13621==    by 0x1A7900: dictresize (dictobject.c:1242)
==13621==    by 0x1AB232: insertion_resize (dictobject.c:1060)
==13621==    by 0x1AB232: insertdict (dictobject.c:1103)
==13621==    by 0x1DFB69: type_dict_set_doc (typeobject.c:6077)
==13621==    by 0x1DFB69: type_ready_fill_dict (typeobject.c:6108)
==13621==    by 0x1DFB69: type_ready (typeobject.c:6337)
==13621==    by 0x1D581E: PyType_Ready (typeobject.c:6370)
==13621==    by 0x1CC6F1: _PyStructSequence_InitType (structseq.c:506)
==13621==    by 0x2E925A: _PySignal_Init (signalmodule.c:1971)
==13621==    by 0x277755: init_interp_main (pylifecycle.c:1110)
==13621==    by 0x277DB7: pyinit_main (pylifecycle.c:1195)
==13621==    by 0x2791AC: Py_InitializeFromConfig (pylifecycle.c:1226)
==13621== 
==13621== 576 bytes in 1 blocks are still reachable in loss record 49 of 124
==13621==    at 0x483B7F3: malloc (in /usr/lib/x86_64-linux-gnu/valgrind/vgpreload_memcheck-amd64-linux.so)
==13621==    by 0x1C08B4: PyMem_RawMalloc (obmalloc.c:572)
==13621==    by 0x1C08B4: _PyObject_Malloc (obmalloc.c:1956)
==13621==    by 0x1C08B4: _PyObject_Malloc (obmalloc.c:1949)
==13621==    by 0x1A774F: new_keys_object (dictobject.c:600)
==13621==    by 0x1A7900: dictresize (dictobject.c:1242)
==13621==    by 0x1AFA9A: insertion_resize (dictobject.c:1060)
==13621==    by 0x1AFA9A: PyDict_SetDefault (dictobject.c:3067)
==13621==    by 0x1DF9E5: type_add_members (typeobject.c:5645)
==13621==    by 0x1DF9E5: type_ready_fill_dict (typeobject.c:6102)
==13621==    by 0x1DF9E5: type_ready (typeobject.c:6337)
==13621==    by 0x1D581E: PyType_Ready (typeobject.c:6370)
==13621==    by 0x271AE6: PyModule_AddType (modsupport.c:706)
==13621==    by 0x2D9561: collections_exec (_collectionsmodule.c:2612)
==13621==    by 0x1B9056: PyModule_ExecDef (moduleobject.c:407)
==13621==    by 0x25EA72: _imp_exec_builtin (import.c.h:64)
==13621==    by 0x345556: cfunction_vectorcall_O (methodobject.c:516)
==13621== 
==13621== 576 bytes in 1 blocks are still reachable in loss record 50 of 124
==13621==    at 0x483B7F3: malloc (in /usr/lib/x86_64-linux-gnu/valgrind/vgpreload_memcheck-amd64-linux.so)
==13621==    by 0x1C08B4: PyMem_RawMalloc (obmalloc.c:572)
==13621==    by 0x1C08B4: _PyObject_Malloc (obmalloc.c:1956)
==13621==    by 0x1C08B4: _PyObject_Malloc (obmalloc.c:1949)
==13621==    by 0x1A774F: new_keys_object (dictobject.c:600)
==13621==    by 0x1A7900: dictresize (dictobject.c:1242)
==13621==    by 0x1AB232: insertion_resize (dictobject.c:1060)
==13621==    by 0x1AB232: insertdict (dictobject.c:1103)
==13621==    by 0x1DFB69: type_dict_set_doc (typeobject.c:6077)
==13621==    by 0x1DFB69: type_ready_fill_dict (typeobject.c:6108)
==13621==    by 0x1DFB69: type_ready (typeobject.c:6337)
==13621==    by 0x1D581E: PyType_Ready (typeobject.c:6370)
==13621==    by 0x55BDD1A: _ctypes_add_types (_ctypes.c:5711)
==13621==    by 0x55BDD1A: _ctypes_mod_exec (_ctypes.c:5829)
==13621==    by 0x55BDD1A: PyInit__ctypes (_ctypes.c:5851)
==13621==    by 0x262340: _PyImport_LoadDynamicModuleWithSpec (importdl.c:167)
==13621==    by 0x25E6D4: _imp_create_dynamic_impl (import.c:2049)
==13621==    by 0x25E6D4: _imp_create_dynamic (import.c.h:330)
==13621==    by 0x3457DB: cfunction_vectorcall_FASTCALL (methodobject.c:430)
==13621==    by 0x18064B: PyVectorcall_Call (call.c:255)
==13621== 
==13621== 576 bytes in 1 blocks are still reachable in loss record 51 of 124
==13621==    at 0x483B7F3: malloc (in /usr/lib/x86_64-linux-gnu/valgrind/vgpreload_memcheck-amd64-linux.so)
==13621==    by 0x1C08B4: PyMem_RawMalloc (obmalloc.c:572)
==13621==    by 0x1C08B4: _PyObject_Malloc (obmalloc.c:1956)
==13621==    by 0x1C08B4: _PyObject_Malloc (obmalloc.c:1949)
==13621==    by 0x1A774F: new_keys_object (dictobject.c:600)
==13621==    by 0x1A7900: dictresize (dictobject.c:1242)
==13621==    by 0x1AB232: insertion_resize (dictobject.c:1060)
==13621==    by 0x1AB232: insertdict (dictobject.c:1103)
==13621==    by 0x1DFB69: type_dict_set_doc (typeobject.c:6077)
==13621==    by 0x1DFB69: type_ready_fill_dict (typeobject.c:6108)
==13621==    by 0x1DFB69: type_ready (typeobject.c:6337)
==13621==    by 0x1D581E: PyType_Ready (typeobject.c:6370)
==13621==    by 0x55BDD35: _ctypes_add_types (_ctypes.c:5712)
==13621==    by 0x55BDD35: _ctypes_mod_exec (_ctypes.c:5829)
==13621==    by 0x55BDD35: PyInit__ctypes (_ctypes.c:5851)
==13621==    by 0x262340: _PyImport_LoadDynamicModuleWithSpec (importdl.c:167)
==13621==    by 0x25E6D4: _imp_create_dynamic_impl (import.c:2049)
==13621==    by 0x25E6D4: _imp_create_dynamic (import.c.h:330)
==13621==    by 0x3457DB: cfunction_vectorcall_FASTCALL (methodobject.c:430)
==13621==    by 0x18064B: PyVectorcall_Call (call.c:255)
==13621== 
==13621== 576 bytes in 1 blocks are still reachable in loss record 52 of 124
==13621==    at 0x483B7F3: malloc (in /usr/lib/x86_64-linux-gnu/valgrind/vgpreload_memcheck-amd64-linux.so)
==13621==    by 0x1C08B4: PyMem_RawMalloc (obmalloc.c:572)
==13621==    by 0x1C08B4: _PyObject_Malloc (obmalloc.c:1956)
==13621==    by 0x1C08B4: _PyObject_Malloc (obmalloc.c:1949)
==13621==    by 0x1A774F: new_keys_object (dictobject.c:600)
==13621==    by 0x1A7900: dictresize (dictobject.c:1242)
==13621==    by 0x1AB232: insertion_resize (dictobject.c:1060)
==13621==    by 0x1AB232: insertdict (dictobject.c:1103)
==13621==    by 0x1BCC2E: _PyObject_GenericSetAttrWithDict (object.c:1391)
==13621==    by 0x1BCC2E: PyObject_GenericSetAttr (object.c:1413)
==13621==    by 0x1BB394: PyObject_SetAttr (object.c:1044)
==13621==    by 0x1BB524: PyObject_SetAttrString (object.c:843)
==13621==    by 0x1B7CBF: _add_methods_to_object (moduleobject.c:163)
==13621==    by 0x1B8B99: PyModule_FromDefAndSpec2 (moduleobject.c:349)
==13621==    by 0x25E6D4: _imp_create_dynamic_impl (import.c:2049)
==13621==    by 0x25E6D4: _imp_create_dynamic (import.c.h:330)
==13621==    by 0x3457DB: cfunction_vectorcall_FASTCALL (methodobject.c:430)
==13621== 
==13621== 576 bytes in 1 blocks are still reachable in loss record 53 of 124
==13621==    at 0x483B7F3: malloc (in /usr/lib/x86_64-linux-gnu/valgrind/vgpreload_memcheck-amd64-linux.so)
==13621==    by 0x1C08B4: PyMem_RawMalloc (obmalloc.c:572)
==13621==    by 0x1C08B4: _PyObject_Malloc (obmalloc.c:1956)
==13621==    by 0x1C08B4: _PyObject_Malloc (obmalloc.c:1949)
==13621==    by 0x1A774F: new_keys_object (dictobject.c:600)
==13621==    by 0x1A7900: dictresize (dictobject.c:1242)
==13621==    by 0x1AFA9A: insertion_resize (dictobject.c:1060)
==13621==    by 0x1AFA9A: PyDict_SetDefault (dictobject.c:3067)
==13621==    by 0x1DF80E: type_add_method (typeobject.c:5597)
==13621==    by 0x1DF80E: type_add_methods (typeobject.c:5623)
==13621==    by 0x1DF80E: type_ready_fill_dict (typeobject.c:6099)
==13621==    by 0x1DF80E: type_ready (typeobject.c:6337)
==13621==    by 0x1D581E: PyType_Ready (typeobject.c:6370)
==13621==    by 0x1E1E70: PyType_FromModuleAndSpec (typeobject.c:3559)
==13621==    by 0x55E9C8E: _structmodule_exec (_struct.c:2380)
==13621==    by 0x1B9056: PyModule_ExecDef (moduleobject.c:407)
==13621==    by 0x25EB12: exec_builtin_or_dynamic (import.c:1997)
==13621==    by 0x25EB12: _imp_exec_dynamic_impl (import.c:2071)
==13621==    by 0x25EB12: _imp_exec_dynamic (import.c.h:358)
==13621==    by 0x345556: cfunction_vectorcall_O (methodobject.c:516)
==13621== 
==13621== 576 bytes in 1 blocks are still reachable in loss record 54 of 124
==13621==    at 0x483B7F3: malloc (in /usr/lib/x86_64-linux-gnu/valgrind/vgpreload_memcheck-amd64-linux.so)
==13621==    by 0x1C08B4: PyMem_RawMalloc (obmalloc.c:572)
==13621==    by 0x1C08B4: _PyObject_Malloc (obmalloc.c:1956)
==13621==    by 0x1C08B4: _PyObject_Malloc (obmalloc.c:1949)
==13621==    by 0x1A774F: new_keys_object (dictobject.c:600)
==13621==    by 0x1A7900: dictresize (dictobject.c:1242)
==13621==    by 0x1AB232: insertion_resize (dictobject.c:1060)
==13621==    by 0x1AB232: insertdict (dictobject.c:1103)
==13621==    by 0x55EDA22: cache_struct_converter (_struct.c:2138)
==13621==    by 0x55EDA22: calcsize (_struct.c.h:202)
==13621==    by 0x345556: cfunction_vectorcall_O (methodobject.c:516)
==13621==    by 0x16B72D: _PyObject_VectorcallTstate (abstract.h:114)
==13621==    by 0x16B72D: PyObject_Vectorcall (abstract.h:123)
==13621==    by 0x16B72D: call_function (ceval.c:5867)
==13621==    by 0x16B72D: _PyEval_EvalFrameDefault (ceval.c:4213)
==13621==    by 0x239197: _PyEval_EvalFrame (pycore_ceval.h:46)
==13621==    by 0x239197: _PyEval_Vector (ceval.c:5065)
==13621==    by 0x16B72D: _PyObject_VectorcallTstate (abstract.h:114)
==13621==    by 0x16B72D: PyObject_Vectorcall (abstract.h:123)
==13621==    by 0x16B72D: call_function (ceval.c:5867)
==13621==    by 0x16B72D: _PyEval_EvalFrameDefault (ceval.c:4213)
==13621==    by 0x239016: _PyEval_EvalFrame (pycore_ceval.h:46)
==13621==    by 0x239016: _PyEval_Vector (ceval.c:5065)
==13621==    by 0x239016: PyEval_EvalCode (ceval.c:1134)
==13621==    by 0x37F198: builtin_exec_impl (bltinmodule.c:1056)
==13621==    by 0x37F198: builtin_exec (bltinmodule.c.h:371)
==13621== 
==13621== 624 bytes in 3 blocks are still reachable in loss record 55 of 124
==13621==    at 0x483DD99: calloc (in /usr/lib/x86_64-linux-gnu/valgrind/vgpreload_memcheck-amd64-linux.so)
==13621==    by 0x401331C: _dl_check_map_versions (dl-version.c:274)
==13621==    by 0x40160FC: dl_open_worker (dl-open.c:577)
==13621==    by 0x4B31927: _dl_catch_exception (dl-error-skeleton.c:208)
==13621==    by 0x4015609: _dl_open (dl-open.c:837)
==13621==    by 0x487834B: dlopen_doit (dlopen.c:66)
==13621==    by 0x4B31927: _dl_catch_exception (dl-error-skeleton.c:208)
==13621==    by 0x4B319F2: _dl_catch_error (dl-error-skeleton.c:227)
==13621==    by 0x4878B58: _dlerror_run (dlerror.c:170)
==13621==    by 0x48783D9: dlopen@@GLIBC_2.2.5 (dlopen.c:87)
==13621==    by 0x29E650: _PyImport_FindSharedFuncptr (dynload_shlib.c:100)
==13621==    by 0x2622F7: _PyImport_LoadDynamicModuleWithSpec (importdl.c:137)
==13621== 
==13621== 645 bytes in 1 blocks are still reachable in loss record 56 of 124
==13621==    at 0x483B7F3: malloc (in /usr/lib/x86_64-linux-gnu/valgrind/vgpreload_memcheck-amd64-linux.so)
==13621==    by 0x1C08B4: PyMem_RawMalloc (obmalloc.c:572)
==13621==    by 0x1C08B4: _PyObject_Malloc (obmalloc.c:1956)
==13621==    by 0x1C08B4: _PyObject_Malloc (obmalloc.c:1949)
==13621==    by 0x1F05FF: PyUnicode_New (unicodeobject.c:1463)
==13621==    by 0x21D047: unicode_decode_utf8 (unicodeobject.c:5203)
==13621==    by 0x1DFB47: type_dict_set_doc (typeobject.c:6072)
==13621==    by 0x1DFB47: type_ready_fill_dict (typeobject.c:6108)
==13621==    by 0x1DFB47: type_ready (typeobject.c:6337)
==13621==    by 0x1D581E: PyType_Ready (typeobject.c:6370)
==13621==    by 0x1BD68B: _PyTypes_Init (object.c:1869)
==13621==    by 0x275860: pycore_init_types (pylifecycle.c:699)
==13621==    by 0x275860: pycore_interp_init (pylifecycle.c:810)
==13621==    by 0x278724: pyinit_config (pylifecycle.c:866)
==13621==    by 0x278724: pyinit_core.constprop.0 (pylifecycle.c:1029)
==13621==    by 0x279113: Py_InitializeFromConfig (pylifecycle.c:1219)
==13621==    by 0x16E719: pymain_init (main.c:66)
==13621==    by 0x16F9F7: pymain_main (main.c:687)
==13621==    by 0x16F9F7: Py_BytesMain (main.c:720)
==13621== 
==13621== 654 bytes in 1 blocks are still reachable in loss record 57 of 124
==13621==    at 0x483B7F3: malloc (in /usr/lib/x86_64-linux-gnu/valgrind/vgpreload_memcheck-amd64-linux.so)
==13621==    by 0x1C08B4: PyMem_RawMalloc (obmalloc.c:572)
==13621==    by 0x1C08B4: _PyObject_Malloc (obmalloc.c:1956)
==13621==    by 0x1C08B4: _PyObject_Malloc (obmalloc.c:1949)
==13621==    by 0x1F05FF: PyUnicode_New (unicodeobject.c:1463)
==13621==    by 0x21D047: unicode_decode_utf8 (unicodeobject.c:5203)
==13621==    by 0x1DFB47: type_dict_set_doc (typeobject.c:6072)
==13621==    by 0x1DFB47: type_ready_fill_dict (typeobject.c:6108)
==13621==    by 0x1DFB47: type_ready (typeobject.c:6337)
==13621==    by 0x1E11B4: PyType_Ready (typeobject.c:6370)
==13621==    by 0x1E11B4: type_ready_set_bases (typeobject.c:6005)
==13621==    by 0x1E11B4: type_ready (typeobject.c:6328)
==13621==    by 0x1D581E: PyType_Ready (typeobject.c:6370)
==13621==    by 0x1BD1C7: _PyTypes_Init (object.c:1808)
==13621==    by 0x275860: pycore_init_types (pylifecycle.c:699)
==13621==    by 0x275860: pycore_interp_init (pylifecycle.c:810)
==13621==    by 0x278724: pyinit_config (pylifecycle.c:866)
==13621==    by 0x278724: pyinit_core.constprop.0 (pylifecycle.c:1029)
==13621==    by 0x279113: Py_InitializeFromConfig (pylifecycle.c:1219)
==13621==    by 0x16E719: pymain_init (main.c:66)
==13621== 
==13621== 680 bytes in 1 blocks are still reachable in loss record 58 of 124
==13621==    at 0x483B7F3: malloc (in /usr/lib/x86_64-linux-gnu/valgrind/vgpreload_memcheck-amd64-linux.so)
==13621==    by 0x1C08B4: PyMem_RawMalloc (obmalloc.c:572)
==13621==    by 0x1C08B4: _PyObject_Malloc (obmalloc.c:1956)
==13621==    by 0x1C08B4: _PyObject_Malloc (obmalloc.c:1949)
==13621==    by 0x1CC65E: _PyStructSequence_InitType (structseq.c:498)
==13621==    by 0x28E451: _PySys_InitCore (sysmodule.c:2828)
==13621==    by 0x28E451: _PySys_Create (sysmodule.c:3070)
==13621==    by 0x27572F: pycore_interp_init (pylifecycle.c:824)
==13621==    by 0x278724: pyinit_config (pylifecycle.c:866)
==13621==    by 0x278724: pyinit_core.constprop.0 (pylifecycle.c:1029)
==13621==    by 0x279113: Py_InitializeFromConfig (pylifecycle.c:1219)
==13621==    by 0x16E719: pymain_init (main.c:66)
==13621==    by 0x16F9F7: pymain_main (main.c:687)
==13621==    by 0x16F9F7: Py_BytesMain (main.c:720)
==13621==    by 0x49F5082: (below main) (libc-start.c:308)
==13621== 
==13621== 718 bytes in 1 blocks are still reachable in loss record 59 of 124
==13621==    at 0x483B7F3: malloc (in /usr/lib/x86_64-linux-gnu/valgrind/vgpreload_memcheck-amd64-linux.so)
==13621==    by 0x1C08B4: PyMem_RawMalloc (obmalloc.c:572)
==13621==    by 0x1C08B4: _PyObject_Malloc (obmalloc.c:1956)
==13621==    by 0x1C08B4: _PyObject_Malloc (obmalloc.c:1949)
==13621==    by 0x1F05FF: PyUnicode_New (unicodeobject.c:1463)
==13621==    by 0x21D047: unicode_decode_utf8 (unicodeobject.c:5203)
==13621==    by 0x1DFB47: type_dict_set_doc (typeobject.c:6072)
==13621==    by 0x1DFB47: type_ready_fill_dict (typeobject.c:6108)
==13621==    by 0x1DFB47: type_ready (typeobject.c:6337)
==13621==    by 0x1D581E: PyType_Ready (typeobject.c:6370)
==13621==    by 0x1BD2A3: _PyTypes_Init (object.c:1819)
==13621==    by 0x275860: pycore_init_types (pylifecycle.c:699)
==13621==    by 0x275860: pycore_interp_init (pylifecycle.c:810)
==13621==    by 0x278724: pyinit_config (pylifecycle.c:866)
==13621==    by 0x278724: pyinit_core.constprop.0 (pylifecycle.c:1029)
==13621==    by 0x279113: Py_InitializeFromConfig (pylifecycle.c:1219)
==13621==    by 0x16E719: pymain_init (main.c:66)
==13621==    by 0x16F9F7: pymain_main (main.c:687)
==13621==    by 0x16F9F7: Py_BytesMain (main.c:720)
==13621== 
==13621== 762 bytes in 1 blocks are still reachable in loss record 60 of 124
==13621==    at 0x483B7F3: malloc (in /usr/lib/x86_64-linux-gnu/valgrind/vgpreload_memcheck-amd64-linux.so)
==13621==    by 0x1C08B4: PyMem_RawMalloc (obmalloc.c:572)
==13621==    by 0x1C08B4: _PyObject_Malloc (obmalloc.c:1956)
==13621==    by 0x1C08B4: _PyObject_Malloc (obmalloc.c:1949)
==13621==    by 0x1F05FF: PyUnicode_New (unicodeobject.c:1463)
==13621==    by 0x1F1BEC: _PyUnicode_FromUCS1 (unicodeobject.c:2463)
==13621==    by 0x26D3BD: r_object (marshal.c:1112)
==13621==    by 0x26D830: r_object (marshal.c:1174)
==13621==    by 0x26E20B: r_object (marshal.c:1350)
==13621==    by 0x26D830: r_object (marshal.c:1174)
==13621==    by 0x26E20B: r_object (marshal.c:1350)
==13621==    by 0x26EFD7: read_object (marshal.c:1445)
==13621==    by 0x26F13C: marshal_loads_impl (marshal.c:1754)
==13621==    by 0x26F13C: marshal_loads (marshal.c.h:148)
==13621==    by 0x345556: cfunction_vectorcall_O (methodobject.c:516)
==13621== 
==13621== 768 bytes in 1 blocks are still reachable in loss record 61 of 124
==13621==    at 0x483B723: malloc (in /usr/lib/x86_64-linux-gnu/valgrind/vgpreload_memcheck-amd64-linux.so)
==13621==    by 0x483E017: realloc (in /usr/lib/x86_64-linux-gnu/valgrind/vgpreload_memcheck-amd64-linux.so)
==13621==    by 0x1C06C9: PyMem_RawRealloc (obmalloc.c:590)
==13621==    by 0x1C06C9: new_arena (obmalloc.c:1563)
==13621==    by 0x1C06C9: allocate_from_new_pool (obmalloc.c:1777)
==13621==    by 0x1C08CC: pymalloc_alloc (obmalloc.c:1941)
==13621==    by 0x1C08CC: _PyObject_Malloc (obmalloc.c:1951)
==13621==    by 0x1A6F8A: _PyLong_New (longobject.c:134)
==13621==    by 0x1A6F8A: _PyLong_Init (longobject.c:5713)
==13621==    by 0x2754A8: pycore_init_singletons (pylifecycle.c:661)
==13621==    by 0x2754A8: pycore_interp_init (pylifecycle.c:799)
==13621==    by 0x278724: pyinit_config (pylifecycle.c:866)
==13621==    by 0x278724: pyinit_core.constprop.0 (pylifecycle.c:1029)
==13621==    by 0x279113: Py_InitializeFromConfig (pylifecycle.c:1219)
==13621==    by 0x16E719: pymain_init (main.c:66)
==13621==    by 0x16F9F7: pymain_main (main.c:687)
==13621==    by 0x16F9F7: Py_BytesMain (main.c:720)
==13621==    by 0x49F5082: (below main) (libc-start.c:308)
==13621== 
==13621== 827 bytes in 1 blocks are still reachable in loss record 62 of 124
==13621==    at 0x483B7F3: malloc (in /usr/lib/x86_64-linux-gnu/valgrind/vgpreload_memcheck-amd64-linux.so)
==13621==    by 0x1C08B4: PyMem_RawMalloc (obmalloc.c:572)
==13621==    by 0x1C08B4: _PyObject_Malloc (obmalloc.c:1956)
==13621==    by 0x1C08B4: _PyObject_Malloc (obmalloc.c:1949)
==13621==    by 0x1F05FF: PyUnicode_New (unicodeobject.c:1463)
==13621==    by 0x21D047: unicode_decode_utf8 (unicodeobject.c:5203)
==13621==    by 0x1DFB47: type_dict_set_doc (typeobject.c:6072)
==13621==    by 0x1DFB47: type_ready_fill_dict (typeobject.c:6108)
==13621==    by 0x1DFB47: type_ready (typeobject.c:6337)
==13621==    by 0x1D581E: PyType_Ready (typeobject.c:6370)
==13621==    by 0x271AE6: PyModule_AddType (modsupport.c:706)
==13621==    by 0x2F1217: PyInit__io (_iomodule.c:737)
==13621==    by 0x25FD67: create_builtin.part.0 (import.c:1012)
==13621==    by 0x25FE7C: create_builtin (import.c:1000)
==13621==    by 0x25FE7C: _imp_create_builtin (import.c:1063)
==13621==    by 0x345556: cfunction_vectorcall_O (methodobject.c:516)
==13621==    by 0x18064B: PyVectorcall_Call (call.c:255)
==13621== 
==13621== 944 bytes in 1 blocks are still reachable in loss record 63 of 124
==13621==    at 0x483B7F3: malloc (in /usr/lib/x86_64-linux-gnu/valgrind/vgpreload_memcheck-amd64-linux.so)
==13621==    by 0x1C08B4: PyMem_RawMalloc (obmalloc.c:572)
==13621==    by 0x1C08B4: _PyObject_Malloc (obmalloc.c:1956)
==13621==    by 0x1C08B4: _PyObject_Malloc (obmalloc.c:1949)
==13621==    by 0x2A3405: _PyObject_GC_Alloc (gcmodule.c:2274)
==13621==    by 0x2A3405: _PyObject_GC_Malloc (gcmodule.c:2301)
==13621==    by 0x1D1B89: PyType_GenericAlloc (typeobject.c:1154)
==13621==    by 0x1E2DE4: type_new_alloc (typeobject.c:2741)
==13621==    by 0x1E2DE4: type_new_init (typeobject.c:3153)
==13621==    by 0x1E2DE4: type_new_impl (typeobject.c:3176)
==13621==    by 0x1E2DE4: type_new (typeobject.c:3325)
==13621==    by 0x1D3538: type_call (typeobject.c:1121)
==13621==    by 0x17FC2B: _PyObject_MakeTpCall (call.c:215)
==13621==    by 0x1802F2: _PyObject_VectorcallTstate (abstract.h:114)
==13621==    by 0x1802F2: _PyObject_CallFunctionVa.part.0 (call.c:485)
==13621==    by 0x181349: _PyObject_CallFunctionVa (call.c:457)
==13621==    by 0x181349: PyObject_CallFunction (call.c:507)
==13621==    by 0x256071: PyErr_NewException (errors.c:1153)
==13621==    by 0x55BDC92: _ctypes_mod_exec (_ctypes.c:5824)
==13621==    by 0x55BDC92: PyInit__ctypes (_ctypes.c:5851)
==13621==    by 0x262340: _PyImport_LoadDynamicModuleWithSpec (importdl.c:167)
==13621== 
==13621== 944 bytes in 1 blocks are still reachable in loss record 64 of 124
==13621==    at 0x483B7F3: malloc (in /usr/lib/x86_64-linux-gnu/valgrind/vgpreload_memcheck-amd64-linux.so)
==13621==    by 0x1C08B4: PyMem_RawMalloc (obmalloc.c:572)
==13621==    by 0x1C08B4: _PyObject_Malloc (obmalloc.c:1956)
==13621==    by 0x1C08B4: _PyObject_Malloc (obmalloc.c:1949)
==13621==    by 0x2A3405: _PyObject_GC_Alloc (gcmodule.c:2274)
==13621==    by 0x2A3405: _PyObject_GC_Malloc (gcmodule.c:2301)
==13621==    by 0x1D1B89: PyType_GenericAlloc (typeobject.c:1154)
==13621==    by 0x1E1C63: PyType_FromModuleAndSpec (typeobject.c:3410)
==13621==    by 0x55E9CBF: _structmodule_exec (_struct.c:2389)
==13621==    by 0x1B9056: PyModule_ExecDef (moduleobject.c:407)
==13621==    by 0x25EB12: exec_builtin_or_dynamic (import.c:1997)
==13621==    by 0x25EB12: _imp_exec_dynamic_impl (import.c:2071)
==13621==    by 0x25EB12: _imp_exec_dynamic (import.c.h:358)
==13621==    by 0x345556: cfunction_vectorcall_O (methodobject.c:516)
==13621==    by 0x18064B: PyVectorcall_Call (call.c:255)
==13621==    by 0x164AA1: do_call_core (ceval.c:5919)
==13621==    by 0x164AA1: _PyEval_EvalFrameDefault (ceval.c:4277)
==13621==    by 0x239197: _PyEval_EvalFrame (pycore_ceval.h:46)
==13621==    by 0x239197: _PyEval_Vector (ceval.c:5065)
==13621== 
==13621== 944 bytes in 1 blocks are still reachable in loss record 65 of 124
==13621==    at 0x483B7F3: malloc (in /usr/lib/x86_64-linux-gnu/valgrind/vgpreload_memcheck-amd64-linux.so)
==13621==    by 0x1C08B4: PyMem_RawMalloc (obmalloc.c:572)
==13621==    by 0x1C08B4: _PyObject_Malloc (obmalloc.c:1956)
==13621==    by 0x1C08B4: _PyObject_Malloc (obmalloc.c:1949)
==13621==    by 0x2A3405: _PyObject_GC_Alloc (gcmodule.c:2274)
==13621==    by 0x2A3405: _PyObject_GC_Malloc (gcmodule.c:2301)
==13621==    by 0x1D1B89: PyType_GenericAlloc (typeobject.c:1154)
==13621==    by 0x1E2DE4: type_new_alloc (typeobject.c:2741)
==13621==    by 0x1E2DE4: type_new_init (typeobject.c:3153)
==13621==    by 0x1E2DE4: type_new_impl (typeobject.c:3176)
==13621==    by 0x1E2DE4: type_new (typeobject.c:3325)
==13621==    by 0x1D3538: type_call (typeobject.c:1121)
==13621==    by 0x17FC2B: _PyObject_MakeTpCall (call.c:215)
==13621==    by 0x1802F2: _PyObject_VectorcallTstate (abstract.h:114)
==13621==    by 0x1802F2: _PyObject_CallFunctionVa.part.0 (call.c:485)
==13621==    by 0x181349: _PyObject_CallFunctionVa (call.c:457)
==13621==    by 0x181349: PyObject_CallFunction (call.c:507)
==13621==    by 0x256071: PyErr_NewException (errors.c:1153)
==13621==    by 0x55E9D30: _structmodule_exec (_struct.c:2438)
==13621==    by 0x1B9056: PyModule_ExecDef (moduleobject.c:407)
==13621== 
==13621== 944 bytes in 1 blocks are still reachable in loss record 66 of 124
==13621==    at 0x483B7F3: malloc (in /usr/lib/x86_64-linux-gnu/valgrind/vgpreload_memcheck-amd64-linux.so)
==13621==    by 0x1C08B4: PyMem_RawMalloc (obmalloc.c:572)
==13621==    by 0x1C08B4: _PyObject_Malloc (obmalloc.c:1956)
==13621==    by 0x1C08B4: _PyObject_Malloc (obmalloc.c:1949)
==13621==    by 0x2A3405: _PyObject_GC_Alloc (gcmodule.c:2274)
==13621==    by 0x2A3405: _PyObject_GC_Malloc (gcmodule.c:2301)
==13621==    by 0x1D1B89: PyType_GenericAlloc (typeobject.c:1154)
==13621==    by 0x1E36B2: type_new_alloc (typeobject.c:2741)
==13621==    by 0x1E36B2: type_new_init (typeobject.c:3153)
==13621==    by 0x1E36B2: type_new_impl (typeobject.c:3176)
==13621==    by 0x1E36B2: type_new (typeobject.c:3325)
==13621==    by 0x55B9868: StructUnionType_new (_ctypes.c:496)
==13621==    by 0x1D3538: type_call (typeobject.c:1121)
==13621==    by 0x17FC2B: _PyObject_MakeTpCall (call.c:215)
==13621==    by 0x1804CB: _PyObject_FastCallDictTstate (call.c:137)
==13621==    by 0x1804CB: PyObject_VectorcallDict (call.c:166)
==13621==    by 0x37E34C: builtin___build_class__ (bltinmodule.c:224)
==13621==    by 0x345669: cfunction_vectorcall_FASTCALL_KEYWORDS (methodobject.c:446)
==13621==    by 0x16B1B6: _PyObject_VectorcallTstate (abstract.h:114)
==13621==    by 0x16B1B6: PyObject_Vectorcall (abstract.h:123)
==13621==    by 0x16B1B6: call_function (ceval.c:5867)
==13621==    by 0x16B1B6: _PyEval_EvalFrameDefault (ceval.c:4231)
==13621== 
==13621== 984 bytes in 1 blocks are still reachable in loss record 67 of 124
==13621==    at 0x483B7F3: malloc (in /usr/lib/x86_64-linux-gnu/valgrind/vgpreload_memcheck-amd64-linux.so)
==13621==    by 0x1C08B4: PyMem_RawMalloc (obmalloc.c:572)
==13621==    by 0x1C08B4: _PyObject_Malloc (obmalloc.c:1956)
==13621==    by 0x1C08B4: _PyObject_Malloc (obmalloc.c:1949)
==13621==    by 0x2A3405: _PyObject_GC_Alloc (gcmodule.c:2274)
==13621==    by 0x2A3405: _PyObject_GC_Malloc (gcmodule.c:2301)
==13621==    by 0x1D1B89: PyType_GenericAlloc (typeobject.c:1154)
==13621==    by 0x1E1C63: PyType_FromModuleAndSpec (typeobject.c:3410)
==13621==    by 0x55E9C8E: _structmodule_exec (_struct.c:2380)
==13621==    by 0x1B9056: PyModule_ExecDef (moduleobject.c:407)
==13621==    by 0x25EB12: exec_builtin_or_dynamic (import.c:1997)
==13621==    by 0x25EB12: _imp_exec_dynamic_impl (import.c:2071)
==13621==    by 0x25EB12: _imp_exec_dynamic (import.c.h:358)
==13621==    by 0x345556: cfunction_vectorcall_O (methodobject.c:516)
==13621==    by 0x18064B: PyVectorcall_Call (call.c:255)
==13621==    by 0x164AA1: do_call_core (ceval.c:5919)
==13621==    by 0x164AA1: _PyEval_EvalFrameDefault (ceval.c:4277)
==13621==    by 0x239197: _PyEval_EvalFrame (pycore_ceval.h:46)
==13621==    by 0x239197: _PyEval_Vector (ceval.c:5065)
==13621== 
==13621== 1,112 bytes in 1 blocks are still reachable in loss record 68 of 124
==13621==    at 0x483B7F3: malloc (in /usr/lib/x86_64-linux-gnu/valgrind/vgpreload_memcheck-amd64-linux.so)
==13621==    by 0x1C08B4: PyMem_RawMalloc (obmalloc.c:572)
==13621==    by 0x1C08B4: _PyObject_Malloc (obmalloc.c:1956)
==13621==    by 0x1C08B4: _PyObject_Malloc (obmalloc.c:1949)
==13621==    by 0x1A774F: new_keys_object (dictobject.c:600)
==13621==    by 0x1A7900: dictresize (dictobject.c:1242)
==13621==    by 0x1AFA9A: insertion_resize (dictobject.c:1060)
==13621==    by 0x1AFA9A: PyDict_SetDefault (dictobject.c:3067)
==13621==    by 0x1DFA55: type_add_getset (typeobject.c:5670)
==13621==    by 0x1DFA55: type_ready_fill_dict (typeobject.c:6105)
==13621==    by 0x1DFA55: type_ready (typeobject.c:6337)
==13621==    by 0x1D581E: PyType_Ready (typeobject.c:6370)
==13621==    by 0x1BD18B: _PyTypes_Init (object.c:1801)
==13621==    by 0x275860: pycore_init_types (pylifecycle.c:699)
==13621==    by 0x275860: pycore_interp_init (pylifecycle.c:810)
==13621==    by 0x278724: pyinit_config (pylifecycle.c:866)
==13621==    by 0x278724: pyinit_core.constprop.0 (pylifecycle.c:1029)
==13621==    by 0x279113: Py_InitializeFromConfig (pylifecycle.c:1219)
==13621==    by 0x16E719: pymain_init (main.c:66)
==13621== 
==13621== 1,112 bytes in 1 blocks are still reachable in loss record 69 of 124
==13621==    at 0x483B7F3: malloc (in /usr/lib/x86_64-linux-gnu/valgrind/vgpreload_memcheck-amd64-linux.so)
==13621==    by 0x1C08B4: PyMem_RawMalloc (obmalloc.c:572)
==13621==    by 0x1C08B4: _PyObject_Malloc (obmalloc.c:1956)
==13621==    by 0x1C08B4: _PyObject_Malloc (obmalloc.c:1949)
==13621==    by 0x1A774F: new_keys_object (dictobject.c:600)
==13621==    by 0x1A7900: dictresize (dictobject.c:1242)
==13621==    by 0x1AFA9A: insertion_resize (dictobject.c:1060)
==13621==    by 0x1AFA9A: PyDict_SetDefault (dictobject.c:3067)
==13621==    by 0x1DF9E5: type_add_members (typeobject.c:5645)
==13621==    by 0x1DF9E5: type_ready_fill_dict (typeobject.c:6102)
==13621==    by 0x1DF9E5: type_ready (typeobject.c:6337)
==13621==    by 0x1D581E: PyType_Ready (typeobject.c:6370)
==13621==    by 0x1BD19F: _PyTypes_Init (object.c:1802)
==13621==    by 0x275860: pycore_init_types (pylifecycle.c:699)
==13621==    by 0x275860: pycore_interp_init (pylifecycle.c:810)
==13621==    by 0x278724: pyinit_config (pylifecycle.c:866)
==13621==    by 0x278724: pyinit_core.constprop.0 (pylifecycle.c:1029)
==13621==    by 0x279113: Py_InitializeFromConfig (pylifecycle.c:1219)
==13621==    by 0x16E719: pymain_init (main.c:66)
==13621== 
==13621== 1,112 bytes in 1 blocks are still reachable in loss record 70 of 124
==13621==    at 0x483B7F3: malloc (in /usr/lib/x86_64-linux-gnu/valgrind/vgpreload_memcheck-amd64-linux.so)
==13621==    by 0x1C08B4: PyMem_RawMalloc (obmalloc.c:572)
==13621==    by 0x1C08B4: _PyObject_Malloc (obmalloc.c:1956)
==13621==    by 0x1C08B4: _PyObject_Malloc (obmalloc.c:1949)
==13621==    by 0x1A774F: new_keys_object (dictobject.c:600)
==13621==    by 0x1A7900: dictresize (dictobject.c:1242)
==13621==    by 0x1AFA9A: insertion_resize (dictobject.c:1060)
==13621==    by 0x1AFA9A: PyDict_SetDefault (dictobject.c:3067)
==13621==    by 0x1DF9E5: type_add_members (typeobject.c:5645)
==13621==    by 0x1DF9E5: type_ready_fill_dict (typeobject.c:6102)
==13621==    by 0x1DF9E5: type_ready (typeobject.c:6337)
==13621==    by 0x1D581E: PyType_Ready (typeobject.c:6370)
==13621==    by 0x1BD2B7: _PyTypes_Init (object.c:1820)
==13621==    by 0x275860: pycore_init_types (pylifecycle.c:699)
==13621==    by 0x275860: pycore_interp_init (pylifecycle.c:810)
==13621==    by 0x278724: pyinit_config (pylifecycle.c:866)
==13621==    by 0x278724: pyinit_core.constprop.0 (pylifecycle.c:1029)
==13621==    by 0x279113: Py_InitializeFromConfig (pylifecycle.c:1219)
==13621==    by 0x16E719: pymain_init (main.c:66)
==13621== 
==13621== 1,112 bytes in 1 blocks are still reachable in loss record 71 of 124
==13621==    at 0x483B7F3: malloc (in /usr/lib/x86_64-linux-gnu/valgrind/vgpreload_memcheck-amd64-linux.so)
==13621==    by 0x1C08B4: PyMem_RawMalloc (obmalloc.c:572)
==13621==    by 0x1C08B4: _PyObject_Malloc (obmalloc.c:1956)
==13621==    by 0x1C08B4: _PyObject_Malloc (obmalloc.c:1949)
==13621==    by 0x1A774F: new_keys_object (dictobject.c:600)
==13621==    by 0x1A7900: dictresize (dictobject.c:1242)
==13621==    by 0x1AB232: insertion_resize (dictobject.c:1060)
==13621==    by 0x1AB232: insertdict (dictobject.c:1103)
==13621==    by 0x1DF62E: add_operators (typeobject.c:8636)
==13621==    by 0x1DF62E: type_ready_fill_dict (typeobject.c:6096)
==13621==    by 0x1DF62E: type_ready (typeobject.c:6337)
==13621==    by 0x1D581E: PyType_Ready (typeobject.c:6370)
==13621==    by 0x1BD2CB: _PyTypes_Init (object.c:1821)
==13621==    by 0x275860: pycore_init_types (pylifecycle.c:699)
==13621==    by 0x275860: pycore_interp_init (pylifecycle.c:810)
==13621==    by 0x278724: pyinit_config (pylifecycle.c:866)
==13621==    by 0x278724: pyinit_core.constprop.0 (pylifecycle.c:1029)
==13621==    by 0x279113: Py_InitializeFromConfig (pylifecycle.c:1219)
==13621==    by 0x16E719: pymain_init (main.c:66)
==13621== 
==13621== 1,112 bytes in 1 blocks are still reachable in loss record 72 of 124
==13621==    at 0x483B7F3: malloc (in /usr/lib/x86_64-linux-gnu/valgrind/vgpreload_memcheck-amd64-linux.so)
==13621==    by 0x1C08B4: PyMem_RawMalloc (obmalloc.c:572)
==13621==    by 0x1C08B4: _PyObject_Malloc (obmalloc.c:1956)
==13621==    by 0x1C08B4: _PyObject_Malloc (obmalloc.c:1949)
==13621==    by 0x1A774F: new_keys_object (dictobject.c:600)
==13621==    by 0x1A7900: dictresize (dictobject.c:1242)
==13621==    by 0x1AFA9A: insertion_resize (dictobject.c:1060)
==13621==    by 0x1AFA9A: PyDict_SetDefault (dictobject.c:3067)
==13621==    by 0x1DFA55: type_add_getset (typeobject.c:5670)
==13621==    by 0x1DFA55: type_ready_fill_dict (typeobject.c:6105)
==13621==    by 0x1DFA55: type_ready (typeobject.c:6337)
==13621==    by 0x1D581E: PyType_Ready (typeobject.c:6370)
==13621==    by 0x1BD2F3: _PyTypes_Init (object.c:1823)
==13621==    by 0x275860: pycore_init_types (pylifecycle.c:699)
==13621==    by 0x275860: pycore_interp_init (pylifecycle.c:810)
==13621==    by 0x278724: pyinit_config (pylifecycle.c:866)
==13621==    by 0x278724: pyinit_core.constprop.0 (pylifecycle.c:1029)
==13621==    by 0x279113: Py_InitializeFromConfig (pylifecycle.c:1219)
==13621==    by 0x16E719: pymain_init (main.c:66)
==13621== 
==13621== 1,112 bytes in 1 blocks are still reachable in loss record 73 of 124
==13621==    at 0x483B7F3: malloc (in /usr/lib/x86_64-linux-gnu/valgrind/vgpreload_memcheck-amd64-linux.so)
==13621==    by 0x1C08B4: PyMem_RawMalloc (obmalloc.c:572)
==13621==    by 0x1C08B4: _PyObject_Malloc (obmalloc.c:1956)
==13621==    by 0x1C08B4: _PyObject_Malloc (obmalloc.c:1949)
==13621==    by 0x1A774F: new_keys_object (dictobject.c:600)
==13621==    by 0x1A7900: dictresize (dictobject.c:1242)
==13621==    by 0x1AFA9A: insertion_resize (dictobject.c:1060)
==13621==    by 0x1AFA9A: PyDict_SetDefault (dictobject.c:3067)
==13621==    by 0x1DFA55: type_add_getset (typeobject.c:5670)
==13621==    by 0x1DFA55: type_ready_fill_dict (typeobject.c:6105)
==13621==    by 0x1DFA55: type_ready (typeobject.c:6337)
==13621==    by 0x1D581E: PyType_Ready (typeobject.c:6370)
==13621==    by 0x1BD343: _PyTypes_Init (object.c:1827)
==13621==    by 0x275860: pycore_init_types (pylifecycle.c:699)
==13621==    by 0x275860: pycore_interp_init (pylifecycle.c:810)
==13621==    by 0x278724: pyinit_config (pylifecycle.c:866)
==13621==    by 0x278724: pyinit_core.constprop.0 (pylifecycle.c:1029)
==13621==    by 0x279113: Py_InitializeFromConfig (pylifecycle.c:1219)
==13621==    by 0x16E719: pymain_init (main.c:66)
==13621== 
==13621== 1,112 bytes in 1 blocks are still reachable in loss record 74 of 124
==13621==    at 0x483B7F3: malloc (in /usr/lib/x86_64-linux-gnu/valgrind/vgpreload_memcheck-amd64-linux.so)
==13621==    by 0x1C08B4: PyMem_RawMalloc (obmalloc.c:572)
==13621==    by 0x1C08B4: _PyObject_Malloc (obmalloc.c:1956)
==13621==    by 0x1C08B4: _PyObject_Malloc (obmalloc.c:1949)
==13621==    by 0x1A774F: new_keys_object (dictobject.c:600)
==13621==    by 0x1A7900: dictresize (dictobject.c:1242)
==13621==    by 0x1AFA9A: insertion_resize (dictobject.c:1060)
==13621==    by 0x1AFA9A: PyDict_SetDefault (dictobject.c:3067)
==13621==    by 0x1DF80E: type_add_method (typeobject.c:5597)
==13621==    by 0x1DF80E: type_add_methods (typeobject.c:5623)
==13621==    by 0x1DF80E: type_ready_fill_dict (typeobject.c:6099)
==13621==    by 0x1DF80E: type_ready (typeobject.c:6337)
==13621==    by 0x1D581E: PyType_Ready (typeobject.c:6370)
==13621==    by 0x1BD357: _PyTypes_Init (object.c:1828)
==13621==    by 0x275860: pycore_init_types (pylifecycle.c:699)
==13621==    by 0x275860: pycore_interp_init (pylifecycle.c:810)
==13621==    by 0x278724: pyinit_config (pylifecycle.c:866)
==13621==    by 0x278724: pyinit_core.constprop.0 (pylifecycle.c:1029)
==13621==    by 0x279113: Py_InitializeFromConfig (pylifecycle.c:1219)
==13621==    by 0x16E719: pymain_init (main.c:66)
==13621== 
==13621== 1,112 bytes in 1 blocks are still reachable in loss record 75 of 124
==13621==    at 0x483B7F3: malloc (in /usr/lib/x86_64-linux-gnu/valgrind/vgpreload_memcheck-amd64-linux.so)
==13621==    by 0x1C08B4: PyMem_RawMalloc (obmalloc.c:572)
==13621==    by 0x1C08B4: _PyObject_Malloc (obmalloc.c:1956)
==13621==    by 0x1C08B4: _PyObject_Malloc (obmalloc.c:1949)
==13621==    by 0x1A774F: new_keys_object (dictobject.c:600)
==13621==    by 0x1A7900: dictresize (dictobject.c:1242)
==13621==    by 0x1AFA9A: insertion_resize (dictobject.c:1060)
==13621==    by 0x1AFA9A: PyDict_SetDefault (dictobject.c:3067)
==13621==    by 0x1DF80E: type_add_method (typeobject.c:5597)
==13621==    by 0x1DF80E: type_add_methods (typeobject.c:5623)
==13621==    by 0x1DF80E: type_ready_fill_dict (typeobject.c:6099)
==13621==    by 0x1DF80E: type_ready (typeobject.c:6337)
==13621==    by 0x1D581E: PyType_Ready (typeobject.c:6370)
==13621==    by 0x1BD3BB: _PyTypes_Init (object.c:1833)
==13621==    by 0x275860: pycore_init_types (pylifecycle.c:699)
==13621==    by 0x275860: pycore_interp_init (pylifecycle.c:810)
==13621==    by 0x278724: pyinit_config (pylifecycle.c:866)
==13621==    by 0x278724: pyinit_core.constprop.0 (pylifecycle.c:1029)
==13621==    by 0x279113: Py_InitializeFromConfig (pylifecycle.c:1219)
==13621==    by 0x16E719: pymain_init (main.c:66)
==13621== 
==13621== 1,112 bytes in 1 blocks are still reachable in loss record 76 of 124
==13621==    at 0x483B7F3: malloc (in /usr/lib/x86_64-linux-gnu/valgrind/vgpreload_memcheck-amd64-linux.so)
==13621==    by 0x1C08B4: PyMem_RawMalloc (obmalloc.c:572)
==13621==    by 0x1C08B4: _PyObject_Malloc (obmalloc.c:1956)
==13621==    by 0x1C08B4: _PyObject_Malloc (obmalloc.c:1949)
==13621==    by 0x1A774F: new_keys_object (dictobject.c:600)
==13621==    by 0x1A7900: dictresize (dictobject.c:1242)
==13621==    by 0x1AFA9A: insertion_resize (dictobject.c:1060)
==13621==    by 0x1AFA9A: PyDict_SetDefault (dictobject.c:3067)
==13621==    by 0x1DF80E: type_add_method (typeobject.c:5597)
==13621==    by 0x1DF80E: type_add_methods (typeobject.c:5623)
==13621==    by 0x1DF80E: type_ready_fill_dict (typeobject.c:6099)
==13621==    by 0x1DF80E: type_ready (typeobject.c:6337)
==13621==    by 0x1D581E: PyType_Ready (typeobject.c:6370)
==13621==    by 0x1BD41F: _PyTypes_Init (object.c:1838)
==13621==    by 0x275860: pycore_init_types (pylifecycle.c:699)
==13621==    by 0x275860: pycore_interp_init (pylifecycle.c:810)
==13621==    by 0x278724: pyinit_config (pylifecycle.c:866)
==13621==    by 0x278724: pyinit_core.constprop.0 (pylifecycle.c:1029)
==13621==    by 0x279113: Py_InitializeFromConfig (pylifecycle.c:1219)
==13621==    by 0x16E719: pymain_init (main.c:66)
==13621== 
==13621== 1,112 bytes in 1 blocks are still reachable in loss record 77 of 124
==13621==    at 0x483B7F3: malloc (in /usr/lib/x86_64-linux-gnu/valgrind/vgpreload_memcheck-amd64-linux.so)
==13621==    by 0x1C08B4: PyMem_RawMalloc (obmalloc.c:572)
==13621==    by 0x1C08B4: _PyObject_Malloc (obmalloc.c:1956)
==13621==    by 0x1C08B4: _PyObject_Malloc (obmalloc.c:1949)
==13621==    by 0x1A774F: new_keys_object (dictobject.c:600)
==13621==    by 0x1A7900: dictresize (dictobject.c:1242)
==13621==    by 0x1AB232: insertion_resize (dictobject.c:1060)
==13621==    by 0x1AB232: insertdict (dictobject.c:1103)
==13621==    by 0x1DF62E: add_operators (typeobject.c:8636)
==13621==    by 0x1DF62E: type_ready_fill_dict (typeobject.c:6096)
==13621==    by 0x1DF62E: type_ready (typeobject.c:6337)
==13621==    by 0x1D581E: PyType_Ready (typeobject.c:6370)
==13621==    by 0x1BD4AB: _PyTypes_Init (object.c:1845)
==13621==    by 0x275860: pycore_init_types (pylifecycle.c:699)
==13621==    by 0x275860: pycore_interp_init (pylifecycle.c:810)
==13621==    by 0x278724: pyinit_config (pylifecycle.c:866)
==13621==    by 0x278724: pyinit_core.constprop.0 (pylifecycle.c:1029)
==13621==    by 0x279113: Py_InitializeFromConfig (pylifecycle.c:1219)
==13621==    by 0x16E719: pymain_init (main.c:66)
==13621== 
==13621== 1,112 bytes in 1 blocks are still reachable in loss record 78 of 124
==13621==    at 0x483B7F3: malloc (in /usr/lib/x86_64-linux-gnu/valgrind/vgpreload_memcheck-amd64-linux.so)
==13621==    by 0x1C08B4: PyMem_RawMalloc (obmalloc.c:572)
==13621==    by 0x1C08B4: _PyObject_Malloc (obmalloc.c:1956)
==13621==    by 0x1C08B4: _PyObject_Malloc (obmalloc.c:1949)
==13621==    by 0x1A774F: new_keys_object (dictobject.c:600)
==13621==    by 0x1A7900: dictresize (dictobject.c:1242)
==13621==    by 0x1AFA9A: insertion_resize (dictobject.c:1060)
==13621==    by 0x1AFA9A: PyDict_SetDefault (dictobject.c:3067)
==13621==    by 0x1DF80E: type_add_method (typeobject.c:5597)
==13621==    by 0x1DF80E: type_add_methods (typeobject.c:5623)
==13621==    by 0x1DF80E: type_ready_fill_dict (typeobject.c:6099)
==13621==    by 0x1DF80E: type_ready (typeobject.c:6337)
==13621==    by 0x1D581E: PyType_Ready (typeobject.c:6370)
==13621==    by 0x1BD4FB: _PyTypes_Init (object.c:1849)
==13621==    by 0x275860: pycore_init_types (pylifecycle.c:699)
==13621==    by 0x275860: pycore_interp_init (pylifecycle.c:810)
==13621==    by 0x278724: pyinit_config (pylifecycle.c:866)
==13621==    by 0x278724: pyinit_core.constprop.0 (pylifecycle.c:1029)
==13621==    by 0x279113: Py_InitializeFromConfig (pylifecycle.c:1219)
==13621==    by 0x16E719: pymain_init (main.c:66)
==13621== 
==13621== 1,112 bytes in 1 blocks are still reachable in loss record 79 of 124
==13621==    at 0x483B7F3: malloc (in /usr/lib/x86_64-linux-gnu/valgrind/vgpreload_memcheck-amd64-linux.so)
==13621==    by 0x1C08B4: PyMem_RawMalloc (obmalloc.c:572)
==13621==    by 0x1C08B4: _PyObject_Malloc (obmalloc.c:1956)
==13621==    by 0x1C08B4: _PyObject_Malloc (obmalloc.c:1949)
==13621==    by 0x1A774F: new_keys_object (dictobject.c:600)
==13621==    by 0x1A7900: dictresize (dictobject.c:1242)
==13621==    by 0x1AFA9A: insertion_resize (dictobject.c:1060)
==13621==    by 0x1AFA9A: PyDict_SetDefault (dictobject.c:3067)
==13621==    by 0x1DF80E: type_add_method (typeobject.c:5597)
==13621==    by 0x1DF80E: type_add_methods (typeobject.c:5623)
==13621==    by 0x1DF80E: type_ready_fill_dict (typeobject.c:6099)
==13621==    by 0x1DF80E: type_ready (typeobject.c:6337)
==13621==    by 0x1D581E: PyType_Ready (typeobject.c:6370)
==13621==    by 0x1BD5AF: _PyTypes_Init (object.c:1858)
==13621==    by 0x275860: pycore_init_types (pylifecycle.c:699)
==13621==    by 0x275860: pycore_interp_init (pylifecycle.c:810)
==13621==    by 0x278724: pyinit_config (pylifecycle.c:866)
==13621==    by 0x278724: pyinit_core.constprop.0 (pylifecycle.c:1029)
==13621==    by 0x279113: Py_InitializeFromConfig (pylifecycle.c:1219)
==13621==    by 0x16E719: pymain_init (main.c:66)
==13621== 
==13621== 1,112 bytes in 1 blocks are still reachable in loss record 80 of 124
==13621==    at 0x483B7F3: malloc (in /usr/lib/x86_64-linux-gnu/valgrind/vgpreload_memcheck-amd64-linux.so)
==13621==    by 0x1C08B4: PyMem_RawMalloc (obmalloc.c:572)
==13621==    by 0x1C08B4: _PyObject_Malloc (obmalloc.c:1956)
==13621==    by 0x1C08B4: _PyObject_Malloc (obmalloc.c:1949)
==13621==    by 0x1A774F: new_keys_object (dictobject.c:600)
==13621==    by 0x1A7900: dictresize (dictobject.c:1242)
==13621==    by 0x1AFA9A: insertion_resize (dictobject.c:1060)
==13621==    by 0x1AFA9A: PyDict_SetDefault (dictobject.c:3067)
==13621==    by 0x1DF9E5: type_add_members (typeobject.c:5645)
==13621==    by 0x1DF9E5: type_ready_fill_dict (typeobject.c:6102)
==13621==    by 0x1DF9E5: type_ready (typeobject.c:6337)
==13621==    by 0x1D581E: PyType_Ready (typeobject.c:6370)
==13621==    by 0x1BD5FF: _PyTypes_Init (object.c:1862)
==13621==    by 0x275860: pycore_init_types (pylifecycle.c:699)
==13621==    by 0x275860: pycore_interp_init (pylifecycle.c:810)
==13621==    by 0x278724: pyinit_config (pylifecycle.c:866)
==13621==    by 0x278724: pyinit_core.constprop.0 (pylifecycle.c:1029)
==13621==    by 0x279113: Py_InitializeFromConfig (pylifecycle.c:1219)
==13621==    by 0x16E719: pymain_init (main.c:66)
==13621== 
==13621== 1,112 bytes in 1 blocks are still reachable in loss record 81 of 124
==13621==    at 0x483B7F3: malloc (in /usr/lib/x86_64-linux-gnu/valgrind/vgpreload_memcheck-amd64-linux.so)
==13621==    by 0x1C08B4: PyMem_RawMalloc (obmalloc.c:572)
==13621==    by 0x1C08B4: _PyObject_Malloc (obmalloc.c:1956)
==13621==    by 0x1C08B4: _PyObject_Malloc (obmalloc.c:1949)
==13621==    by 0x1A774F: new_keys_object (dictobject.c:600)
==13621==    by 0x1A7900: dictresize (dictobject.c:1242)
==13621==    by 0x1AB232: insertion_resize (dictobject.c:1060)
==13621==    by 0x1AB232: insertdict (dictobject.c:1103)
==13621==    by 0x1DFB69: type_dict_set_doc (typeobject.c:6077)
==13621==    by 0x1DFB69: type_ready_fill_dict (typeobject.c:6108)
==13621==    by 0x1DFB69: type_ready (typeobject.c:6337)
==13621==    by 0x1D581E: PyType_Ready (typeobject.c:6370)
==13621==    by 0x1BD6EF: _PyTypes_Init (object.c:1874)
==13621==    by 0x275860: pycore_init_types (pylifecycle.c:699)
==13621==    by 0x275860: pycore_interp_init (pylifecycle.c:810)
==13621==    by 0x278724: pyinit_config (pylifecycle.c:866)
==13621==    by 0x278724: pyinit_core.constprop.0 (pylifecycle.c:1029)
==13621==    by 0x279113: Py_InitializeFromConfig (pylifecycle.c:1219)
==13621==    by 0x16E719: pymain_init (main.c:66)
==13621== 
==13621== 1,112 bytes in 1 blocks are still reachable in loss record 82 of 124
==13621==    at 0x483B7F3: malloc (in /usr/lib/x86_64-linux-gnu/valgrind/vgpreload_memcheck-amd64-linux.so)
==13621==    by 0x1C08B4: PyMem_RawMalloc (obmalloc.c:572)
==13621==    by 0x1C08B4: _PyObject_Malloc (obmalloc.c:1956)
==13621==    by 0x1C08B4: _PyObject_Malloc (obmalloc.c:1949)
==13621==    by 0x1A774F: new_keys_object (dictobject.c:600)
==13621==    by 0x1A7900: dictresize (dictobject.c:1242)
==13621==    by 0x1AFA9A: insertion_resize (dictobject.c:1060)
==13621==    by 0x1AFA9A: PyDict_SetDefault (dictobject.c:3067)
==13621==    by 0x1DFA55: type_add_getset (typeobject.c:5670)
==13621==    by 0x1DFA55: type_ready_fill_dict (typeobject.c:6105)
==13621==    by 0x1DFA55: type_ready (typeobject.c:6337)
==13621==    by 0x1D581E: PyType_Ready (typeobject.c:6370)
==13621==    by 0x1BD73F: _PyTypes_Init (object.c:1878)
==13621==    by 0x275860: pycore_init_types (pylifecycle.c:699)
==13621==    by 0x275860: pycore_interp_init (pylifecycle.c:810)
==13621==    by 0x278724: pyinit_config (pylifecycle.c:866)
==13621==    by 0x278724: pyinit_core.constprop.0 (pylifecycle.c:1029)
==13621==    by 0x279113: Py_InitializeFromConfig (pylifecycle.c:1219)
==13621==    by 0x16E719: pymain_init (main.c:66)
==13621== 
==13621== 1,112 bytes in 1 blocks are still reachable in loss record 83 of 124
==13621==    at 0x483B7F3: malloc (in /usr/lib/x86_64-linux-gnu/valgrind/vgpreload_memcheck-amd64-linux.so)
==13621==    by 0x1C08B4: PyMem_RawMalloc (obmalloc.c:572)
==13621==    by 0x1C08B4: _PyObject_Malloc (obmalloc.c:1956)
==13621==    by 0x1C08B4: _PyObject_Malloc (obmalloc.c:1949)
==13621==    by 0x1A774F: new_keys_object (dictobject.c:600)
==13621==    by 0x1A7900: dictresize (dictobject.c:1242)
==13621==    by 0x1AB232: insertion_resize (dictobject.c:1060)
==13621==    by 0x1AB232: insertdict (dictobject.c:1103)
==13621==    by 0x1B08C5: PyDict_SetItem (dictobject.c:1623)
==13621==    by 0x1B08C5: PyDict_SetItemString (dictobject.c:3614)
==13621==    by 0x1CB882: initialize_structseq_dict.isra.0 (structseq.c:403)
==13621==    by 0x1CC718: _PyStructSequence_InitType (structseq.c:512)
==13621==    by 0x28E451: _PySys_InitCore (sysmodule.c:2828)
==13621==    by 0x28E451: _PySys_Create (sysmodule.c:3070)
==13621==    by 0x27572F: pycore_interp_init (pylifecycle.c:824)
==13621==    by 0x278724: pyinit_config (pylifecycle.c:866)
==13621==    by 0x278724: pyinit_core.constprop.0 (pylifecycle.c:1029)
==13621==    by 0x279113: Py_InitializeFromConfig (pylifecycle.c:1219)
==13621== 
==13621== 1,112 bytes in 1 blocks are still reachable in loss record 84 of 124
==13621==    at 0x483B7F3: malloc (in /usr/lib/x86_64-linux-gnu/valgrind/vgpreload_memcheck-amd64-linux.so)
==13621==    by 0x1C08B4: PyMem_RawMalloc (obmalloc.c:572)
==13621==    by 0x1C08B4: _PyObject_Malloc (obmalloc.c:1956)
==13621==    by 0x1C08B4: _PyObject_Malloc (obmalloc.c:1949)
==13621==    by 0x1A774F: new_keys_object (dictobject.c:600)
==13621==    by 0x1A7900: dictresize (dictobject.c:1242)
==13621==    by 0x1AFA9A: insertion_resize (dictobject.c:1060)
==13621==    by 0x1AFA9A: PyDict_SetDefault (dictobject.c:3067)
==13621==    by 0x1DF80E: type_add_method (typeobject.c:5597)
==13621==    by 0x1DF80E: type_add_methods (typeobject.c:5623)
==13621==    by 0x1DF80E: type_ready_fill_dict (typeobject.c:6099)
==13621==    by 0x1DF80E: type_ready (typeobject.c:6337)
==13621==    by 0x1D581E: PyType_Ready (typeobject.c:6370)
==13621==    by 0x271AE6: PyModule_AddType (modsupport.c:706)
==13621==    by 0x2F11AD: PyInit__io (_iomodule.c:729)
==13621==    by 0x25FD67: create_builtin.part.0 (import.c:1012)
==13621==    by 0x25FE7C: create_builtin (import.c:1000)
==13621==    by 0x25FE7C: _imp_create_builtin (import.c:1063)
==13621==    by 0x345556: cfunction_vectorcall_O (methodobject.c:516)
==13621== 
==13621== 1,112 bytes in 1 blocks are still reachable in loss record 85 of 124
==13621==    at 0x483B7F3: malloc (in /usr/lib/x86_64-linux-gnu/valgrind/vgpreload_memcheck-amd64-linux.so)
==13621==    by 0x1C08B4: PyMem_RawMalloc (obmalloc.c:572)
==13621==    by 0x1C08B4: _PyObject_Malloc (obmalloc.c:1956)
==13621==    by 0x1C08B4: _PyObject_Malloc (obmalloc.c:1949)
==13621==    by 0x1A774F: new_keys_object (dictobject.c:600)
==13621==    by 0x1A7900: dictresize (dictobject.c:1242)
==13621==    by 0x1AFA9A: insertion_resize (dictobject.c:1060)
==13621==    by 0x1AFA9A: PyDict_SetDefault (dictobject.c:3067)
==13621==    by 0x1DFA55: type_add_getset (typeobject.c:5670)
==13621==    by 0x1DFA55: type_ready_fill_dict (typeobject.c:6105)
==13621==    by 0x1DFA55: type_ready (typeobject.c:6337)
==13621==    by 0x1D581E: PyType_Ready (typeobject.c:6370)
==13621==    by 0x271AE6: PyModule_AddType (modsupport.c:706)
==13621==    by 0x2F1217: PyInit__io (_iomodule.c:737)
==13621==    by 0x25FD67: create_builtin.part.0 (import.c:1012)
==13621==    by 0x25FE7C: create_builtin (import.c:1000)
==13621==    by 0x25FE7C: _imp_create_builtin (import.c:1063)
==13621==    by 0x345556: cfunction_vectorcall_O (methodobject.c:516)
==13621== 
==13621== 1,112 bytes in 1 blocks are still reachable in loss record 86 of 124
==13621==    at 0x483B7F3: malloc (in /usr/lib/x86_64-linux-gnu/valgrind/vgpreload_memcheck-amd64-linux.so)
==13621==    by 0x1C08B4: PyMem_RawMalloc (obmalloc.c:572)
==13621==    by 0x1C08B4: _PyObject_Malloc (obmalloc.c:1956)
==13621==    by 0x1C08B4: _PyObject_Malloc (obmalloc.c:1949)
==13621==    by 0x1A774F: new_keys_object (dictobject.c:600)
==13621==    by 0x1A7900: dictresize (dictobject.c:1242)
==13621==    by 0x1AFA9A: insertion_resize (dictobject.c:1060)
==13621==    by 0x1AFA9A: PyDict_SetDefault (dictobject.c:3067)
==13621==    by 0x1DF80E: type_add_method (typeobject.c:5597)
==13621==    by 0x1DF80E: type_add_methods (typeobject.c:5623)
==13621==    by 0x1DF80E: type_ready_fill_dict (typeobject.c:6099)
==13621==    by 0x1DF80E: type_ready (typeobject.c:6337)
==13621==    by 0x1D581E: PyType_Ready (typeobject.c:6370)
==13621==    by 0x271AE6: PyModule_AddType (modsupport.c:706)
==13621==    by 0x2F123C: PyInit__io (_iomodule.c:741)
==13621==    by 0x25FD67: create_builtin.part.0 (import.c:1012)
==13621==    by 0x25FE7C: create_builtin (import.c:1000)
==13621==    by 0x25FE7C: _imp_create_builtin (import.c:1063)
==13621==    by 0x345556: cfunction_vectorcall_O (methodobject.c:516)
==13621== 
==13621== 1,112 bytes in 1 blocks are still reachable in loss record 87 of 124
==13621==    at 0x483B7F3: malloc (in /usr/lib/x86_64-linux-gnu/valgrind/vgpreload_memcheck-amd64-linux.so)
==13621==    by 0x1C08B4: PyMem_RawMalloc (obmalloc.c:572)
==13621==    by 0x1C08B4: _PyObject_Malloc (obmalloc.c:1956)
==13621==    by 0x1C08B4: _PyObject_Malloc (obmalloc.c:1949)
==13621==    by 0x1A774F: new_keys_object (dictobject.c:600)
==13621==    by 0x1A7900: dictresize (dictobject.c:1242)
==13621==    by 0x1AFA9A: insertion_resize (dictobject.c:1060)
==13621==    by 0x1AFA9A: PyDict_SetDefault (dictobject.c:3067)
==13621==    by 0x1DF80E: type_add_method (typeobject.c:5597)
==13621==    by 0x1DF80E: type_add_methods (typeobject.c:5623)
==13621==    by 0x1DF80E: type_ready_fill_dict (typeobject.c:6099)
==13621==    by 0x1DF80E: type_ready (typeobject.c:6337)
==13621==    by 0x1D581E: PyType_Ready (typeobject.c:6370)
==13621==    by 0x271AE6: PyModule_AddType (modsupport.c:706)
==13621==    by 0x2F1293: PyInit__io (_iomodule.c:757)
==13621==    by 0x25FD67: create_builtin.part.0 (import.c:1012)
==13621==    by 0x25FE7C: create_builtin (import.c:1000)
==13621==    by 0x25FE7C: _imp_create_builtin (import.c:1063)
==13621==    by 0x345556: cfunction_vectorcall_O (methodobject.c:516)
==13621== 
==13621== 1,112 bytes in 1 blocks are still reachable in loss record 88 of 124
==13621==    at 0x483B7F3: malloc (in /usr/lib/x86_64-linux-gnu/valgrind/vgpreload_memcheck-amd64-linux.so)
==13621==    by 0x1C08B4: PyMem_RawMalloc (obmalloc.c:572)
==13621==    by 0x1C08B4: _PyObject_Malloc (obmalloc.c:1956)
==13621==    by 0x1C08B4: _PyObject_Malloc (obmalloc.c:1949)
==13621==    by 0x1A774F: new_keys_object (dictobject.c:600)
==13621==    by 0x1A7900: dictresize (dictobject.c:1242)
==13621==    by 0x1AB232: insertion_resize (dictobject.c:1060)
==13621==    by 0x1AB232: insertdict (dictobject.c:1103)
==13621==    by 0x1DFB69: type_dict_set_doc (typeobject.c:6077)
==13621==    by 0x1DFB69: type_ready_fill_dict (typeobject.c:6108)
==13621==    by 0x1DFB69: type_ready (typeobject.c:6337)
==13621==    by 0x1D581E: PyType_Ready (typeobject.c:6370)
==13621==    by 0x271AE6: PyModule_AddType (modsupport.c:706)
==13621==    by 0x2F12B1: PyInit__io (_iomodule.c:761)
==13621==    by 0x25FD67: create_builtin.part.0 (import.c:1012)
==13621==    by 0x25FE7C: create_builtin (import.c:1000)
==13621==    by 0x25FE7C: _imp_create_builtin (import.c:1063)
==13621==    by 0x345556: cfunction_vectorcall_O (methodobject.c:516)
==13621== 
==13621== 1,112 bytes in 1 blocks are still reachable in loss record 89 of 124
==13621==    at 0x483B7F3: malloc (in /usr/lib/x86_64-linux-gnu/valgrind/vgpreload_memcheck-amd64-linux.so)
==13621==    by 0x1C08B4: PyMem_RawMalloc (obmalloc.c:572)
==13621==    by 0x1C08B4: _PyObject_Malloc (obmalloc.c:1956)
==13621==    by 0x1C08B4: _PyObject_Malloc (obmalloc.c:1949)
==13621==    by 0x1A774F: new_keys_object (dictobject.c:600)
==13621==    by 0x1A7900: dictresize (dictobject.c:1242)
==13621==    by 0x1AFA9A: insertion_resize (dictobject.c:1060)
==13621==    by 0x1AFA9A: PyDict_SetDefault (dictobject.c:3067)
==13621==    by 0x1DF80E: type_add_method (typeobject.c:5597)
==13621==    by 0x1DF80E: type_add_methods (typeobject.c:5623)
==13621==    by 0x1DF80E: type_ready_fill_dict (typeobject.c:6099)
==13621==    by 0x1DF80E: type_ready (typeobject.c:6337)
==13621==    by 0x1D581E: PyType_Ready (typeobject.c:6370)
==13621==    by 0x271AE6: PyModule_AddType (modsupport.c:706)
==13621==    by 0x2F12ED: PyInit__io (_iomodule.c:769)
==13621==    by 0x25FD67: create_builtin.part.0 (import.c:1012)
==13621==    by 0x25FE7C: create_builtin (import.c:1000)
==13621==    by 0x25FE7C: _imp_create_builtin (import.c:1063)
==13621==    by 0x345556: cfunction_vectorcall_O (methodobject.c:516)
==13621== 
==13621== 1,112 bytes in 1 blocks are still reachable in loss record 90 of 124
==13621==    at 0x483B7F3: malloc (in /usr/lib/x86_64-linux-gnu/valgrind/vgpreload_memcheck-amd64-linux.so)
==13621==    by 0x1C08B4: PyMem_RawMalloc (obmalloc.c:572)
==13621==    by 0x1C08B4: _PyObject_Malloc (obmalloc.c:1956)
==13621==    by 0x1C08B4: _PyObject_Malloc (obmalloc.c:1949)
==13621==    by 0x1A774F: new_keys_object (dictobject.c:600)
==13621==    by 0x1A7900: dictresize (dictobject.c:1242)
==13621==    by 0x1AFA9A: insertion_resize (dictobject.c:1060)
==13621==    by 0x1AFA9A: PyDict_SetDefault (dictobject.c:3067)
==13621==    by 0x1DF9E5: type_add_members (typeobject.c:5645)
==13621==    by 0x1DF9E5: type_ready_fill_dict (typeobject.c:6102)
==13621==    by 0x1DF9E5: type_ready (typeobject.c:6337)
==13621==    by 0x1D581E: PyType_Ready (typeobject.c:6370)
==13621==    by 0x271AE6: PyModule_AddType (modsupport.c:706)
==13621==    by 0x2F130B: PyInit__io (_iomodule.c:773)
==13621==    by 0x25FD67: create_builtin.part.0 (import.c:1012)
==13621==    by 0x25FE7C: create_builtin (import.c:1000)
==13621==    by 0x25FE7C: _imp_create_builtin (import.c:1063)
==13621==    by 0x345556: cfunction_vectorcall_O (methodobject.c:516)
==13621== 
==13621== 1,112 bytes in 1 blocks are still reachable in loss record 91 of 124
==13621==    at 0x483B7F3: malloc (in /usr/lib/x86_64-linux-gnu/valgrind/vgpreload_memcheck-amd64-linux.so)
==13621==    by 0x1C08B4: PyMem_RawMalloc (obmalloc.c:572)
==13621==    by 0x1C08B4: _PyObject_Malloc (obmalloc.c:1956)
==13621==    by 0x1C08B4: _PyObject_Malloc (obmalloc.c:1949)
==13621==    by 0x1A774F: new_keys_object (dictobject.c:600)
==13621==    by 0x1A7900: dictresize (dictobject.c:1242)
==13621==    by 0x1AB232: insertion_resize (dictobject.c:1060)
==13621==    by 0x1AB232: insertdict (dictobject.c:1103)
==13621==    by 0x1D07EC: add_subclass.isra.0 (typeobject.c:6406)
==13621==    by 0x1E0219: type_ready_add_subclasses (typeobject.c:6256)
==13621==    by 0x1E0219: type_ready (typeobject.c:6346)
==13621==    by 0x1E3212: PyType_Ready (typeobject.c:6370)
==13621==    by 0x1E3212: type_new_impl (typeobject.c:3186)
==13621==    by 0x1E3212: type_new (typeobject.c:3325)
==13621==    by 0x1D3538: type_call (typeobject.c:1121)
==13621==    by 0x17FC2B: _PyObject_MakeTpCall (call.c:215)
==13621==    by 0x1802F2: _PyObject_VectorcallTstate (abstract.h:114)
==13621==    by 0x1802F2: _PyObject_CallFunctionVa.part.0 (call.c:485)
==13621==    by 0x181349: _PyObject_CallFunctionVa (call.c:457)
==13621==    by 0x181349: PyObject_CallFunction (call.c:507)
==13621== 
==13621== 1,112 bytes in 1 blocks are still reachable in loss record 92 of 124
==13621==    at 0x483B7F3: malloc (in /usr/lib/x86_64-linux-gnu/valgrind/vgpreload_memcheck-amd64-linux.so)
==13621==    by 0x1C08B4: PyMem_RawMalloc (obmalloc.c:572)
==13621==    by 0x1C08B4: _PyObject_Malloc (obmalloc.c:1956)
==13621==    by 0x1C08B4: _PyObject_Malloc (obmalloc.c:1949)
==13621==    by 0x1A774F: new_keys_object (dictobject.c:600)
==13621==    by 0x1A7900: dictresize (dictobject.c:1242)
==13621==    by 0x1AB232: insertion_resize (dictobject.c:1060)
==13621==    by 0x1AB232: insertdict (dictobject.c:1103)
==13621==    by 0x1D07EC: add_subclass.isra.0 (typeobject.c:6406)
==13621==    by 0x1E0219: type_ready_add_subclasses (typeobject.c:6256)
==13621==    by 0x1E0219: type_ready (typeobject.c:6346)
==13621==    by 0x1E3212: PyType_Ready (typeobject.c:6370)
==13621==    by 0x1E3212: type_new_impl (typeobject.c:3186)
==13621==    by 0x1E3212: type_new (typeobject.c:3325)
==13621==    by 0x55BB907: PyCSimpleType_new (_ctypes.c:2079)
==13621==    by 0x1D3538: type_call (typeobject.c:1121)
==13621==    by 0x17FC2B: _PyObject_MakeTpCall (call.c:215)
==13621==    by 0x1804CB: _PyObject_FastCallDictTstate (call.c:137)
==13621==    by 0x1804CB: PyObject_VectorcallDict (call.c:166)
==13621== 
==13621== 1,152 bytes in 2 blocks are still reachable in loss record 93 of 124
==13621==    at 0x483B7F3: malloc (in /usr/lib/x86_64-linux-gnu/valgrind/vgpreload_memcheck-amd64-linux.so)
==13621==    by 0x1C08B4: PyMem_RawMalloc (obmalloc.c:572)
==13621==    by 0x1C08B4: _PyObject_Malloc (obmalloc.c:1956)
==13621==    by 0x1C08B4: _PyObject_Malloc (obmalloc.c:1949)
==13621==    by 0x1A948E: clone_combined_dict_keys.isra.0 (dictobject.c:709)
==13621==    by 0x1AEC43: PyDict_Copy (dictobject.c:2811)
==13621==    by 0x1E29DB: type_new_init (typeobject.c:3139)
==13621==    by 0x1E29DB: type_new_impl (typeobject.c:3176)
==13621==    by 0x1E29DB: type_new (typeobject.c:3325)
==13621==    by 0x1D3538: type_call (typeobject.c:1121)
==13621==    by 0x17FC2B: _PyObject_MakeTpCall (call.c:215)
==13621==    by 0x180475: _PyObject_FastCallDictTstate (call.c:142)
==13621==    by 0x180475: PyObject_VectorcallDict (call.c:166)
==13621==    by 0x37E34C: builtin___build_class__ (bltinmodule.c:224)
==13621==    by 0x345669: cfunction_vectorcall_FASTCALL_KEYWORDS (methodobject.c:446)
==13621==    by 0x16B72D: _PyObject_VectorcallTstate (abstract.h:114)
==13621==    by 0x16B72D: PyObject_Vectorcall (abstract.h:123)
==13621==    by 0x16B72D: call_function (ceval.c:5867)
==13621==    by 0x16B72D: _PyEval_EvalFrameDefault (ceval.c:4213)
==13621==    by 0x239016: _PyEval_EvalFrame (pycore_ceval.h:46)
==13621==    by 0x239016: _PyEval_Vector (ceval.c:5065)
==13621==    by 0x239016: PyEval_EvalCode (ceval.c:1134)
==13621== 
==13621== 1,196 bytes in 1 blocks are still reachable in loss record 94 of 124
==13621==    at 0x483DD99: calloc (in /usr/lib/x86_64-linux-gnu/valgrind/vgpreload_memcheck-amd64-linux.so)
==13621==    by 0x400D283: _dl_new_object (dl-object.c:89)
==13621==    by 0x4006E96: _dl_map_object_from_fd (dl-load.c:997)
==13621==    by 0x400A61A: _dl_map_object (dl-load.c:2236)
==13621==    by 0x400F514: openaux (dl-deps.c:64)
==13621==    by 0x4B31927: _dl_catch_exception (dl-error-skeleton.c:208)
==13621==    by 0x400F962: _dl_map_object_deps (dl-deps.c:248)
==13621==    by 0x4015DAF: dl_open_worker (dl-open.c:571)
==13621==    by 0x4B31927: _dl_catch_exception (dl-error-skeleton.c:208)
==13621==    by 0x4015609: _dl_open (dl-open.c:837)
==13621==    by 0x487834B: dlopen_doit (dlopen.c:66)
==13621==    by 0x4B31927: _dl_catch_exception (dl-error-skeleton.c:208)
==13621== 
==13621== 1,284 bytes in 1 blocks are still reachable in loss record 95 of 124
==13621==    at 0x483B7F3: malloc (in /usr/lib/x86_64-linux-gnu/valgrind/vgpreload_memcheck-amd64-linux.so)
==13621==    by 0x1C08B4: PyMem_RawMalloc (obmalloc.c:572)
==13621==    by 0x1C08B4: _PyObject_Malloc (obmalloc.c:1956)
==13621==    by 0x1C08B4: _PyObject_Malloc (obmalloc.c:1949)
==13621==    by 0x1F05FF: PyUnicode_New (unicodeobject.c:1463)
==13621==    by 0x21D047: unicode_decode_utf8 (unicodeobject.c:5203)
==13621==    by 0x1DFB47: type_dict_set_doc (typeobject.c:6072)
==13621==    by 0x1DFB47: type_ready_fill_dict (typeobject.c:6108)
==13621==    by 0x1DFB47: type_ready (typeobject.c:6337)
==13621==    by 0x1D581E: PyType_Ready (typeobject.c:6370)
==13621==    by 0x271AE6: PyModule_AddType (modsupport.c:706)
==13621==    by 0x2F11AD: PyInit__io (_iomodule.c:729)
==13621==    by 0x25FD67: create_builtin.part.0 (import.c:1012)
==13621==    by 0x25FE7C: create_builtin (import.c:1000)
==13621==    by 0x25FE7C: _imp_create_builtin (import.c:1063)
==13621==    by 0x345556: cfunction_vectorcall_O (methodobject.c:516)
==13621==    by 0x18064B: PyVectorcall_Call (call.c:255)
==13621== 
==13621== 1,332 bytes in 2 blocks are still reachable in loss record 96 of 124
==13621==    at 0x483B7F3: malloc (in /usr/lib/x86_64-linux-gnu/valgrind/vgpreload_memcheck-amd64-linux.so)
==13621==    by 0x1C08B4: PyMem_RawMalloc (obmalloc.c:572)
==13621==    by 0x1C08B4: _PyObject_Malloc (obmalloc.c:1956)
==13621==    by 0x1C08B4: _PyObject_Malloc (obmalloc.c:1949)
==13621==    by 0x1F05FF: PyUnicode_New (unicodeobject.c:1463)
==13621==    by 0x21D047: unicode_decode_utf8 (unicodeobject.c:5203)
==13621==    by 0x1DFB47: type_dict_set_doc (typeobject.c:6072)
==13621==    by 0x1DFB47: type_ready_fill_dict (typeobject.c:6108)
==13621==    by 0x1DFB47: type_ready (typeobject.c:6337)
==13621==    by 0x1D581E: PyType_Ready (typeobject.c:6370)
==13621==    by 0x271AE6: PyModule_AddType (modsupport.c:706)
==13621==    by 0x2DFB53: itertoolsmodule_exec (itertoolsmodule.c:4872)
==13621==    by 0x1B9056: PyModule_ExecDef (moduleobject.c:407)
==13621==    by 0x25EA72: _imp_exec_builtin (import.c.h:64)
==13621==    by 0x345556: cfunction_vectorcall_O (methodobject.c:516)
==13621==    by 0x18064B: PyVectorcall_Call (call.c:255)
==13621== 
==13621== 1,393 bytes in 1 blocks are still reachable in loss record 97 of 124
==13621==    at 0x483B7F3: malloc (in /usr/lib/x86_64-linux-gnu/valgrind/vgpreload_memcheck-amd64-linux.so)
==13621==    by 0x1C08B4: PyMem_RawMalloc (obmalloc.c:572)
==13621==    by 0x1C08B4: _PyObject_Malloc (obmalloc.c:1956)
==13621==    by 0x1C08B4: _PyObject_Malloc (obmalloc.c:1949)
==13621==    by 0x1F05FF: PyUnicode_New (unicodeobject.c:1463)
==13621==    by 0x21D047: unicode_decode_utf8 (unicodeobject.c:5203)
==13621==    by 0x1DFB47: type_dict_set_doc (typeobject.c:6072)
==13621==    by 0x1DFB47: type_ready_fill_dict (typeobject.c:6108)
==13621==    by 0x1DFB47: type_ready (typeobject.c:6337)
==13621==    by 0x1D581E: PyType_Ready (typeobject.c:6370)
==13621==    by 0x271AE6: PyModule_AddType (modsupport.c:706)
==13621==    by 0x2F130B: PyInit__io (_iomodule.c:773)
==13621==    by 0x25FD67: create_builtin.part.0 (import.c:1012)
==13621==    by 0x25FE7C: create_builtin (import.c:1000)
==13621==    by 0x25FE7C: _imp_create_builtin (import.c:1063)
==13621==    by 0x345556: cfunction_vectorcall_O (methodobject.c:516)
==13621==    by 0x18064B: PyVectorcall_Call (call.c:255)
==13621== 
==13621== 1,489 bytes in 1 blocks are still reachable in loss record 98 of 124
==13621==    at 0x483B7F3: malloc (in /usr/lib/x86_64-linux-gnu/valgrind/vgpreload_memcheck-amd64-linux.so)
==13621==    by 0x1C08B4: PyMem_RawMalloc (obmalloc.c:572)
==13621==    by 0x1C08B4: _PyObject_Malloc (obmalloc.c:1956)
==13621==    by 0x1C08B4: _PyObject_Malloc (obmalloc.c:1949)
==13621==    by 0x1E3009: type_new_set_doc (typeobject.c:2883)
==13621==    by 0x1E3009: type_new_set_attrs (typeobject.c:3072)
==13621==    by 0x1E3009: type_new_impl (typeobject.c:3181)
==13621==    by 0x1E3009: type_new (typeobject.c:3325)
==13621==    by 0x1D3538: type_call (typeobject.c:1121)
==13621==    by 0x17FC2B: _PyObject_MakeTpCall (call.c:215)
==13621==    by 0x180475: _PyObject_FastCallDictTstate (call.c:142)
==13621==    by 0x180475: PyObject_VectorcallDict (call.c:166)
==13621==    by 0x37E34C: builtin___build_class__ (bltinmodule.c:224)
==13621==    by 0x345669: cfunction_vectorcall_FASTCALL_KEYWORDS (methodobject.c:446)
==13621==    by 0x16B72D: _PyObject_VectorcallTstate (abstract.h:114)
==13621==    by 0x16B72D: PyObject_Vectorcall (abstract.h:123)
==13621==    by 0x16B72D: call_function (ceval.c:5867)
==13621==    by 0x16B72D: _PyEval_EvalFrameDefault (ceval.c:4213)
==13621==    by 0x239016: _PyEval_EvalFrame (pycore_ceval.h:46)
==13621==    by 0x239016: _PyEval_Vector (ceval.c:5065)
==13621==    by 0x239016: PyEval_EvalCode (ceval.c:1134)
==13621==    by 0x2607C9: exec_code_in_module (import.c:793)
==13621==    by 0x2607C9: PyImport_ImportFrozenModuleObject (import.c:1194)
==13621==    by 0x260A8D: PyImport_ImportFrozenModule (import.c:1216)
==13621== 
==13621== 1,537 bytes in 1 blocks are still reachable in loss record 99 of 124
==13621==    at 0x483B7F3: malloc (in /usr/lib/x86_64-linux-gnu/valgrind/vgpreload_memcheck-amd64-linux.so)
==13621==    by 0x1C08B4: PyMem_RawMalloc (obmalloc.c:572)
==13621==    by 0x1C08B4: _PyObject_Malloc (obmalloc.c:1956)
==13621==    by 0x1C08B4: _PyObject_Malloc (obmalloc.c:1949)
==13621==    by 0x1F05FF: PyUnicode_New (unicodeobject.c:1463)
==13621==    by 0x1F1BEC: _PyUnicode_FromUCS1 (unicodeobject.c:2463)
==13621==    by 0x26D3BD: r_object (marshal.c:1112)
==13621==    by 0x26D830: r_object (marshal.c:1174)
==13621==    by 0x26E20B: r_object (marshal.c:1350)
==13621==    by 0x26D830: r_object (marshal.c:1174)
==13621==    by 0x26E20B: r_object (marshal.c:1350)
==13621==    by 0x26EFD7: read_object (marshal.c:1445)
==13621==    by 0x26FBE4: PyMarshal_ReadObjectFromString (marshal.c:1562)
==13621==    by 0x26077F: PyImport_ImportFrozenModuleObject (import.c:1162)
==13621== 
==13621== 1,888 bytes in 2 blocks are still reachable in loss record 100 of 124
==13621==    at 0x483B7F3: malloc (in /usr/lib/x86_64-linux-gnu/valgrind/vgpreload_memcheck-amd64-linux.so)
==13621==    by 0x1C08B4: PyMem_RawMalloc (obmalloc.c:572)
==13621==    by 0x1C08B4: _PyObject_Malloc (obmalloc.c:1956)
==13621==    by 0x1C08B4: _PyObject_Malloc (obmalloc.c:1949)
==13621==    by 0x2A3405: _PyObject_GC_Alloc (gcmodule.c:2274)
==13621==    by 0x2A3405: _PyObject_GC_Malloc (gcmodule.c:2301)
==13621==    by 0x1D1B89: PyType_GenericAlloc (typeobject.c:1154)
==13621==    by 0x1E2DE4: type_new_alloc (typeobject.c:2741)
==13621==    by 0x1E2DE4: type_new_init (typeobject.c:3153)
==13621==    by 0x1E2DE4: type_new_impl (typeobject.c:3176)
==13621==    by 0x1E2DE4: type_new (typeobject.c:3325)
==13621==    by 0x55BC68C: PyCPointerType_new (_ctypes.c:1117)
==13621==    by 0x1D3538: type_call (typeobject.c:1121)
==13621==    by 0x17FC2B: _PyObject_MakeTpCall (call.c:215)
==13621==    by 0x1803A8: _PyObject_VectorcallTstate (abstract.h:112)
==13621==    by 0x1803A8: _PyObject_VectorcallTstate (abstract.h:99)
==13621==    by 0x1803A8: _PyObject_CallFunctionVa.part.0 (call.c:485)
==13621==    by 0x181349: _PyObject_CallFunctionVa (call.c:457)
==13621==    by 0x181349: PyObject_CallFunction (call.c:507)
==13621==    by 0x55BF93C: POINTER (callproc.c:1923)
==13621==    by 0x55BF93C: POINTER (callproc.c:1882)
==13621==    by 0x345556: cfunction_vectorcall_O (methodobject.c:516)
==13621== 
==13621== 2,048 bytes in 1 blocks are still reachable in loss record 101 of 124
==13621==    at 0x483DD99: calloc (in /usr/lib/x86_64-linux-gnu/valgrind/vgpreload_memcheck-amd64-linux.so)
==13621==    by 0x1BEDAA: PyMem_RawCalloc (obmalloc.c:581)
==13621==    by 0x1BEDAA: arena_map_get (obmalloc.c:1425)
==13621==    by 0x1C04B5: arena_map_mark_used (obmalloc.c:1468)
==13621==    by 0x1C04B5: new_arena (obmalloc.c:1597)
==13621==    by 0x1C04B5: allocate_from_new_pool (obmalloc.c:1777)
==13621==    by 0x1C08CC: pymalloc_alloc (obmalloc.c:1941)
==13621==    by 0x1C08CC: _PyObject_Malloc (obmalloc.c:1951)
==13621==    by 0x1A6F8A: _PyLong_New (longobject.c:134)
==13621==    by 0x1A6F8A: _PyLong_Init (longobject.c:5713)
==13621==    by 0x2754A8: pycore_init_singletons (pylifecycle.c:661)
==13621==    by 0x2754A8: pycore_interp_init (pylifecycle.c:799)
==13621==    by 0x278724: pyinit_config (pylifecycle.c:866)
==13621==    by 0x278724: pyinit_core.constprop.0 (pylifecycle.c:1029)
==13621==    by 0x279113: Py_InitializeFromConfig (pylifecycle.c:1219)
==13621==    by 0x16E719: pymain_init (main.c:66)
==13621==    by 0x16F9F7: pymain_main (main.c:687)
==13621==    by 0x16F9F7: Py_BytesMain (main.c:720)
==13621==    by 0x49F5082: (below main) (libc-start.c:308)
==13621== 
==13621== 2,208 bytes in 1 blocks are still reachable in loss record 102 of 124
==13621==    at 0x483B7F3: malloc (in /usr/lib/x86_64-linux-gnu/valgrind/vgpreload_memcheck-amd64-linux.so)
==13621==    by 0x1C08B4: PyMem_RawMalloc (obmalloc.c:572)
==13621==    by 0x1C08B4: _PyObject_Malloc (obmalloc.c:1956)
==13621==    by 0x1C08B4: _PyObject_Malloc (obmalloc.c:1949)
==13621==    by 0x1A774F: new_keys_object (dictobject.c:600)
==13621==    by 0x1A7900: dictresize (dictobject.c:1242)
==13621==    by 0x1AB232: insertion_resize (dictobject.c:1060)
==13621==    by 0x1AB232: insertdict (dictobject.c:1103)
==13621==    by 0x1DF62E: add_operators (typeobject.c:8636)
==13621==    by 0x1DF62E: type_ready_fill_dict (typeobject.c:6096)
==13621==    by 0x1DF62E: type_ready (typeobject.c:6337)
==13621==    by 0x1E11B4: PyType_Ready (typeobject.c:6370)
==13621==    by 0x1E11B4: type_ready_set_bases (typeobject.c:6005)
==13621==    by 0x1E11B4: type_ready (typeobject.c:6328)
==13621==    by 0x1D581E: PyType_Ready (typeobject.c:6370)
==13621==    by 0x1BD1C7: _PyTypes_Init (object.c:1808)
==13621==    by 0x275860: pycore_init_types (pylifecycle.c:699)
==13621==    by 0x275860: pycore_interp_init (pylifecycle.c:810)
==13621==    by 0x278724: pyinit_config (pylifecycle.c:866)
==13621==    by 0x278724: pyinit_core.constprop.0 (pylifecycle.c:1029)
==13621==    by 0x279113: Py_InitializeFromConfig (pylifecycle.c:1219)
==13621== 
==13621== 2,208 bytes in 1 blocks are still reachable in loss record 103 of 124
==13621==    at 0x483B7F3: malloc (in /usr/lib/x86_64-linux-gnu/valgrind/vgpreload_memcheck-amd64-linux.so)
==13621==    by 0x1C08B4: PyMem_RawMalloc (obmalloc.c:572)
==13621==    by 0x1C08B4: _PyObject_Malloc (obmalloc.c:1956)
==13621==    by 0x1C08B4: _PyObject_Malloc (obmalloc.c:1949)
==13621==    by 0x1A774F: new_keys_object (dictobject.c:600)
==13621==    by 0x1A7900: dictresize (dictobject.c:1242)
==13621==    by 0x1AFA9A: insertion_resize (dictobject.c:1060)
==13621==    by 0x1AFA9A: PyDict_SetDefault (dictobject.c:3067)
==13621==    by 0x1DF80E: type_add_method (typeobject.c:5597)
==13621==    by 0x1DF80E: type_add_methods (typeobject.c:5623)
==13621==    by 0x1DF80E: type_ready_fill_dict (typeobject.c:6099)
==13621==    by 0x1DF80E: type_ready (typeobject.c:6337)
==13621==    by 0x1D581E: PyType_Ready (typeobject.c:6370)
==13621==    by 0x1BD1EF: _PyTypes_Init (object.c:1810)
==13621==    by 0x275860: pycore_init_types (pylifecycle.c:699)
==13621==    by 0x275860: pycore_interp_init (pylifecycle.c:810)
==13621==    by 0x278724: pyinit_config (pylifecycle.c:866)
==13621==    by 0x278724: pyinit_core.constprop.0 (pylifecycle.c:1029)
==13621==    by 0x279113: Py_InitializeFromConfig (pylifecycle.c:1219)
==13621==    by 0x16E719: pymain_init (main.c:66)
==13621== 
==13621== 2,208 bytes in 1 blocks are still reachable in loss record 104 of 124
==13621==    at 0x483B7F3: malloc (in /usr/lib/x86_64-linux-gnu/valgrind/vgpreload_memcheck-amd64-linux.so)
==13621==    by 0x1C08B4: PyMem_RawMalloc (obmalloc.c:572)
==13621==    by 0x1C08B4: _PyObject_Malloc (obmalloc.c:1956)
==13621==    by 0x1C08B4: _PyObject_Malloc (obmalloc.c:1949)
==13621==    by 0x1A774F: new_keys_object (dictobject.c:600)
==13621==    by 0x1A7900: dictresize (dictobject.c:1242)
==13621==    by 0x1AFA9A: insertion_resize (dictobject.c:1060)
==13621==    by 0x1AFA9A: PyDict_SetDefault (dictobject.c:3067)
==13621==    by 0x1DF80E: type_add_method (typeobject.c:5597)
==13621==    by 0x1DF80E: type_add_methods (typeobject.c:5623)
==13621==    by 0x1DF80E: type_ready_fill_dict (typeobject.c:6099)
==13621==    by 0x1DF80E: type_ready (typeobject.c:6337)
==13621==    by 0x1D581E: PyType_Ready (typeobject.c:6370)
==13621==    by 0x1BD217: _PyTypes_Init (object.c:1812)
==13621==    by 0x275860: pycore_init_types (pylifecycle.c:699)
==13621==    by 0x275860: pycore_interp_init (pylifecycle.c:810)
==13621==    by 0x278724: pyinit_config (pylifecycle.c:866)
==13621==    by 0x278724: pyinit_core.constprop.0 (pylifecycle.c:1029)
==13621==    by 0x279113: Py_InitializeFromConfig (pylifecycle.c:1219)
==13621==    by 0x16E719: pymain_init (main.c:66)
==13621== 
==13621== 2,208 bytes in 1 blocks are still reachable in loss record 105 of 124
==13621==    at 0x483B7F3: malloc (in /usr/lib/x86_64-linux-gnu/valgrind/vgpreload_memcheck-amd64-linux.so)
==13621==    by 0x1C08B4: PyMem_RawMalloc (obmalloc.c:572)
==13621==    by 0x1C08B4: _PyObject_Malloc (obmalloc.c:1956)
==13621==    by 0x1C08B4: _PyObject_Malloc (obmalloc.c:1949)
==13621==    by 0x1A774F: new_keys_object (dictobject.c:600)
==13621==    by 0x1A7900: dictresize (dictobject.c:1242)
==13621==    by 0x1AFA9A: insertion_resize (dictobject.c:1060)
==13621==    by 0x1AFA9A: PyDict_SetDefault (dictobject.c:3067)
==13621==    by 0x1DF80E: type_add_method (typeobject.c:5597)
==13621==    by 0x1DF80E: type_add_methods (typeobject.c:5623)
==13621==    by 0x1DF80E: type_ready_fill_dict (typeobject.c:6099)
==13621==    by 0x1DF80E: type_ready (typeobject.c:6337)
==13621==    by 0x1D581E: PyType_Ready (typeobject.c:6370)
==13621==    by 0x1BD3F7: _PyTypes_Init (object.c:1836)
==13621==    by 0x275860: pycore_init_types (pylifecycle.c:699)
==13621==    by 0x275860: pycore_interp_init (pylifecycle.c:810)
==13621==    by 0x278724: pyinit_config (pylifecycle.c:866)
==13621==    by 0x278724: pyinit_core.constprop.0 (pylifecycle.c:1029)
==13621==    by 0x279113: Py_InitializeFromConfig (pylifecycle.c:1219)
==13621==    by 0x16E719: pymain_init (main.c:66)
==13621== 
==13621== 2,208 bytes in 1 blocks are still reachable in loss record 106 of 124
==13621==    at 0x483B7F3: malloc (in /usr/lib/x86_64-linux-gnu/valgrind/vgpreload_memcheck-amd64-linux.so)
==13621==    by 0x1C08B4: PyMem_RawMalloc (obmalloc.c:572)
==13621==    by 0x1C08B4: _PyObject_Malloc (obmalloc.c:1956)
==13621==    by 0x1C08B4: _PyObject_Malloc (obmalloc.c:1949)
==13621==    by 0x1A774F: new_keys_object (dictobject.c:600)
==13621==    by 0x1A7900: dictresize (dictobject.c:1242)
==13621==    by 0x1AFA9A: insertion_resize (dictobject.c:1060)
==13621==    by 0x1AFA9A: PyDict_SetDefault (dictobject.c:3067)
==13621==    by 0x1DF80E: type_add_method (typeobject.c:5597)
==13621==    by 0x1DF80E: type_add_methods (typeobject.c:5623)
==13621==    by 0x1DF80E: type_ready_fill_dict (typeobject.c:6099)
==13621==    by 0x1DF80E: type_ready (typeobject.c:6337)
==13621==    by 0x1D581E: PyType_Ready (typeobject.c:6370)
==13621==    by 0x1BD663: _PyTypes_Init (object.c:1867)
==13621==    by 0x275860: pycore_init_types (pylifecycle.c:699)
==13621==    by 0x275860: pycore_interp_init (pylifecycle.c:810)
==13621==    by 0x278724: pyinit_config (pylifecycle.c:866)
==13621==    by 0x278724: pyinit_core.constprop.0 (pylifecycle.c:1029)
==13621==    by 0x279113: Py_InitializeFromConfig (pylifecycle.c:1219)
==13621==    by 0x16E719: pymain_init (main.c:66)
==13621== 
==13621== 2,208 bytes in 1 blocks are still reachable in loss record 107 of 124
==13621==    at 0x483B7F3: malloc (in /usr/lib/x86_64-linux-gnu/valgrind/vgpreload_memcheck-amd64-linux.so)
==13621==    by 0x1C08B4: PyMem_RawMalloc (obmalloc.c:572)
==13621==    by 0x1C08B4: _PyObject_Malloc (obmalloc.c:1956)
==13621==    by 0x1C08B4: _PyObject_Malloc (obmalloc.c:1949)
==13621==    by 0x1A774F: new_keys_object (dictobject.c:600)
==13621==    by 0x1A7900: dictresize (dictobject.c:1242)
==13621==    by 0x1AFA9A: insertion_resize (dictobject.c:1060)
==13621==    by 0x1AFA9A: PyDict_SetDefault (dictobject.c:3067)
==13621==    by 0x1DF80E: type_add_method (typeobject.c:5597)
==13621==    by 0x1DF80E: type_add_methods (typeobject.c:5623)
==13621==    by 0x1DF80E: type_ready_fill_dict (typeobject.c:6099)
==13621==    by 0x1DF80E: type_ready (typeobject.c:6337)
==13621==    by 0x1D581E: PyType_Ready (typeobject.c:6370)
==13621==    by 0x1BD717: _PyTypes_Init (object.c:1876)
==13621==    by 0x275860: pycore_init_types (pylifecycle.c:699)
==13621==    by 0x275860: pycore_interp_init (pylifecycle.c:810)
==13621==    by 0x278724: pyinit_config (pylifecycle.c:866)
==13621==    by 0x278724: pyinit_core.constprop.0 (pylifecycle.c:1029)
==13621==    by 0x279113: Py_InitializeFromConfig (pylifecycle.c:1219)
==13621==    by 0x16E719: pymain_init (main.c:66)
==13621== 
==13621== 2,208 bytes in 1 blocks are still reachable in loss record 108 of 124
==13621==    at 0x483B7F3: malloc (in /usr/lib/x86_64-linux-gnu/valgrind/vgpreload_memcheck-amd64-linux.so)
==13621==    by 0x1C08B4: PyMem_RawMalloc (obmalloc.c:572)
==13621==    by 0x1C08B4: _PyObject_Malloc (obmalloc.c:1956)
==13621==    by 0x1C08B4: _PyObject_Malloc (obmalloc.c:1949)
==13621==    by 0x1A774F: new_keys_object (dictobject.c:600)
==13621==    by 0x1A7900: dictresize (dictobject.c:1242)
==13621==    by 0x1AB232: insertion_resize (dictobject.c:1060)
==13621==    by 0x1AB232: insertdict (dictobject.c:1103)
==13621==    by 0x1DF62E: add_operators (typeobject.c:8636)
==13621==    by 0x1DF62E: type_ready_fill_dict (typeobject.c:6096)
==13621==    by 0x1DF62E: type_ready (typeobject.c:6337)
==13621==    by 0x1D581E: PyType_Ready (typeobject.c:6370)
==13621==    by 0x1BD82F: _PyTypes_Init (object.c:1890)
==13621==    by 0x275860: pycore_init_types (pylifecycle.c:699)
==13621==    by 0x275860: pycore_interp_init (pylifecycle.c:810)
==13621==    by 0x278724: pyinit_config (pylifecycle.c:866)
==13621==    by 0x278724: pyinit_core.constprop.0 (pylifecycle.c:1029)
==13621==    by 0x279113: Py_InitializeFromConfig (pylifecycle.c:1219)
==13621==    by 0x16E719: pymain_init (main.c:66)
==13621== 
==13621== 2,208 bytes in 1 blocks are still reachable in loss record 109 of 124
==13621==    at 0x483B7F3: malloc (in /usr/lib/x86_64-linux-gnu/valgrind/vgpreload_memcheck-amd64-linux.so)
==13621==    by 0x1C08B4: PyMem_RawMalloc (obmalloc.c:572)
==13621==    by 0x1C08B4: _PyObject_Malloc (obmalloc.c:1956)
==13621==    by 0x1C08B4: _PyObject_Malloc (obmalloc.c:1949)
==13621==    by 0x1A774F: new_keys_object (dictobject.c:600)
==13621==    by 0x1A7900: dictresize (dictobject.c:1242)
==13621==    by 0x1AB232: insertion_resize (dictobject.c:1060)
==13621==    by 0x1AB232: insertdict (dictobject.c:1103)
==13621==    by 0x1DF62E: add_operators (typeobject.c:8636)
==13621==    by 0x1DF62E: type_ready_fill_dict (typeobject.c:6096)
==13621==    by 0x1DF62E: type_ready (typeobject.c:6337)
==13621==    by 0x1D581E: PyType_Ready (typeobject.c:6370)
==13621==    by 0x1BD843: _PyTypes_Init (object.c:1891)
==13621==    by 0x275860: pycore_init_types (pylifecycle.c:699)
==13621==    by 0x275860: pycore_interp_init (pylifecycle.c:810)
==13621==    by 0x278724: pyinit_config (pylifecycle.c:866)
==13621==    by 0x278724: pyinit_core.constprop.0 (pylifecycle.c:1029)
==13621==    by 0x279113: Py_InitializeFromConfig (pylifecycle.c:1219)
==13621==    by 0x16E719: pymain_init (main.c:66)
==13621== 
==13621== 2,208 bytes in 1 blocks are still reachable in loss record 110 of 124
==13621==    at 0x483B7F3: malloc (in /usr/lib/x86_64-linux-gnu/valgrind/vgpreload_memcheck-amd64-linux.so)
==13621==    by 0x1C08B4: PyMem_RawMalloc (obmalloc.c:572)
==13621==    by 0x1C08B4: _PyObject_Malloc (obmalloc.c:1956)
==13621==    by 0x1C08B4: _PyObject_Malloc (obmalloc.c:1949)
==13621==    by 0x1A774F: new_keys_object (dictobject.c:600)
==13621==    by 0x1A7900: dictresize (dictobject.c:1242)
==13621==    by 0x1AB232: insertion_resize (dictobject.c:1060)
==13621==    by 0x1AB232: insertdict (dictobject.c:1103)
==13621==    by 0x169FE5: _PyEval_EvalFrameDefault (ceval.c:2770)
==13621==    by 0x239016: _PyEval_EvalFrame (pycore_ceval.h:46)
==13621==    by 0x239016: _PyEval_Vector (ceval.c:5065)
==13621==    by 0x239016: PyEval_EvalCode (ceval.c:1134)
==13621==    by 0x2607C9: exec_code_in_module (import.c:793)
==13621==    by 0x2607C9: PyImport_ImportFrozenModuleObject (import.c:1194)
==13621==    by 0x260A8D: PyImport_ImportFrozenModule (import.c:1216)
==13621==    by 0x275AA6: init_importlib (pylifecycle.c:167)
==13621==    by 0x275AA6: pycore_interp_init (pylifecycle.c:837)
==13621==    by 0x278724: pyinit_config (pylifecycle.c:866)
==13621==    by 0x278724: pyinit_core.constprop.0 (pylifecycle.c:1029)
==13621==    by 0x279113: Py_InitializeFromConfig (pylifecycle.c:1219)
==13621== 
==13621== 2,208 bytes in 1 blocks are still reachable in loss record 111 of 124
==13621==    at 0x483B7F3: malloc (in /usr/lib/x86_64-linux-gnu/valgrind/vgpreload_memcheck-amd64-linux.so)
==13621==    by 0x1C08B4: PyMem_RawMalloc (obmalloc.c:572)
==13621==    by 0x1C08B4: _PyObject_Malloc (obmalloc.c:1956)
==13621==    by 0x1C08B4: _PyObject_Malloc (obmalloc.c:1949)
==13621==    by 0x1A774F: new_keys_object (dictobject.c:600)
==13621==    by 0x1A7900: dictresize (dictobject.c:1242)
==13621==    by 0x1AB232: insertion_resize (dictobject.c:1060)
==13621==    by 0x1AB232: insertdict (dictobject.c:1103)
==13621==    by 0x169FE5: _PyEval_EvalFrameDefault (ceval.c:2770)
==13621==    by 0x239016: _PyEval_EvalFrame (pycore_ceval.h:46)
==13621==    by 0x239016: _PyEval_Vector (ceval.c:5065)
==13621==    by 0x239016: PyEval_EvalCode (ceval.c:1134)
==13621==    by 0x37F198: builtin_exec_impl (bltinmodule.c:1056)
==13621==    by 0x37F198: builtin_exec (bltinmodule.c.h:371)
==13621==    by 0x3457DB: cfunction_vectorcall_FASTCALL (methodobject.c:430)
==13621==    by 0x16B72D: _PyObject_VectorcallTstate (abstract.h:114)
==13621==    by 0x16B72D: PyObject_Vectorcall (abstract.h:123)
==13621==    by 0x16B72D: call_function (ceval.c:5867)
==13621==    by 0x16B72D: _PyEval_EvalFrameDefault (ceval.c:4213)
==13621==    by 0x239197: _PyEval_EvalFrame (pycore_ceval.h:46)
==13621==    by 0x239197: _PyEval_Vector (ceval.c:5065)
==13621==    by 0x16BECD: _PyObject_VectorcallTstate (abstract.h:114)
==13621==    by 0x16BECD: PyObject_Vectorcall (abstract.h:123)
==13621==    by 0x16BECD: call_function (ceval.c:5867)
==13621==    by 0x16BECD: _PyEval_EvalFrameDefault (ceval.c:4181)
==13621== 
==13621== 2,208 bytes in 1 blocks are still reachable in loss record 112 of 124
==13621==    at 0x483B7F3: malloc (in /usr/lib/x86_64-linux-gnu/valgrind/vgpreload_memcheck-amd64-linux.so)
==13621==    by 0x1C08B4: PyMem_RawMalloc (obmalloc.c:572)
==13621==    by 0x1C08B4: _PyObject_Malloc (obmalloc.c:1956)
==13621==    by 0x1C08B4: _PyObject_Malloc (obmalloc.c:1949)
==13621==    by 0x1A774F: new_keys_object (dictobject.c:600)
==13621==    by 0x1A7900: dictresize (dictobject.c:1242)
==13621==    by 0x1AB232: insertion_resize (dictobject.c:1060)
==13621==    by 0x1AB232: insertdict (dictobject.c:1103)
==13621==    by 0x1693E1: import_all_from (ceval.c:6166)
==13621==    by 0x1693E1: _PyEval_EvalFrameDefault (ceval.c:3719)
==13621==    by 0x239016: _PyEval_EvalFrame (pycore_ceval.h:46)
==13621==    by 0x239016: _PyEval_Vector (ceval.c:5065)
==13621==    by 0x239016: PyEval_EvalCode (ceval.c:1134)
==13621==    by 0x37F198: builtin_exec_impl (bltinmodule.c:1056)
==13621==    by 0x37F198: builtin_exec (bltinmodule.c.h:371)
==13621==    by 0x3457DB: cfunction_vectorcall_FASTCALL (methodobject.c:430)
==13621==    by 0x18064B: PyVectorcall_Call (call.c:255)
==13621==    by 0x164AA1: do_call_core (ceval.c:5919)
==13621==    by 0x164AA1: _PyEval_EvalFrameDefault (ceval.c:4277)
==13621==    by 0x239197: _PyEval_EvalFrame (pycore_ceval.h:46)
==13621==    by 0x239197: _PyEval_Vector (ceval.c:5065)
==13621== 
==13621== 2,208 bytes in 1 blocks are still reachable in loss record 113 of 124
==13621==    at 0x483B7F3: malloc (in /usr/lib/x86_64-linux-gnu/valgrind/vgpreload_memcheck-amd64-linux.so)
==13621==    by 0x1C08B4: PyMem_RawMalloc (obmalloc.c:572)
==13621==    by 0x1C08B4: _PyObject_Malloc (obmalloc.c:1956)
==13621==    by 0x1C08B4: _PyObject_Malloc (obmalloc.c:1949)
==13621==    by 0x1A774F: new_keys_object (dictobject.c:600)
==13621==    by 0x1A7900: dictresize (dictobject.c:1242)
==13621==    by 0x1AB232: insertion_resize (dictobject.c:1060)
==13621==    by 0x1AB232: insertdict (dictobject.c:1103)
==13621==    by 0x169FE5: _PyEval_EvalFrameDefault (ceval.c:2770)
==13621==    by 0x239016: _PyEval_EvalFrame (pycore_ceval.h:46)
==13621==    by 0x239016: _PyEval_Vector (ceval.c:5065)
==13621==    by 0x239016: PyEval_EvalCode (ceval.c:1134)
==13621==    by 0x37F198: builtin_exec_impl (bltinmodule.c:1056)
==13621==    by 0x37F198: builtin_exec (bltinmodule.c.h:371)
==13621==    by 0x3457DB: cfunction_vectorcall_FASTCALL (methodobject.c:430)
==13621==    by 0x18064B: PyVectorcall_Call (call.c:255)
==13621==    by 0x164AA1: do_call_core (ceval.c:5919)
==13621==    by 0x164AA1: _PyEval_EvalFrameDefault (ceval.c:4277)
==13621==    by 0x239197: _PyEval_EvalFrame (pycore_ceval.h:46)
==13621==    by 0x239197: _PyEval_Vector (ceval.c:5065)
==13621== 
==13621== 2,208 bytes in 1 blocks are still reachable in loss record 114 of 124
==13621==    at 0x483B7F3: malloc (in /usr/lib/x86_64-linux-gnu/valgrind/vgpreload_memcheck-amd64-linux.so)
==13621==    by 0x1C08B4: PyMem_RawMalloc (obmalloc.c:572)
==13621==    by 0x1C08B4: _PyObject_Malloc (obmalloc.c:1956)
==13621==    by 0x1C08B4: _PyObject_Malloc (obmalloc.c:1949)
==13621==    by 0x1A774F: new_keys_object (dictobject.c:600)
==13621==    by 0x1A7900: dictresize (dictobject.c:1242)
==13621==    by 0x1AFA9A: insertion_resize (dictobject.c:1060)
==13621==    by 0x1AFA9A: PyDict_SetDefault (dictobject.c:3067)
==13621==    by 0x1DFA55: type_add_getset (typeobject.c:5670)
==13621==    by 0x1DFA55: type_ready_fill_dict (typeobject.c:6105)
==13621==    by 0x1DFA55: type_ready (typeobject.c:6337)
==13621==    by 0x1D581E: PyType_Ready (typeobject.c:6370)
==13621==    by 0x271AE6: PyModule_AddType (modsupport.c:706)
==13621==    by 0x2D9561: collections_exec (_collectionsmodule.c:2612)
==13621==    by 0x1B9056: PyModule_ExecDef (moduleobject.c:407)
==13621==    by 0x25EA72: _imp_exec_builtin (import.c.h:64)
==13621==    by 0x345556: cfunction_vectorcall_O (methodobject.c:516)
==13621== 
==13621== 2,208 bytes in 1 blocks are still reachable in loss record 115 of 124
==13621==    at 0x483B7F3: malloc (in /usr/lib/x86_64-linux-gnu/valgrind/vgpreload_memcheck-amd64-linux.so)
==13621==    by 0x1C08B4: PyMem_RawMalloc (obmalloc.c:572)
==13621==    by 0x1C08B4: _PyObject_Malloc (obmalloc.c:1956)
==13621==    by 0x1C08B4: _PyObject_Malloc (obmalloc.c:1949)
==13621==    by 0x1A774F: new_keys_object (dictobject.c:600)
==13621==    by 0x1A7900: dictresize (dictobject.c:1242)
==13621==    by 0x1AB232: insertion_resize (dictobject.c:1060)
==13621==    by 0x1AB232: insertdict (dictobject.c:1103)
==13621==    by 0x1B08C5: PyDict_SetItem (dictobject.c:1623)
==13621==    by 0x1B08C5: PyDict_SetItemString (dictobject.c:3614)
==13621==    by 0x27175E: PyModule_AddObjectRef (modsupport.c:662)
==13621==    by 0x55BE231: _ctypes_add_objects (_ctypes.c:5804)
==13621==    by 0x55BE231: _ctypes_mod_exec (_ctypes.c:5836)
==13621==    by 0x55BE231: PyInit__ctypes (_ctypes.c:5851)
==13621==    by 0x262340: _PyImport_LoadDynamicModuleWithSpec (importdl.c:167)
==13621==    by 0x25E6D4: _imp_create_dynamic_impl (import.c:2049)
==13621==    by 0x25E6D4: _imp_create_dynamic (import.c.h:330)
==13621==    by 0x3457DB: cfunction_vectorcall_FASTCALL (methodobject.c:430)
==13621==    by 0x18064B: PyVectorcall_Call (call.c:255)
==13621== 
==13621== 3,781 bytes in 3 blocks are still reachable in loss record 116 of 124
==13621==    at 0x483DD99: calloc (in /usr/lib/x86_64-linux-gnu/valgrind/vgpreload_memcheck-amd64-linux.so)
==13621==    by 0x400D283: _dl_new_object (dl-object.c:89)
==13621==    by 0x4006E96: _dl_map_object_from_fd (dl-load.c:997)
==13621==    by 0x400A61A: _dl_map_object (dl-load.c:2236)
==13621==    by 0x4015D46: dl_open_worker (dl-open.c:513)
==13621==    by 0x4B31927: _dl_catch_exception (dl-error-skeleton.c:208)
==13621==    by 0x4015609: _dl_open (dl-open.c:837)
==13621==    by 0x487834B: dlopen_doit (dlopen.c:66)
==13621==    by 0x4B31927: _dl_catch_exception (dl-error-skeleton.c:208)
==13621==    by 0x4B319F2: _dl_catch_error (dl-error-skeleton.c:227)
==13621==    by 0x4878B58: _dlerror_run (dlerror.c:170)
==13621==    by 0x48783D9: dlopen@@GLIBC_2.2.5 (dlopen.c:87)
==13621== 
==13621== 5,664 bytes in 6 blocks are still reachable in loss record 117 of 124
==13621==    at 0x483B7F3: malloc (in /usr/lib/x86_64-linux-gnu/valgrind/vgpreload_memcheck-amd64-linux.so)
==13621==    by 0x1C08B4: PyMem_RawMalloc (obmalloc.c:572)
==13621==    by 0x1C08B4: _PyObject_Malloc (obmalloc.c:1956)
==13621==    by 0x1C08B4: _PyObject_Malloc (obmalloc.c:1949)
==13621==    by 0x2A3405: _PyObject_GC_Alloc (gcmodule.c:2274)
==13621==    by 0x2A3405: _PyObject_GC_Malloc (gcmodule.c:2301)
==13621==    by 0x1D1B89: PyType_GenericAlloc (typeobject.c:1154)
==13621==    by 0x1E2DE4: type_new_alloc (typeobject.c:2741)
==13621==    by 0x1E2DE4: type_new_init (typeobject.c:3153)
==13621==    by 0x1E2DE4: type_new_impl (typeobject.c:3176)
==13621==    by 0x1E2DE4: type_new (typeobject.c:3325)
==13621==    by 0x55B897B: PyCFuncPtrType_new (_ctypes.c:2584)
==13621==    by 0x1D3538: type_call (typeobject.c:1121)
==13621==    by 0x17FC2B: _PyObject_MakeTpCall (call.c:215)
==13621==    by 0x1804CB: _PyObject_FastCallDictTstate (call.c:137)
==13621==    by 0x1804CB: PyObject_VectorcallDict (call.c:166)
==13621==    by 0x37E34C: builtin___build_class__ (bltinmodule.c:224)
==13621==    by 0x345669: cfunction_vectorcall_FASTCALL_KEYWORDS (methodobject.c:446)
==13621==    by 0x16B72D: _PyObject_VectorcallTstate (abstract.h:114)
==13621==    by 0x16B72D: PyObject_Vectorcall (abstract.h:123)
==13621==    by 0x16B72D: call_function (ceval.c:5867)
==13621==    by 0x16B72D: _PyEval_EvalFrameDefault (ceval.c:4213)
==13621== 
==13621== 7,552 bytes in 8 blocks are still reachable in loss record 118 of 124
==13621==    at 0x483B7F3: malloc (in /usr/lib/x86_64-linux-gnu/valgrind/vgpreload_memcheck-amd64-linux.so)
==13621==    by 0x1C08B4: PyMem_RawMalloc (obmalloc.c:572)
==13621==    by 0x1C08B4: _PyObject_Malloc (obmalloc.c:1956)
==13621==    by 0x1C08B4: _PyObject_Malloc (obmalloc.c:1949)
==13621==    by 0x2A3405: _PyObject_GC_Alloc (gcmodule.c:2274)
==13621==    by 0x2A3405: _PyObject_GC_Malloc (gcmodule.c:2301)
==13621==    by 0x1D1B89: PyType_GenericAlloc (typeobject.c:1154)
==13621==    by 0x1E2DE4: type_new_alloc (typeobject.c:2741)
==13621==    by 0x1E2DE4: type_new_init (typeobject.c:3153)
==13621==    by 0x1E2DE4: type_new_impl (typeobject.c:3176)
==13621==    by 0x1E2DE4: type_new (typeobject.c:3325)
==13621==    by 0x55BBBB3: CreateSwappedType (_ctypes.c:2004)
==13621==    by 0x55BBBB3: PyCSimpleType_new (_ctypes.c:2213)
==13621==    by 0x1D3538: type_call (typeobject.c:1121)
==13621==    by 0x17FC2B: _PyObject_MakeTpCall (call.c:215)
==13621==    by 0x1804CB: _PyObject_FastCallDictTstate (call.c:137)
==13621==    by 0x1804CB: PyObject_VectorcallDict (call.c:166)
==13621==    by 0x37E34C: builtin___build_class__ (bltinmodule.c:224)
==13621==    by 0x345669: cfunction_vectorcall_FASTCALL_KEYWORDS (methodobject.c:446)
==13621==    by 0x16B72D: _PyObject_VectorcallTstate (abstract.h:114)
==13621==    by 0x16B72D: PyObject_Vectorcall (abstract.h:123)
==13621==    by 0x16B72D: call_function (ceval.c:5867)
==13621==    by 0x16B72D: _PyEval_EvalFrameDefault (ceval.c:4213)
==13621== 
==13621== 8,192 bytes in 1 blocks are still reachable in loss record 119 of 124
==13621==    at 0x483DD99: calloc (in /usr/lib/x86_64-linux-gnu/valgrind/vgpreload_memcheck-amd64-linux.so)
==13621==    by 0x1BEDE2: PyMem_RawCalloc (obmalloc.c:581)
==13621==    by 0x1BEDE2: arena_map_get (obmalloc.c:1413)
==13621==    by 0x1C04B5: arena_map_mark_used (obmalloc.c:1468)
==13621==    by 0x1C04B5: new_arena (obmalloc.c:1597)
==13621==    by 0x1C04B5: allocate_from_new_pool (obmalloc.c:1777)
==13621==    by 0x1C08CC: pymalloc_alloc (obmalloc.c:1941)
==13621==    by 0x1C08CC: _PyObject_Malloc (obmalloc.c:1951)
==13621==    by 0x1A6F8A: _PyLong_New (longobject.c:134)
==13621==    by 0x1A6F8A: _PyLong_Init (longobject.c:5713)
==13621==    by 0x2754A8: pycore_init_singletons (pylifecycle.c:661)
==13621==    by 0x2754A8: pycore_interp_init (pylifecycle.c:799)
==13621==    by 0x278724: pyinit_config (pylifecycle.c:866)
==13621==    by 0x278724: pyinit_core.constprop.0 (pylifecycle.c:1029)
==13621==    by 0x279113: Py_InitializeFromConfig (pylifecycle.c:1219)
==13621==    by 0x16E719: pymain_init (main.c:66)
==13621==    by 0x16F9F7: pymain_main (main.c:687)
==13621==    by 0x16F9F7: Py_BytesMain (main.c:720)
==13621==    by 0x49F5082: (below main) (libc-start.c:308)
==13621== 
==13621== 8,496 bytes in 9 blocks are still reachable in loss record 120 of 124
==13621==    at 0x483B7F3: malloc (in /usr/lib/x86_64-linux-gnu/valgrind/vgpreload_memcheck-amd64-linux.so)
==13621==    by 0x1C08B4: PyMem_RawMalloc (obmalloc.c:572)
==13621==    by 0x1C08B4: _PyObject_Malloc (obmalloc.c:1956)
==13621==    by 0x1C08B4: _PyObject_Malloc (obmalloc.c:1949)
==13621==    by 0x2A3405: _PyObject_GC_Alloc (gcmodule.c:2274)
==13621==    by 0x2A3405: _PyObject_GC_Malloc (gcmodule.c:2301)
==13621==    by 0x1D1B89: PyType_GenericAlloc (typeobject.c:1154)
==13621==    by 0x1E2DE4: type_new_alloc (typeobject.c:2741)
==13621==    by 0x1E2DE4: type_new_init (typeobject.c:3153)
==13621==    by 0x1E2DE4: type_new_impl (typeobject.c:3176)
==13621==    by 0x1E2DE4: type_new (typeobject.c:3325)
==13621==    by 0x1D3538: type_call (typeobject.c:1121)
==13621==    by 0x17FC2B: _PyObject_MakeTpCall (call.c:215)
==13621==    by 0x180475: _PyObject_FastCallDictTstate (call.c:142)
==13621==    by 0x180475: PyObject_VectorcallDict (call.c:166)
==13621==    by 0x37E34C: builtin___build_class__ (bltinmodule.c:224)
==13621==    by 0x345669: cfunction_vectorcall_FASTCALL_KEYWORDS (methodobject.c:446)
==13621==    by 0x16B72D: _PyObject_VectorcallTstate (abstract.h:114)
==13621==    by 0x16B72D: PyObject_Vectorcall (abstract.h:123)
==13621==    by 0x16B72D: call_function (ceval.c:5867)
==13621==    by 0x16B72D: _PyEval_EvalFrameDefault (ceval.c:4213)
==13621==    by 0x239016: _PyEval_EvalFrame (pycore_ceval.h:46)
==13621==    by 0x239016: _PyEval_Vector (ceval.c:5065)
==13621==    by 0x239016: PyEval_EvalCode (ceval.c:1134)
==13621== 
==13621== 9,248 bytes in 1 blocks are still reachable in loss record 121 of 124
==13621==    at 0x483B7F3: malloc (in /usr/lib/x86_64-linux-gnu/valgrind/vgpreload_memcheck-amd64-linux.so)
==13621==    by 0x1C08B4: PyMem_RawMalloc (obmalloc.c:572)
==13621==    by 0x1C08B4: _PyObject_Malloc (obmalloc.c:1956)
==13621==    by 0x1C08B4: _PyObject_Malloc (obmalloc.c:1949)
==13621==    by 0x1A7617: new_keys_object (dictobject.c:600)
==13621==    by 0x1A7900: dictresize (dictobject.c:1242)
==13621==    by 0x1AB232: insertion_resize (dictobject.c:1060)
==13621==    by 0x1AB232: insertdict (dictobject.c:1103)
==13621==    by 0x1D07EC: add_subclass.isra.0 (typeobject.c:6406)
==13621==    by 0x1E0219: type_ready_add_subclasses (typeobject.c:6256)
==13621==    by 0x1E0219: type_ready (typeobject.c:6346)
==13621==    by 0x1E3212: PyType_Ready (typeobject.c:6370)
==13621==    by 0x1E3212: type_new_impl (typeobject.c:3186)
==13621==    by 0x1E3212: type_new (typeobject.c:3325)
==13621==    by 0x1D3538: type_call (typeobject.c:1121)
==13621==    by 0x17FC2B: _PyObject_MakeTpCall (call.c:215)
==13621==    by 0x180475: _PyObject_FastCallDictTstate (call.c:142)
==13621==    by 0x180475: PyObject_VectorcallDict (call.c:166)
==13621==    by 0x37E34C: builtin___build_class__ (bltinmodule.c:224)
==13621== 
==13621== 16,992 bytes in 18 blocks are still reachable in loss record 122 of 124
==13621==    at 0x483B7F3: malloc (in /usr/lib/x86_64-linux-gnu/valgrind/vgpreload_memcheck-amd64-linux.so)
==13621==    by 0x1C08B4: PyMem_RawMalloc (obmalloc.c:572)
==13621==    by 0x1C08B4: _PyObject_Malloc (obmalloc.c:1956)
==13621==    by 0x1C08B4: _PyObject_Malloc (obmalloc.c:1949)
==13621==    by 0x2A3405: _PyObject_GC_Alloc (gcmodule.c:2274)
==13621==    by 0x2A3405: _PyObject_GC_Malloc (gcmodule.c:2301)
==13621==    by 0x1D1B89: PyType_GenericAlloc (typeobject.c:1154)
==13621==    by 0x1E2DE4: type_new_alloc (typeobject.c:2741)
==13621==    by 0x1E2DE4: type_new_init (typeobject.c:3153)
==13621==    by 0x1E2DE4: type_new_impl (typeobject.c:3176)
==13621==    by 0x1E2DE4: type_new (typeobject.c:3325)
==13621==    by 0x55BB907: PyCSimpleType_new (_ctypes.c:2079)
==13621==    by 0x1D3538: type_call (typeobject.c:1121)
==13621==    by 0x17FC2B: _PyObject_MakeTpCall (call.c:215)
==13621==    by 0x1804CB: _PyObject_FastCallDictTstate (call.c:137)
==13621==    by 0x1804CB: PyObject_VectorcallDict (call.c:166)
==13621==    by 0x37E34C: builtin___build_class__ (bltinmodule.c:224)
==13621==    by 0x345669: cfunction_vectorcall_FASTCALL_KEYWORDS (methodobject.c:446)
==13621==    by 0x16B72D: _PyObject_VectorcallTstate (abstract.h:114)
==13621==    by 0x16B72D: PyObject_Vectorcall (abstract.h:123)
==13621==    by 0x16B72D: call_function (ceval.c:5867)
==13621==    by 0x16B72D: _PyEval_EvalFrameDefault (ceval.c:4213)
==13621== 
==13621== 23,088 bytes in 2 blocks are still reachable in loss record 123 of 124
==13621==    at 0x483B7F3: malloc (in /usr/lib/x86_64-linux-gnu/valgrind/vgpreload_memcheck-amd64-linux.so)
==13621==    by 0x1C08B4: PyMem_RawMalloc (obmalloc.c:572)
==13621==    by 0x1C08B4: _PyObject_Malloc (obmalloc.c:1956)
==13621==    by 0x1C08B4: _PyObject_Malloc (obmalloc.c:1949)
==13621==    by 0x1A7617: new_keys_object (dictobject.c:600)
==13621==    by 0x1A7900: dictresize (dictobject.c:1242)
==13621==    by 0x1AB232: insertion_resize (dictobject.c:1060)
==13621==    by 0x1AB232: insertdict (dictobject.c:1103)
==13621==    by 0x169FE5: _PyEval_EvalFrameDefault (ceval.c:2770)
==13621==    by 0x239016: _PyEval_EvalFrame (pycore_ceval.h:46)
==13621==    by 0x239016: _PyEval_Vector (ceval.c:5065)
==13621==    by 0x239016: PyEval_EvalCode (ceval.c:1134)
==13621==    by 0x37F198: builtin_exec_impl (bltinmodule.c:1056)
==13621==    by 0x37F198: builtin_exec (bltinmodule.c.h:371)
==13621==    by 0x3457DB: cfunction_vectorcall_FASTCALL (methodobject.c:430)
==13621==    by 0x18064B: PyVectorcall_Call (call.c:255)
==13621==    by 0x164AA1: do_call_core (ceval.c:5919)
==13621==    by 0x164AA1: _PyEval_EvalFrameDefault (ceval.c:4277)
==13621==    by 0x239197: _PyEval_EvalFrame (pycore_ceval.h:46)
==13621==    by 0x239197: _PyEval_Vector (ceval.c:5065)
==13621== 
==13621== 2,097,152 bytes in 1 blocks are definitely lost in loss record 124 of 124
==13621==    at 0x483B7F3: malloc (in /usr/lib/x86_64-linux-gnu/valgrind/vgpreload_memcheck-amd64-linux.so)
==13621==    by 0x55D1141: leak (in /workspaces/memoryleaks/compile/leak/leak.so)
==13621==    by 0x55E0FF4: ??? (in /usr/lib/x86_64-linux-gnu/libffi.so.7.1.0)
==13621==    by 0x55E0409: ??? (in /usr/lib/x86_64-linux-gnu/libffi.so.7.1.0)
==13621==    by 0x55C0F50: _call_function_pointer (callproc.c:916)
==13621==    by 0x55C0F50: _ctypes_callproc (callproc.c:1259)
==13621==    by 0x55BAA10: PyCFuncPtr_call (_ctypes.c:4201)
==13621==    by 0x17FC2B: _PyObject_MakeTpCall (call.c:215)
==13621==    by 0x16BF1E: _PyObject_VectorcallTstate (abstract.h:112)
==13621==    by 0x16BF1E: _PyObject_VectorcallTstate (abstract.h:99)
==13621==    by 0x16BF1E: PyObject_Vectorcall (abstract.h:123)
==13621==    by 0x16BF1E: call_function (ceval.c:5867)
==13621==    by 0x16BF1E: _PyEval_EvalFrameDefault (ceval.c:4181)
==13621==    by 0x239197: _PyEval_EvalFrame (pycore_ceval.h:46)
==13621==    by 0x239197: _PyEval_Vector (ceval.c:5065)
==13621==    by 0x16B72D: _PyObject_VectorcallTstate (abstract.h:114)
==13621==    by 0x16B72D: PyObject_Vectorcall (abstract.h:123)
==13621==    by 0x16B72D: call_function (ceval.c:5867)
==13621==    by 0x16B72D: _PyEval_EvalFrameDefault (ceval.c:4213)
==13621==    by 0x239016: _PyEval_EvalFrame (pycore_ceval.h:46)
==13621==    by 0x239016: _PyEval_Vector (ceval.c:5065)
==13621==    by 0x239016: PyEval_EvalCode (ceval.c:1134)
==13621==    by 0x27EBA6: run_eval_code_obj (pythonrun.c:1291)
==13621==    by 0x27EBA6: run_mod (pythonrun.c:1312)
==13621== 
==13621== LEAK SUMMARY:
==13621==    definitely lost: 2,097,152 bytes in 1 blocks
==13621==    indirectly lost: 0 bytes in 0 blocks
==13621==      possibly lost: 568 bytes in 1 blocks
==13621==    still reachable: 193,008 bytes in 170 blocks
==13621==         suppressed: 0 bytes in 0 blocks
==13621== 
==13621== For lists of detected and suppressed errors, rerun with: -s
==13621== ERROR SUMMARY: 2 errors from 2 contexts (suppressed: 0 from 0)
